[2024-09-26T21:03:39.647+0000] {local_task_job_runner.py:123} INFO - ::group::Pre task execution logs
[2024-09-26T21:03:39.945+0000] {taskinstance.py:2612} INFO - Dependencies all met for dep_context=non-requeueable deps ti=<TaskInstance: fetch_and_save_share_prices.create_table scheduled__2023-09-27T00:00:00+00:00 [queued]>
[2024-09-26T21:03:40.063+0000] {taskinstance.py:2612} INFO - Dependencies all met for dep_context=requeueable deps ti=<TaskInstance: fetch_and_save_share_prices.create_table scheduled__2023-09-27T00:00:00+00:00 [queued]>
[2024-09-26T21:03:40.100+0000] {taskinstance.py:2865} INFO - Starting attempt 2 of 2
[2024-09-26T21:03:40.941+0000] {taskinstance.py:2888} INFO - Executing <Task(PythonOperator): create_table> on 2023-09-27 00:00:00+00:00
[2024-09-26T21:03:40.980+0000] {warnings.py:112} WARNING - /home/***/.local/lib/python3.12/site-packages/***/task/task_runner/standard_task_runner.py:70: DeprecationWarning: This process (pid=1703) is multi-threaded, use of fork() may lead to deadlocks in the child.
  pid = os.fork()

[2024-09-26T21:03:40.988+0000] {standard_task_runner.py:72} INFO - Started process 1756 to run task
[2024-09-26T21:03:41.020+0000] {standard_task_runner.py:104} INFO - Running: ['***', 'tasks', 'run', 'fetch_and_save_share_prices', 'create_table', 'scheduled__2023-09-27T00:00:00+00:00', '--job-id', '36', '--raw', '--subdir', 'DAGS_FOLDER/dag.py', '--cfg-path', '/tmp/tmpe8ve5_kg']
[2024-09-26T21:03:41.026+0000] {standard_task_runner.py:105} INFO - Job 36: Subtask create_table
[2024-09-26T21:03:41.263+0000] {task_command.py:467} INFO - Running <TaskInstance: fetch_and_save_share_prices.create_table scheduled__2023-09-27T00:00:00+00:00 [running]> on host 13b5797a93ab
[2024-09-26T21:03:41.598+0000] {taskinstance.py:3131} INFO - Exporting env vars: AIRFLOW_CTX_DAG_OWNER='***' AIRFLOW_CTX_DAG_ID='fetch_and_save_share_prices' AIRFLOW_CTX_TASK_ID='create_table' AIRFLOW_CTX_EXECUTION_DATE='2023-09-27T00:00:00+00:00' AIRFLOW_CTX_TRY_NUMBER='2' AIRFLOW_CTX_DAG_RUN_ID='scheduled__2023-09-27T00:00:00+00:00'
[2024-09-26T21:03:41.611+0000] {logging_mixin.py:190} INFO - Task instance is in running state
[2024-09-26T21:03:41.622+0000] {logging_mixin.py:190} INFO -  Previous state of the Task instance: queued
[2024-09-26T21:03:41.627+0000] {logging_mixin.py:190} INFO - Current task name:create_table state:running start_date:2024-09-26 21:03:39.961365+00:00
[2024-09-26T21:03:41.646+0000] {logging_mixin.py:190} INFO - Dag name:fetch_and_save_share_prices and current dag run status:running
[2024-09-26T21:03:41.672+0000] {taskinstance.py:731} INFO - ::endgroup::
[2024-09-26T21:03:41.908+0000] {taskinstance.py:3310} ERROR - Task failed with exception
Traceback (most recent call last):
  File "/home/airflow/.local/lib/python3.12/site-packages/airflow/models/taskinstance.py", line 767, in _execute_task
    result = _execute_callable(context=context, **execute_callable_kwargs)
             ^^^^^^^^^^^^^^^^^^^^^^^^^^^^^^^^^^^^^^^^^^^^^^^^^^^^^^^^^^^^^
  File "/home/airflow/.local/lib/python3.12/site-packages/airflow/models/taskinstance.py", line 733, in _execute_callable
    return ExecutionCallableRunner(
           ^^^^^^^^^^^^^^^^^^^^^^^^
  File "/home/airflow/.local/lib/python3.12/site-packages/airflow/utils/operator_helpers.py", line 252, in run
    return self.func(*args, **kwargs)
           ^^^^^^^^^^^^^^^^^^^^^^^^^^
  File "/home/airflow/.local/lib/python3.12/site-packages/airflow/models/baseoperator.py", line 406, in wrapper
    return func(self, *args, **kwargs)
           ^^^^^^^^^^^^^^^^^^^^^^^^^^^
  File "/home/airflow/.local/lib/python3.12/site-packages/airflow/operators/python.py", line 238, in execute
    return_value = self.execute_callable()
                   ^^^^^^^^^^^^^^^^^^^^^^^
  File "/home/airflow/.local/lib/python3.12/site-packages/airflow/operators/python.py", line 256, in execute_callable
    return runner.run(*self.op_args, **self.op_kwargs)
           ^^^^^^^^^^^^^^^^^^^^^^^^^^^^^^^^^^^^^^^^^^^
  File "/home/airflow/.local/lib/python3.12/site-packages/airflow/utils/operator_helpers.py", line 252, in run
    return self.func(*args, **kwargs)
           ^^^^^^^^^^^^^^^^^^^^^^^^^^
  File "/opt/airflow/dags/dag.py", line 69, in create_table
    hook.run(create_table_query)
  File "/home/airflow/.local/lib/python3.12/site-packages/airflow/providers/common/sql/hooks/sql.py", line 452, in run
    with self._create_autocommit_connection(autocommit) as conn:
         ^^^^^^^^^^^^^^^^^^^^^^^^^^^^^^^^^^^^^^^^^^^^^^
  File "/usr/local/lib/python3.12/contextlib.py", line 137, in __enter__
    return next(self.gen)
           ^^^^^^^^^^^^^^
  File "/home/airflow/.local/lib/python3.12/site-packages/airflow/providers/common/sql/hooks/sql.py", line 574, in _create_autocommit_connection
    with closing(self.get_conn()) as conn:
                 ^^^^^^^^^^^^^^^
  File "/home/airflow/.local/lib/python3.12/site-packages/airflow/providers/postgres/hooks/postgres.py", line 146, in get_conn
    conn = deepcopy(self.connection or self.get_connection(conn_id))
                                       ^^^^^^^^^^^^^^^^^^^^^^^^^^^^
  File "/home/airflow/.local/lib/python3.12/site-packages/airflow/hooks/base.py", line 83, in get_connection
    conn = Connection.get_connection_from_secrets(conn_id)
           ^^^^^^^^^^^^^^^^^^^^^^^^^^^^^^^^^^^^^^^^^^^^^^^
  File "/home/airflow/.local/lib/python3.12/site-packages/airflow/models/connection.py", line 537, in get_connection_from_secrets
    raise AirflowNotFoundException(f"The conn_id `{conn_id}` isn't defined")
airflow.exceptions.AirflowNotFoundException: The conn_id `my_postgres` isn't defined
[2024-09-26T21:03:42.145+0000] {logging_mixin.py:190} INFO - Task instance in failure state
[2024-09-26T21:03:42.171+0000] {logging_mixin.py:190} INFO - Task start:2024-09-26 21:03:39.961365+00:00 end:2024-09-26 21:03:42.144548+00:00 duration:2.183183
[2024-09-26T21:03:42.208+0000] {logging_mixin.py:190} INFO - Task:<Task(PythonOperator): create_table> dag:<DAG: fetch_and_save_share_prices> dagrun:<DagRun fetch_and_save_share_prices @ 2023-09-27 00:00:00+00:00: scheduled__2023-09-27T00:00:00+00:00, state:running, queued_at: 2024-09-26 20:57:20.864314+00:00. externally triggered: False>
[2024-09-26T21:03:42.219+0000] {logging_mixin.py:190} INFO - Failure caused by The conn_id `my_postgres` isn't defined
[2024-09-26T21:03:42.234+0000] {taskinstance.py:1225} INFO - Marking task as FAILED. dag_id=fetch_and_save_share_prices, task_id=create_table, run_id=scheduled__2023-09-27T00:00:00+00:00, execution_date=20230927T000000, start_date=20240926T210339, end_date=20240926T210342
[2024-09-26T21:03:42.340+0000] {taskinstance.py:340} INFO - ::group::Post task execution logs
[2024-09-26T21:03:42.341+0000] {standard_task_runner.py:124} ERROR - Failed to execute job 36 for task create_table (The conn_id `my_postgres` isn't defined; 1756)
Traceback (most recent call last):
  File "/home/airflow/.local/lib/python3.12/site-packages/airflow/task/task_runner/standard_task_runner.py", line 117, in _start_by_fork
    ret = args.func(args, dag=self.dag)
          ^^^^^^^^^^^^^^^^^^^^^^^^^^^^^
  File "/home/airflow/.local/lib/python3.12/site-packages/airflow/cli/cli_config.py", line 49, in command
    return func(*args, **kwargs)
           ^^^^^^^^^^^^^^^^^^^^^
  File "/home/airflow/.local/lib/python3.12/site-packages/airflow/utils/cli.py", line 115, in wrapper
    return f(*args, **kwargs)
           ^^^^^^^^^^^^^^^^^^
  File "/home/airflow/.local/lib/python3.12/site-packages/airflow/cli/commands/task_command.py", line 483, in task_run
    task_return_code = _run_task_by_selected_method(args, _dag, ti)
                       ^^^^^^^^^^^^^^^^^^^^^^^^^^^^^^^^^^^^^^^^^^^^
  File "/home/airflow/.local/lib/python3.12/site-packages/airflow/cli/commands/task_command.py", line 256, in _run_task_by_selected_method
    return _run_raw_task(args, ti)
           ^^^^^^^^^^^^^^^^^^^^^^^
  File "/home/airflow/.local/lib/python3.12/site-packages/airflow/cli/commands/task_command.py", line 341, in _run_raw_task
    return ti._run_raw_task(
           ^^^^^^^^^^^^^^^^^
  File "/home/airflow/.local/lib/python3.12/site-packages/airflow/utils/session.py", line 97, in wrapper
    return func(*args, session=session, **kwargs)
           ^^^^^^^^^^^^^^^^^^^^^^^^^^^^^^^^^^^^^^
  File "/home/airflow/.local/lib/python3.12/site-packages/airflow/models/taskinstance.py", line 3004, in _run_raw_task
    return _run_raw_task(
           ^^^^^^^^^^^^^^
  File "/home/airflow/.local/lib/python3.12/site-packages/airflow/models/taskinstance.py", line 273, in _run_raw_task
    TaskInstance._execute_task_with_callbacks(
  File "/home/airflow/.local/lib/python3.12/site-packages/airflow/models/taskinstance.py", line 3158, in _execute_task_with_callbacks
    result = self._execute_task(context, task_orig)
             ^^^^^^^^^^^^^^^^^^^^^^^^^^^^^^^^^^^^^^
  File "/home/airflow/.local/lib/python3.12/site-packages/airflow/models/taskinstance.py", line 3182, in _execute_task
    return _execute_task(self, context, task_orig)
           ^^^^^^^^^^^^^^^^^^^^^^^^^^^^^^^^^^^^^^^
  File "/home/airflow/.local/lib/python3.12/site-packages/airflow/models/taskinstance.py", line 767, in _execute_task
    result = _execute_callable(context=context, **execute_callable_kwargs)
             ^^^^^^^^^^^^^^^^^^^^^^^^^^^^^^^^^^^^^^^^^^^^^^^^^^^^^^^^^^^^^
  File "/home/airflow/.local/lib/python3.12/site-packages/airflow/models/taskinstance.py", line 733, in _execute_callable
    return ExecutionCallableRunner(
           ^^^^^^^^^^^^^^^^^^^^^^^^
  File "/home/airflow/.local/lib/python3.12/site-packages/airflow/utils/operator_helpers.py", line 252, in run
    return self.func(*args, **kwargs)
           ^^^^^^^^^^^^^^^^^^^^^^^^^^
  File "/home/airflow/.local/lib/python3.12/site-packages/airflow/models/baseoperator.py", line 406, in wrapper
    return func(self, *args, **kwargs)
           ^^^^^^^^^^^^^^^^^^^^^^^^^^^
  File "/home/airflow/.local/lib/python3.12/site-packages/airflow/operators/python.py", line 238, in execute
    return_value = self.execute_callable()
                   ^^^^^^^^^^^^^^^^^^^^^^^
  File "/home/airflow/.local/lib/python3.12/site-packages/airflow/operators/python.py", line 256, in execute_callable
    return runner.run(*self.op_args, **self.op_kwargs)
           ^^^^^^^^^^^^^^^^^^^^^^^^^^^^^^^^^^^^^^^^^^^
  File "/home/airflow/.local/lib/python3.12/site-packages/airflow/utils/operator_helpers.py", line 252, in run
    return self.func(*args, **kwargs)
           ^^^^^^^^^^^^^^^^^^^^^^^^^^
  File "/opt/airflow/dags/dag.py", line 69, in create_table
    hook.run(create_table_query)
  File "/home/airflow/.local/lib/python3.12/site-packages/airflow/providers/common/sql/hooks/sql.py", line 452, in run
    with self._create_autocommit_connection(autocommit) as conn:
         ^^^^^^^^^^^^^^^^^^^^^^^^^^^^^^^^^^^^^^^^^^^^^^
  File "/usr/local/lib/python3.12/contextlib.py", line 137, in __enter__
    return next(self.gen)
           ^^^^^^^^^^^^^^
  File "/home/airflow/.local/lib/python3.12/site-packages/airflow/providers/common/sql/hooks/sql.py", line 574, in _create_autocommit_connection
    with closing(self.get_conn()) as conn:
                 ^^^^^^^^^^^^^^^
  File "/home/airflow/.local/lib/python3.12/site-packages/airflow/providers/postgres/hooks/postgres.py", line 146, in get_conn
    conn = deepcopy(self.connection or self.get_connection(conn_id))
                                       ^^^^^^^^^^^^^^^^^^^^^^^^^^^^
  File "/home/airflow/.local/lib/python3.12/site-packages/airflow/hooks/base.py", line 83, in get_connection
    conn = Connection.get_connection_from_secrets(conn_id)
           ^^^^^^^^^^^^^^^^^^^^^^^^^^^^^^^^^^^^^^^^^^^^^^^
  File "/home/airflow/.local/lib/python3.12/site-packages/airflow/models/connection.py", line 537, in get_connection_from_secrets
    raise AirflowNotFoundException(f"The conn_id `{conn_id}` isn't defined")
airflow.exceptions.AirflowNotFoundException: The conn_id `my_postgres` isn't defined
[2024-09-26T21:03:42.506+0000] {local_task_job_runner.py:266} INFO - Task exited with return code 1
[2024-09-26T21:03:42.666+0000] {taskinstance.py:3900} INFO - 0 downstream tasks scheduled from follow-on schedule check
[2024-09-26T21:03:42.704+0000] {local_task_job_runner.py:245} INFO - ::endgroup::
[2024-09-26T21:45:13.327+0000] {local_task_job_runner.py:123} INFO - ::group::Pre task execution logs
[2024-09-26T21:45:13.463+0000] {taskinstance.py:2612} INFO - Dependencies all met for dep_context=non-requeueable deps ti=<TaskInstance: fetch_and_save_share_prices.create_table scheduled__2023-09-27T00:00:00+00:00 [queued]>
[2024-09-26T21:45:13.584+0000] {taskinstance.py:2612} INFO - Dependencies all met for dep_context=requeueable deps ti=<TaskInstance: fetch_and_save_share_prices.create_table scheduled__2023-09-27T00:00:00+00:00 [queued]>
[2024-09-26T21:45:13.585+0000] {taskinstance.py:2865} INFO - Starting attempt 2 of 2
[2024-09-26T21:45:13.747+0000] {taskinstance.py:2888} INFO - Executing <Task(PythonOperator): create_table> on 2023-09-27 00:00:00+00:00
[2024-09-26T21:45:13.781+0000] {warnings.py:112} WARNING - /home/***/.local/lib/python3.12/site-packages/***/task/task_runner/standard_task_runner.py:70: DeprecationWarning: This process (pid=3180) is multi-threaded, use of fork() may lead to deadlocks in the child.
  pid = os.fork()

[2024-09-26T21:45:13.817+0000] {standard_task_runner.py:72} INFO - Started process 3211 to run task
[2024-09-26T21:45:13.821+0000] {standard_task_runner.py:104} INFO - Running: ['***', 'tasks', 'run', 'fetch_and_save_share_prices', 'create_table', 'scheduled__2023-09-27T00:00:00+00:00', '--job-id', '272', '--raw', '--subdir', 'DAGS_FOLDER/dag.py', '--cfg-path', '/tmp/tmpvkos84zn']
[2024-09-26T21:45:13.880+0000] {standard_task_runner.py:105} INFO - Job 272: Subtask create_table
[2024-09-26T21:45:14.314+0000] {task_command.py:467} INFO - Running <TaskInstance: fetch_and_save_share_prices.create_table scheduled__2023-09-27T00:00:00+00:00 [running]> on host 13b5797a93ab
[2024-09-26T21:45:15.068+0000] {taskinstance.py:3131} INFO - Exporting env vars: AIRFLOW_CTX_DAG_OWNER='***' AIRFLOW_CTX_DAG_ID='fetch_and_save_share_prices' AIRFLOW_CTX_TASK_ID='create_table' AIRFLOW_CTX_EXECUTION_DATE='2023-09-27T00:00:00+00:00' AIRFLOW_CTX_TRY_NUMBER='2' AIRFLOW_CTX_DAG_RUN_ID='scheduled__2023-09-27T00:00:00+00:00'
[2024-09-26T21:45:15.092+0000] {logging_mixin.py:190} INFO - Task instance is in running state
[2024-09-26T21:45:15.115+0000] {logging_mixin.py:190} INFO -  Previous state of the Task instance: queued
[2024-09-26T21:45:15.130+0000] {logging_mixin.py:190} INFO - Current task name:create_table state:running start_date:2024-09-26 21:45:13.467119+00:00
[2024-09-26T21:45:15.145+0000] {logging_mixin.py:190} INFO - Dag name:fetch_and_save_share_prices and current dag run status:running
[2024-09-26T21:45:15.148+0000] {taskinstance.py:731} INFO - ::endgroup::
[2024-09-26T21:45:15.301+0000] {taskinstance.py:3310} ERROR - Task failed with exception
Traceback (most recent call last):
  File "/home/airflow/.local/lib/python3.12/site-packages/airflow/models/taskinstance.py", line 767, in _execute_task
    result = _execute_callable(context=context, **execute_callable_kwargs)
             ^^^^^^^^^^^^^^^^^^^^^^^^^^^^^^^^^^^^^^^^^^^^^^^^^^^^^^^^^^^^^
  File "/home/airflow/.local/lib/python3.12/site-packages/airflow/models/taskinstance.py", line 733, in _execute_callable
    return ExecutionCallableRunner(
           ^^^^^^^^^^^^^^^^^^^^^^^^
  File "/home/airflow/.local/lib/python3.12/site-packages/airflow/utils/operator_helpers.py", line 252, in run
    return self.func(*args, **kwargs)
           ^^^^^^^^^^^^^^^^^^^^^^^^^^
  File "/home/airflow/.local/lib/python3.12/site-packages/airflow/models/baseoperator.py", line 406, in wrapper
    return func(self, *args, **kwargs)
           ^^^^^^^^^^^^^^^^^^^^^^^^^^^
  File "/home/airflow/.local/lib/python3.12/site-packages/airflow/operators/python.py", line 238, in execute
    return_value = self.execute_callable()
                   ^^^^^^^^^^^^^^^^^^^^^^^
  File "/home/airflow/.local/lib/python3.12/site-packages/airflow/operators/python.py", line 256, in execute_callable
    return runner.run(*self.op_args, **self.op_kwargs)
           ^^^^^^^^^^^^^^^^^^^^^^^^^^^^^^^^^^^^^^^^^^^
  File "/home/airflow/.local/lib/python3.12/site-packages/airflow/utils/operator_helpers.py", line 252, in run
    return self.func(*args, **kwargs)
           ^^^^^^^^^^^^^^^^^^^^^^^^^^
  File "/opt/airflow/dags/dag.py", line 69, in create_table
    hook.run(create_table_query)
  File "/home/airflow/.local/lib/python3.12/site-packages/airflow/providers/common/sql/hooks/sql.py", line 452, in run
    with self._create_autocommit_connection(autocommit) as conn:
         ^^^^^^^^^^^^^^^^^^^^^^^^^^^^^^^^^^^^^^^^^^^^^^
  File "/usr/local/lib/python3.12/contextlib.py", line 137, in __enter__
    return next(self.gen)
           ^^^^^^^^^^^^^^
  File "/home/airflow/.local/lib/python3.12/site-packages/airflow/providers/common/sql/hooks/sql.py", line 574, in _create_autocommit_connection
    with closing(self.get_conn()) as conn:
                 ^^^^^^^^^^^^^^^
  File "/home/airflow/.local/lib/python3.12/site-packages/airflow/providers/postgres/hooks/postgres.py", line 146, in get_conn
    conn = deepcopy(self.connection or self.get_connection(conn_id))
                                       ^^^^^^^^^^^^^^^^^^^^^^^^^^^^
  File "/home/airflow/.local/lib/python3.12/site-packages/airflow/hooks/base.py", line 83, in get_connection
    conn = Connection.get_connection_from_secrets(conn_id)
           ^^^^^^^^^^^^^^^^^^^^^^^^^^^^^^^^^^^^^^^^^^^^^^^
  File "/home/airflow/.local/lib/python3.12/site-packages/airflow/models/connection.py", line 537, in get_connection_from_secrets
    raise AirflowNotFoundException(f"The conn_id `{conn_id}` isn't defined")
airflow.exceptions.AirflowNotFoundException: The conn_id `my_postgres` isn't defined
[2024-09-26T21:45:15.448+0000] {logging_mixin.py:190} INFO - Task instance in failure state
[2024-09-26T21:45:15.464+0000] {logging_mixin.py:190} INFO - Task start:2024-09-26 21:45:13.467119+00:00 end:2024-09-26 21:45:15.446555+00:00 duration:1.979436
[2024-09-26T21:45:15.468+0000] {logging_mixin.py:190} INFO - Task:<Task(PythonOperator): create_table> dag:<DAG: fetch_and_save_share_prices> dagrun:<DagRun fetch_and_save_share_prices @ 2023-09-27 00:00:00+00:00: scheduled__2023-09-27T00:00:00+00:00, state:running, queued_at: 2024-09-26 21:39:50.840530+00:00. externally triggered: False>
[2024-09-26T21:45:15.479+0000] {logging_mixin.py:190} INFO - Failure caused by The conn_id `my_postgres` isn't defined
[2024-09-26T21:45:15.498+0000] {taskinstance.py:1225} INFO - Marking task as FAILED. dag_id=fetch_and_save_share_prices, task_id=create_table, run_id=scheduled__2023-09-27T00:00:00+00:00, execution_date=20230927T000000, start_date=20240926T214513, end_date=20240926T214515
[2024-09-26T21:45:15.733+0000] {taskinstance.py:340} INFO - ::group::Post task execution logs
[2024-09-26T21:45:15.777+0000] {standard_task_runner.py:124} ERROR - Failed to execute job 272 for task create_table (The conn_id `my_postgres` isn't defined; 3211)
Traceback (most recent call last):
  File "/home/airflow/.local/lib/python3.12/site-packages/airflow/task/task_runner/standard_task_runner.py", line 117, in _start_by_fork
    ret = args.func(args, dag=self.dag)
          ^^^^^^^^^^^^^^^^^^^^^^^^^^^^^
  File "/home/airflow/.local/lib/python3.12/site-packages/airflow/cli/cli_config.py", line 49, in command
    return func(*args, **kwargs)
           ^^^^^^^^^^^^^^^^^^^^^
  File "/home/airflow/.local/lib/python3.12/site-packages/airflow/utils/cli.py", line 115, in wrapper
    return f(*args, **kwargs)
           ^^^^^^^^^^^^^^^^^^
  File "/home/airflow/.local/lib/python3.12/site-packages/airflow/cli/commands/task_command.py", line 483, in task_run
    task_return_code = _run_task_by_selected_method(args, _dag, ti)
                       ^^^^^^^^^^^^^^^^^^^^^^^^^^^^^^^^^^^^^^^^^^^^
  File "/home/airflow/.local/lib/python3.12/site-packages/airflow/cli/commands/task_command.py", line 256, in _run_task_by_selected_method
    return _run_raw_task(args, ti)
           ^^^^^^^^^^^^^^^^^^^^^^^
  File "/home/airflow/.local/lib/python3.12/site-packages/airflow/cli/commands/task_command.py", line 341, in _run_raw_task
    return ti._run_raw_task(
           ^^^^^^^^^^^^^^^^^
  File "/home/airflow/.local/lib/python3.12/site-packages/airflow/utils/session.py", line 97, in wrapper
    return func(*args, session=session, **kwargs)
           ^^^^^^^^^^^^^^^^^^^^^^^^^^^^^^^^^^^^^^
  File "/home/airflow/.local/lib/python3.12/site-packages/airflow/models/taskinstance.py", line 3004, in _run_raw_task
    return _run_raw_task(
           ^^^^^^^^^^^^^^
  File "/home/airflow/.local/lib/python3.12/site-packages/airflow/models/taskinstance.py", line 273, in _run_raw_task
    TaskInstance._execute_task_with_callbacks(
  File "/home/airflow/.local/lib/python3.12/site-packages/airflow/models/taskinstance.py", line 3158, in _execute_task_with_callbacks
    result = self._execute_task(context, task_orig)
             ^^^^^^^^^^^^^^^^^^^^^^^^^^^^^^^^^^^^^^
  File "/home/airflow/.local/lib/python3.12/site-packages/airflow/models/taskinstance.py", line 3182, in _execute_task
    return _execute_task(self, context, task_orig)
           ^^^^^^^^^^^^^^^^^^^^^^^^^^^^^^^^^^^^^^^
  File "/home/airflow/.local/lib/python3.12/site-packages/airflow/models/taskinstance.py", line 767, in _execute_task
    result = _execute_callable(context=context, **execute_callable_kwargs)
             ^^^^^^^^^^^^^^^^^^^^^^^^^^^^^^^^^^^^^^^^^^^^^^^^^^^^^^^^^^^^^
  File "/home/airflow/.local/lib/python3.12/site-packages/airflow/models/taskinstance.py", line 733, in _execute_callable
    return ExecutionCallableRunner(
           ^^^^^^^^^^^^^^^^^^^^^^^^
  File "/home/airflow/.local/lib/python3.12/site-packages/airflow/utils/operator_helpers.py", line 252, in run
    return self.func(*args, **kwargs)
           ^^^^^^^^^^^^^^^^^^^^^^^^^^
  File "/home/airflow/.local/lib/python3.12/site-packages/airflow/models/baseoperator.py", line 406, in wrapper
    return func(self, *args, **kwargs)
           ^^^^^^^^^^^^^^^^^^^^^^^^^^^
  File "/home/airflow/.local/lib/python3.12/site-packages/airflow/operators/python.py", line 238, in execute
    return_value = self.execute_callable()
                   ^^^^^^^^^^^^^^^^^^^^^^^
  File "/home/airflow/.local/lib/python3.12/site-packages/airflow/operators/python.py", line 256, in execute_callable
    return runner.run(*self.op_args, **self.op_kwargs)
           ^^^^^^^^^^^^^^^^^^^^^^^^^^^^^^^^^^^^^^^^^^^
  File "/home/airflow/.local/lib/python3.12/site-packages/airflow/utils/operator_helpers.py", line 252, in run
    return self.func(*args, **kwargs)
           ^^^^^^^^^^^^^^^^^^^^^^^^^^
  File "/opt/airflow/dags/dag.py", line 69, in create_table
    hook.run(create_table_query)
  File "/home/airflow/.local/lib/python3.12/site-packages/airflow/providers/common/sql/hooks/sql.py", line 452, in run
    with self._create_autocommit_connection(autocommit) as conn:
         ^^^^^^^^^^^^^^^^^^^^^^^^^^^^^^^^^^^^^^^^^^^^^^
  File "/usr/local/lib/python3.12/contextlib.py", line 137, in __enter__
    return next(self.gen)
           ^^^^^^^^^^^^^^
  File "/home/airflow/.local/lib/python3.12/site-packages/airflow/providers/common/sql/hooks/sql.py", line 574, in _create_autocommit_connection
    with closing(self.get_conn()) as conn:
                 ^^^^^^^^^^^^^^^
  File "/home/airflow/.local/lib/python3.12/site-packages/airflow/providers/postgres/hooks/postgres.py", line 146, in get_conn
    conn = deepcopy(self.connection or self.get_connection(conn_id))
                                       ^^^^^^^^^^^^^^^^^^^^^^^^^^^^
  File "/home/airflow/.local/lib/python3.12/site-packages/airflow/hooks/base.py", line 83, in get_connection
    conn = Connection.get_connection_from_secrets(conn_id)
           ^^^^^^^^^^^^^^^^^^^^^^^^^^^^^^^^^^^^^^^^^^^^^^^
  File "/home/airflow/.local/lib/python3.12/site-packages/airflow/models/connection.py", line 537, in get_connection_from_secrets
    raise AirflowNotFoundException(f"The conn_id `{conn_id}` isn't defined")
airflow.exceptions.AirflowNotFoundException: The conn_id `my_postgres` isn't defined
[2024-09-26T21:45:15.978+0000] {local_task_job_runner.py:266} INFO - Task exited with return code 1
[2024-09-26T21:45:16.127+0000] {taskinstance.py:3900} INFO - 0 downstream tasks scheduled from follow-on schedule check
[2024-09-26T21:45:16.162+0000] {local_task_job_runner.py:245} INFO - ::endgroup::
[2024-09-26T21:53:07.597+0000] {local_task_job_runner.py:123} INFO - ::group::Pre task execution logs
[2024-09-26T21:53:07.651+0000] {taskinstance.py:2612} INFO - Dependencies all met for dep_context=non-requeueable deps ti=<TaskInstance: fetch_and_save_share_prices.create_table scheduled__2023-09-27T00:00:00+00:00 [queued]>
[2024-09-26T21:53:07.677+0000] {taskinstance.py:2612} INFO - Dependencies all met for dep_context=requeueable deps ti=<TaskInstance: fetch_and_save_share_prices.create_table scheduled__2023-09-27T00:00:00+00:00 [queued]>
[2024-09-26T21:53:07.678+0000] {taskinstance.py:2865} INFO - Starting attempt 2 of 2
[2024-09-26T21:53:07.987+0000] {taskinstance.py:2888} INFO - Executing <Task(PythonOperator): create_table> on 2023-09-27 00:00:00+00:00
[2024-09-26T21:53:08.000+0000] {warnings.py:112} WARNING - /home/***/.local/lib/python3.12/site-packages/***/task/task_runner/standard_task_runner.py:70: DeprecationWarning: This process (pid=3461) is multi-threaded, use of fork() may lead to deadlocks in the child.
  pid = os.fork()

[2024-09-26T21:53:08.010+0000] {standard_task_runner.py:72} INFO - Started process 3472 to run task
[2024-09-26T21:53:08.016+0000] {standard_task_runner.py:104} INFO - Running: ['***', 'tasks', 'run', 'fetch_and_save_share_prices', 'create_table', 'scheduled__2023-09-27T00:00:00+00:00', '--job-id', '318', '--raw', '--subdir', 'DAGS_FOLDER/dag.py', '--cfg-path', '/tmp/tmpxvecjeeg']
[2024-09-26T21:53:08.024+0000] {standard_task_runner.py:105} INFO - Job 318: Subtask create_table
[2024-09-26T21:53:08.324+0000] {task_command.py:467} INFO - Running <TaskInstance: fetch_and_save_share_prices.create_table scheduled__2023-09-27T00:00:00+00:00 [running]> on host 13b5797a93ab
[2024-09-26T21:53:08.723+0000] {taskinstance.py:3131} INFO - Exporting env vars: AIRFLOW_CTX_DAG_OWNER='***' AIRFLOW_CTX_DAG_ID='fetch_and_save_share_prices' AIRFLOW_CTX_TASK_ID='create_table' AIRFLOW_CTX_EXECUTION_DATE='2023-09-27T00:00:00+00:00' AIRFLOW_CTX_TRY_NUMBER='2' AIRFLOW_CTX_DAG_RUN_ID='scheduled__2023-09-27T00:00:00+00:00'
[2024-09-26T21:53:08.734+0000] {logging_mixin.py:190} INFO - Task instance is in running state
[2024-09-26T21:53:08.735+0000] {logging_mixin.py:190} INFO -  Previous state of the Task instance: queued
[2024-09-26T21:53:08.736+0000] {logging_mixin.py:190} INFO - Current task name:create_table state:running start_date:2024-09-26 21:53:07.652420+00:00
[2024-09-26T21:53:08.737+0000] {logging_mixin.py:190} INFO - Dag name:fetch_and_save_share_prices and current dag run status:running
[2024-09-26T21:53:08.738+0000] {taskinstance.py:731} INFO - ::endgroup::
[2024-09-26T21:53:08.772+0000] {base.py:84} INFO - Retrieving connection 'dse_connection'
[2024-09-26T21:53:08.799+0000] {sql.py:509} INFO - Running statement: 
        CREATE TABLE IF NOT EXISTS company_share_prices (
            id SERIAL,
            company_id INTEGER NOT NULL,
            date DATE,
            latest_trading_price VARCHAR(50),
            low_price VARCHAR(50),
            high_price VARCHAR(50),
            closing_price VARCHAR(50),
            ycp VARCHAR(50),
            change VARCHAR(10),
            trade VARCHAR(50),
            value VARCHAR(50),
            volume VARCHAR(50),
            PRIMARY KEY(company_id, id),
            FOREIGN KEY(company_id)
                REFERENCES company_list(company_id)
                ON UPDATE CASCADE ON DELETE CASCADE
        );
    , parameters: None
[2024-09-26T21:53:08.824+0000] {taskinstance.py:3310} ERROR - Task failed with exception
Traceback (most recent call last):
  File "/home/airflow/.local/lib/python3.12/site-packages/airflow/models/taskinstance.py", line 767, in _execute_task
    result = _execute_callable(context=context, **execute_callable_kwargs)
             ^^^^^^^^^^^^^^^^^^^^^^^^^^^^^^^^^^^^^^^^^^^^^^^^^^^^^^^^^^^^^
  File "/home/airflow/.local/lib/python3.12/site-packages/airflow/models/taskinstance.py", line 733, in _execute_callable
    return ExecutionCallableRunner(
           ^^^^^^^^^^^^^^^^^^^^^^^^
  File "/home/airflow/.local/lib/python3.12/site-packages/airflow/utils/operator_helpers.py", line 252, in run
    return self.func(*args, **kwargs)
           ^^^^^^^^^^^^^^^^^^^^^^^^^^
  File "/home/airflow/.local/lib/python3.12/site-packages/airflow/models/baseoperator.py", line 406, in wrapper
    return func(self, *args, **kwargs)
           ^^^^^^^^^^^^^^^^^^^^^^^^^^^
  File "/home/airflow/.local/lib/python3.12/site-packages/airflow/operators/python.py", line 238, in execute
    return_value = self.execute_callable()
                   ^^^^^^^^^^^^^^^^^^^^^^^
  File "/home/airflow/.local/lib/python3.12/site-packages/airflow/operators/python.py", line 256, in execute_callable
    return runner.run(*self.op_args, **self.op_kwargs)
           ^^^^^^^^^^^^^^^^^^^^^^^^^^^^^^^^^^^^^^^^^^^
  File "/home/airflow/.local/lib/python3.12/site-packages/airflow/utils/operator_helpers.py", line 252, in run
    return self.func(*args, **kwargs)
           ^^^^^^^^^^^^^^^^^^^^^^^^^^
  File "/opt/airflow/dags/dag.py", line 69, in create_table
    hook.run(create_table_query)
  File "/home/airflow/.local/lib/python3.12/site-packages/airflow/providers/common/sql/hooks/sql.py", line 456, in run
    self._run_command(cur, sql_statement, parameters)
  File "/home/airflow/.local/lib/python3.12/site-packages/airflow/providers/common/sql/hooks/sql.py", line 514, in _run_command
    cur.execute(sql_statement)
psycopg2.errors.UndefinedTable: relation "company_list" does not exist

[2024-09-26T21:53:08.885+0000] {logging_mixin.py:190} INFO - Task instance in failure state
[2024-09-26T21:53:08.886+0000] {logging_mixin.py:190} INFO - Task start:2024-09-26 21:53:07.652420+00:00 end:2024-09-26 21:53:08.884210+00:00 duration:1.23179
[2024-09-26T21:53:08.887+0000] {logging_mixin.py:190} INFO - Task:<Task(PythonOperator): create_table> dag:<DAG: fetch_and_save_share_prices> dagrun:<DagRun fetch_and_save_share_prices @ 2023-09-27 00:00:00+00:00: scheduled__2023-09-27T00:00:00+00:00, state:running, queued_at: 2024-09-26 21:47:47.720815+00:00. externally triggered: False>
[2024-09-26T21:53:08.888+0000] {logging_mixin.py:190} INFO - Failure caused by relation "company_list" does not exist
[2024-09-26T21:53:08.892+0000] {taskinstance.py:1225} INFO - Marking task as FAILED. dag_id=fetch_and_save_share_prices, task_id=create_table, run_id=scheduled__2023-09-27T00:00:00+00:00, execution_date=20230927T000000, start_date=20240926T215307, end_date=20240926T215308
[2024-09-26T21:53:08.926+0000] {taskinstance.py:340} INFO - ::group::Post task execution logs
[2024-09-26T21:53:08.942+0000] {standard_task_runner.py:124} ERROR - Failed to execute job 318 for task create_table (relation "company_list" does not exist
; 3472)
Traceback (most recent call last):
  File "/home/airflow/.local/lib/python3.12/site-packages/airflow/task/task_runner/standard_task_runner.py", line 117, in _start_by_fork
    ret = args.func(args, dag=self.dag)
          ^^^^^^^^^^^^^^^^^^^^^^^^^^^^^
  File "/home/airflow/.local/lib/python3.12/site-packages/airflow/cli/cli_config.py", line 49, in command
    return func(*args, **kwargs)
           ^^^^^^^^^^^^^^^^^^^^^
  File "/home/airflow/.local/lib/python3.12/site-packages/airflow/utils/cli.py", line 115, in wrapper
    return f(*args, **kwargs)
           ^^^^^^^^^^^^^^^^^^
  File "/home/airflow/.local/lib/python3.12/site-packages/airflow/cli/commands/task_command.py", line 483, in task_run
    task_return_code = _run_task_by_selected_method(args, _dag, ti)
                       ^^^^^^^^^^^^^^^^^^^^^^^^^^^^^^^^^^^^^^^^^^^^
  File "/home/airflow/.local/lib/python3.12/site-packages/airflow/cli/commands/task_command.py", line 256, in _run_task_by_selected_method
    return _run_raw_task(args, ti)
           ^^^^^^^^^^^^^^^^^^^^^^^
  File "/home/airflow/.local/lib/python3.12/site-packages/airflow/cli/commands/task_command.py", line 341, in _run_raw_task
    return ti._run_raw_task(
           ^^^^^^^^^^^^^^^^^
  File "/home/airflow/.local/lib/python3.12/site-packages/airflow/utils/session.py", line 97, in wrapper
    return func(*args, session=session, **kwargs)
           ^^^^^^^^^^^^^^^^^^^^^^^^^^^^^^^^^^^^^^
  File "/home/airflow/.local/lib/python3.12/site-packages/airflow/models/taskinstance.py", line 3004, in _run_raw_task
    return _run_raw_task(
           ^^^^^^^^^^^^^^
  File "/home/airflow/.local/lib/python3.12/site-packages/airflow/models/taskinstance.py", line 273, in _run_raw_task
    TaskInstance._execute_task_with_callbacks(
  File "/home/airflow/.local/lib/python3.12/site-packages/airflow/models/taskinstance.py", line 3158, in _execute_task_with_callbacks
    result = self._execute_task(context, task_orig)
             ^^^^^^^^^^^^^^^^^^^^^^^^^^^^^^^^^^^^^^
  File "/home/airflow/.local/lib/python3.12/site-packages/airflow/models/taskinstance.py", line 3182, in _execute_task
    return _execute_task(self, context, task_orig)
           ^^^^^^^^^^^^^^^^^^^^^^^^^^^^^^^^^^^^^^^
  File "/home/airflow/.local/lib/python3.12/site-packages/airflow/models/taskinstance.py", line 767, in _execute_task
    result = _execute_callable(context=context, **execute_callable_kwargs)
             ^^^^^^^^^^^^^^^^^^^^^^^^^^^^^^^^^^^^^^^^^^^^^^^^^^^^^^^^^^^^^
  File "/home/airflow/.local/lib/python3.12/site-packages/airflow/models/taskinstance.py", line 733, in _execute_callable
    return ExecutionCallableRunner(
           ^^^^^^^^^^^^^^^^^^^^^^^^
  File "/home/airflow/.local/lib/python3.12/site-packages/airflow/utils/operator_helpers.py", line 252, in run
    return self.func(*args, **kwargs)
           ^^^^^^^^^^^^^^^^^^^^^^^^^^
  File "/home/airflow/.local/lib/python3.12/site-packages/airflow/models/baseoperator.py", line 406, in wrapper
    return func(self, *args, **kwargs)
           ^^^^^^^^^^^^^^^^^^^^^^^^^^^
  File "/home/airflow/.local/lib/python3.12/site-packages/airflow/operators/python.py", line 238, in execute
    return_value = self.execute_callable()
                   ^^^^^^^^^^^^^^^^^^^^^^^
  File "/home/airflow/.local/lib/python3.12/site-packages/airflow/operators/python.py", line 256, in execute_callable
    return runner.run(*self.op_args, **self.op_kwargs)
           ^^^^^^^^^^^^^^^^^^^^^^^^^^^^^^^^^^^^^^^^^^^
  File "/home/airflow/.local/lib/python3.12/site-packages/airflow/utils/operator_helpers.py", line 252, in run
    return self.func(*args, **kwargs)
           ^^^^^^^^^^^^^^^^^^^^^^^^^^
  File "/opt/airflow/dags/dag.py", line 69, in create_table
    hook.run(create_table_query)
  File "/home/airflow/.local/lib/python3.12/site-packages/airflow/providers/common/sql/hooks/sql.py", line 456, in run
    self._run_command(cur, sql_statement, parameters)
  File "/home/airflow/.local/lib/python3.12/site-packages/airflow/providers/common/sql/hooks/sql.py", line 514, in _run_command
    cur.execute(sql_statement)
psycopg2.errors.UndefinedTable: relation "company_list" does not exist

[2024-09-26T21:53:09.006+0000] {local_task_job_runner.py:266} INFO - Task exited with return code 1
[2024-09-26T21:53:09.090+0000] {taskinstance.py:3900} INFO - 0 downstream tasks scheduled from follow-on schedule check
[2024-09-26T21:53:09.102+0000] {local_task_job_runner.py:245} INFO - ::endgroup::
[2024-09-26T21:59:59.454+0000] {local_task_job_runner.py:123} INFO - ::group::Pre task execution logs
[2024-09-26T21:59:59.494+0000] {taskinstance.py:2612} INFO - Dependencies all met for dep_context=non-requeueable deps ti=<TaskInstance: fetch_and_save_share_prices.create_table scheduled__2023-09-27T00:00:00+00:00 [queued]>
[2024-09-26T21:59:59.511+0000] {taskinstance.py:2612} INFO - Dependencies all met for dep_context=requeueable deps ti=<TaskInstance: fetch_and_save_share_prices.create_table scheduled__2023-09-27T00:00:00+00:00 [queued]>
[2024-09-26T21:59:59.512+0000] {taskinstance.py:2865} INFO - Starting attempt 2 of 2
[2024-09-26T21:59:59.711+0000] {taskinstance.py:2888} INFO - Executing <Task(PythonOperator): create_table> on 2023-09-27 00:00:00+00:00
[2024-09-26T21:59:59.727+0000] {warnings.py:112} WARNING - /home/***/.local/lib/python3.12/site-packages/***/task/task_runner/standard_task_runner.py:70: DeprecationWarning: This process (pid=3740) is multi-threaded, use of fork() may lead to deadlocks in the child.
  pid = os.fork()

[2024-09-26T21:59:59.731+0000] {standard_task_runner.py:72} INFO - Started process 3756 to run task
[2024-09-26T21:59:59.735+0000] {standard_task_runner.py:104} INFO - Running: ['***', 'tasks', 'run', 'fetch_and_save_share_prices', 'create_table', 'scheduled__2023-09-27T00:00:00+00:00', '--job-id', '367', '--raw', '--subdir', 'DAGS_FOLDER/dag.py', '--cfg-path', '/tmp/tmpi25cu3qs']
[2024-09-26T21:59:59.738+0000] {standard_task_runner.py:105} INFO - Job 367: Subtask create_table
[2024-09-26T21:59:59.846+0000] {task_command.py:467} INFO - Running <TaskInstance: fetch_and_save_share_prices.create_table scheduled__2023-09-27T00:00:00+00:00 [running]> on host 13b5797a93ab
[2024-09-26T22:00:00.079+0000] {taskinstance.py:3131} INFO - Exporting env vars: AIRFLOW_CTX_DAG_OWNER='***' AIRFLOW_CTX_DAG_ID='fetch_and_save_share_prices' AIRFLOW_CTX_TASK_ID='create_table' AIRFLOW_CTX_EXECUTION_DATE='2023-09-27T00:00:00+00:00' AIRFLOW_CTX_TRY_NUMBER='2' AIRFLOW_CTX_DAG_RUN_ID='scheduled__2023-09-27T00:00:00+00:00'
[2024-09-26T22:00:00.084+0000] {logging_mixin.py:190} INFO - Task instance is in running state
[2024-09-26T22:00:00.085+0000] {logging_mixin.py:190} INFO -  Previous state of the Task instance: queued
[2024-09-26T22:00:00.086+0000] {logging_mixin.py:190} INFO - Current task name:create_table state:running start_date:2024-09-26 21:59:59.495557+00:00
[2024-09-26T22:00:00.087+0000] {logging_mixin.py:190} INFO - Dag name:fetch_and_save_share_prices and current dag run status:running
[2024-09-26T22:00:00.091+0000] {taskinstance.py:731} INFO - ::endgroup::
[2024-09-26T22:00:00.112+0000] {base.py:84} INFO - Retrieving connection 'dse_connection'
[2024-09-26T22:00:00.122+0000] {sql.py:509} INFO - Running statement: 
        CREATE TABLE IF NOT EXISTS company_share_prices (
            id SERIAL,
            company_id INTEGER NOT NULL,
            date DATE,
            latest_trading_price VARCHAR(50),
            low_price VARCHAR(50),
            high_price VARCHAR(50),
            closing_price VARCHAR(50),
            ycp VARCHAR(50),
            change VARCHAR(10),
            trade VARCHAR(50),
            value VARCHAR(50),
            volume VARCHAR(50),
            PRIMARY KEY(company_id, id),
            FOREIGN KEY(company_id)
                REFERENCES company_list(company_id)
                ON UPDATE CASCADE ON DELETE CASCADE
        );
    , parameters: None
[2024-09-26T22:00:00.138+0000] {taskinstance.py:3310} ERROR - Task failed with exception
Traceback (most recent call last):
  File "/home/airflow/.local/lib/python3.12/site-packages/airflow/models/taskinstance.py", line 767, in _execute_task
    result = _execute_callable(context=context, **execute_callable_kwargs)
             ^^^^^^^^^^^^^^^^^^^^^^^^^^^^^^^^^^^^^^^^^^^^^^^^^^^^^^^^^^^^^
  File "/home/airflow/.local/lib/python3.12/site-packages/airflow/models/taskinstance.py", line 733, in _execute_callable
    return ExecutionCallableRunner(
           ^^^^^^^^^^^^^^^^^^^^^^^^
  File "/home/airflow/.local/lib/python3.12/site-packages/airflow/utils/operator_helpers.py", line 252, in run
    return self.func(*args, **kwargs)
           ^^^^^^^^^^^^^^^^^^^^^^^^^^
  File "/home/airflow/.local/lib/python3.12/site-packages/airflow/models/baseoperator.py", line 406, in wrapper
    return func(self, *args, **kwargs)
           ^^^^^^^^^^^^^^^^^^^^^^^^^^^
  File "/home/airflow/.local/lib/python3.12/site-packages/airflow/operators/python.py", line 238, in execute
    return_value = self.execute_callable()
                   ^^^^^^^^^^^^^^^^^^^^^^^
  File "/home/airflow/.local/lib/python3.12/site-packages/airflow/operators/python.py", line 256, in execute_callable
    return runner.run(*self.op_args, **self.op_kwargs)
           ^^^^^^^^^^^^^^^^^^^^^^^^^^^^^^^^^^^^^^^^^^^
  File "/home/airflow/.local/lib/python3.12/site-packages/airflow/utils/operator_helpers.py", line 252, in run
    return self.func(*args, **kwargs)
           ^^^^^^^^^^^^^^^^^^^^^^^^^^
  File "/opt/airflow/dags/dag.py", line 69, in create_table
    hook.run(create_table_query)
  File "/home/airflow/.local/lib/python3.12/site-packages/airflow/providers/common/sql/hooks/sql.py", line 456, in run
    self._run_command(cur, sql_statement, parameters)
  File "/home/airflow/.local/lib/python3.12/site-packages/airflow/providers/common/sql/hooks/sql.py", line 514, in _run_command
    cur.execute(sql_statement)
psycopg2.errors.UndefinedTable: relation "company_list" does not exist

[2024-09-26T22:00:00.172+0000] {logging_mixin.py:190} INFO - Task instance in failure state
[2024-09-26T22:00:00.174+0000] {logging_mixin.py:190} INFO - Task start:2024-09-26 21:59:59.495557+00:00 end:2024-09-26 22:00:00.171706+00:00 duration:0.676149
[2024-09-26T22:00:00.175+0000] {logging_mixin.py:190} INFO - Task:<Task(PythonOperator): create_table> dag:<DAG: fetch_and_save_share_prices> dagrun:<DagRun fetch_and_save_share_prices @ 2023-09-27 00:00:00+00:00: scheduled__2023-09-27T00:00:00+00:00, state:running, queued_at: 2024-09-26 21:54:46.053883+00:00. externally triggered: False>
[2024-09-26T22:00:00.176+0000] {logging_mixin.py:190} INFO - Failure caused by relation "company_list" does not exist
[2024-09-26T22:00:00.177+0000] {taskinstance.py:1225} INFO - Marking task as FAILED. dag_id=fetch_and_save_share_prices, task_id=create_table, run_id=scheduled__2023-09-27T00:00:00+00:00, execution_date=20230927T000000, start_date=20240926T215959, end_date=20240926T220000
[2024-09-26T22:00:00.203+0000] {taskinstance.py:340} INFO - ::group::Post task execution logs
[2024-09-26T22:00:00.207+0000] {standard_task_runner.py:124} ERROR - Failed to execute job 367 for task create_table (relation "company_list" does not exist
; 3756)
Traceback (most recent call last):
  File "/home/airflow/.local/lib/python3.12/site-packages/airflow/task/task_runner/standard_task_runner.py", line 117, in _start_by_fork
    ret = args.func(args, dag=self.dag)
          ^^^^^^^^^^^^^^^^^^^^^^^^^^^^^
  File "/home/airflow/.local/lib/python3.12/site-packages/airflow/cli/cli_config.py", line 49, in command
    return func(*args, **kwargs)
           ^^^^^^^^^^^^^^^^^^^^^
  File "/home/airflow/.local/lib/python3.12/site-packages/airflow/utils/cli.py", line 115, in wrapper
    return f(*args, **kwargs)
           ^^^^^^^^^^^^^^^^^^
  File "/home/airflow/.local/lib/python3.12/site-packages/airflow/cli/commands/task_command.py", line 483, in task_run
    task_return_code = _run_task_by_selected_method(args, _dag, ti)
                       ^^^^^^^^^^^^^^^^^^^^^^^^^^^^^^^^^^^^^^^^^^^^
  File "/home/airflow/.local/lib/python3.12/site-packages/airflow/cli/commands/task_command.py", line 256, in _run_task_by_selected_method
    return _run_raw_task(args, ti)
           ^^^^^^^^^^^^^^^^^^^^^^^
  File "/home/airflow/.local/lib/python3.12/site-packages/airflow/cli/commands/task_command.py", line 341, in _run_raw_task
    return ti._run_raw_task(
           ^^^^^^^^^^^^^^^^^
  File "/home/airflow/.local/lib/python3.12/site-packages/airflow/utils/session.py", line 97, in wrapper
    return func(*args, session=session, **kwargs)
           ^^^^^^^^^^^^^^^^^^^^^^^^^^^^^^^^^^^^^^
  File "/home/airflow/.local/lib/python3.12/site-packages/airflow/models/taskinstance.py", line 3004, in _run_raw_task
    return _run_raw_task(
           ^^^^^^^^^^^^^^
  File "/home/airflow/.local/lib/python3.12/site-packages/airflow/models/taskinstance.py", line 273, in _run_raw_task
    TaskInstance._execute_task_with_callbacks(
  File "/home/airflow/.local/lib/python3.12/site-packages/airflow/models/taskinstance.py", line 3158, in _execute_task_with_callbacks
    result = self._execute_task(context, task_orig)
             ^^^^^^^^^^^^^^^^^^^^^^^^^^^^^^^^^^^^^^
  File "/home/airflow/.local/lib/python3.12/site-packages/airflow/models/taskinstance.py", line 3182, in _execute_task
    return _execute_task(self, context, task_orig)
           ^^^^^^^^^^^^^^^^^^^^^^^^^^^^^^^^^^^^^^^
  File "/home/airflow/.local/lib/python3.12/site-packages/airflow/models/taskinstance.py", line 767, in _execute_task
    result = _execute_callable(context=context, **execute_callable_kwargs)
             ^^^^^^^^^^^^^^^^^^^^^^^^^^^^^^^^^^^^^^^^^^^^^^^^^^^^^^^^^^^^^
  File "/home/airflow/.local/lib/python3.12/site-packages/airflow/models/taskinstance.py", line 733, in _execute_callable
    return ExecutionCallableRunner(
           ^^^^^^^^^^^^^^^^^^^^^^^^
  File "/home/airflow/.local/lib/python3.12/site-packages/airflow/utils/operator_helpers.py", line 252, in run
    return self.func(*args, **kwargs)
           ^^^^^^^^^^^^^^^^^^^^^^^^^^
  File "/home/airflow/.local/lib/python3.12/site-packages/airflow/models/baseoperator.py", line 406, in wrapper
    return func(self, *args, **kwargs)
           ^^^^^^^^^^^^^^^^^^^^^^^^^^^
  File "/home/airflow/.local/lib/python3.12/site-packages/airflow/operators/python.py", line 238, in execute
    return_value = self.execute_callable()
                   ^^^^^^^^^^^^^^^^^^^^^^^
  File "/home/airflow/.local/lib/python3.12/site-packages/airflow/operators/python.py", line 256, in execute_callable
    return runner.run(*self.op_args, **self.op_kwargs)
           ^^^^^^^^^^^^^^^^^^^^^^^^^^^^^^^^^^^^^^^^^^^
  File "/home/airflow/.local/lib/python3.12/site-packages/airflow/utils/operator_helpers.py", line 252, in run
    return self.func(*args, **kwargs)
           ^^^^^^^^^^^^^^^^^^^^^^^^^^
  File "/opt/airflow/dags/dag.py", line 69, in create_table
    hook.run(create_table_query)
  File "/home/airflow/.local/lib/python3.12/site-packages/airflow/providers/common/sql/hooks/sql.py", line 456, in run
    self._run_command(cur, sql_statement, parameters)
  File "/home/airflow/.local/lib/python3.12/site-packages/airflow/providers/common/sql/hooks/sql.py", line 514, in _run_command
    cur.execute(sql_statement)
psycopg2.errors.UndefinedTable: relation "company_list" does not exist

[2024-09-26T22:00:00.277+0000] {local_task_job_runner.py:266} INFO - Task exited with return code 1
[2024-09-26T22:00:00.336+0000] {taskinstance.py:3900} INFO - 0 downstream tasks scheduled from follow-on schedule check
[2024-09-26T22:00:00.347+0000] {local_task_job_runner.py:245} INFO - ::endgroup::
