[2024-09-26T20:58:08.609+0000] {local_task_job_runner.py:123} INFO - ::group::Pre task execution logs
[2024-09-26T20:58:09.093+0000] {taskinstance.py:2612} INFO - Dependencies all met for dep_context=non-requeueable deps ti=<TaskInstance: fetch_and_save_share_prices.create_table scheduled__2023-10-01T00:00:00+00:00 [queued]>
[2024-09-26T20:58:09.152+0000] {taskinstance.py:2612} INFO - Dependencies all met for dep_context=requeueable deps ti=<TaskInstance: fetch_and_save_share_prices.create_table scheduled__2023-10-01T00:00:00+00:00 [queued]>
[2024-09-26T20:58:09.160+0000] {taskinstance.py:2865} INFO - Starting attempt 1 of 2
[2024-09-26T20:58:09.341+0000] {taskinstance.py:2888} INFO - Executing <Task(PythonOperator): create_table> on 2023-10-01 00:00:00+00:00
[2024-09-26T20:58:09.682+0000] {warnings.py:112} WARNING - /home/***/.local/lib/python3.12/site-packages/***/task/task_runner/standard_task_runner.py:70: DeprecationWarning: This process (pid=1582) is multi-threaded, use of fork() may lead to deadlocks in the child.
  pid = os.fork()

[2024-09-26T20:58:10.110+0000] {standard_task_runner.py:72} INFO - Started process 1617 to run task
[2024-09-26T20:58:10.149+0000] {standard_task_runner.py:104} INFO - Running: ['***', 'tasks', 'run', 'fetch_and_save_share_prices', 'create_table', 'scheduled__2023-10-01T00:00:00+00:00', '--job-id', '18', '--raw', '--subdir', 'DAGS_FOLDER/dag.py', '--cfg-path', '/tmp/tmpp1e5xjyx']
[2024-09-26T20:58:10.204+0000] {standard_task_runner.py:105} INFO - Job 18: Subtask create_table
[2024-09-26T20:58:11.957+0000] {task_command.py:467} INFO - Running <TaskInstance: fetch_and_save_share_prices.create_table scheduled__2023-10-01T00:00:00+00:00 [running]> on host 13b5797a93ab
[2024-09-26T20:58:13.016+0000] {taskinstance.py:3131} INFO - Exporting env vars: AIRFLOW_CTX_DAG_OWNER='***' AIRFLOW_CTX_DAG_ID='fetch_and_save_share_prices' AIRFLOW_CTX_TASK_ID='create_table' AIRFLOW_CTX_EXECUTION_DATE='2023-10-01T00:00:00+00:00' AIRFLOW_CTX_TRY_NUMBER='1' AIRFLOW_CTX_DAG_RUN_ID='scheduled__2023-10-01T00:00:00+00:00'
[2024-09-26T20:58:13.055+0000] {logging_mixin.py:190} INFO - Task instance is in running state
[2024-09-26T20:58:13.066+0000] {logging_mixin.py:190} INFO -  Previous state of the Task instance: queued
[2024-09-26T20:58:13.074+0000] {logging_mixin.py:190} INFO - Current task name:create_table state:running start_date:2024-09-26 20:58:09.110564+00:00
[2024-09-26T20:58:13.087+0000] {logging_mixin.py:190} INFO - Dag name:fetch_and_save_share_prices and current dag run status:running
[2024-09-26T20:58:13.100+0000] {taskinstance.py:731} INFO - ::endgroup::
[2024-09-26T20:58:13.736+0000] {taskinstance.py:3310} ERROR - Task failed with exception
Traceback (most recent call last):
  File "/home/airflow/.local/lib/python3.12/site-packages/airflow/models/taskinstance.py", line 767, in _execute_task
    result = _execute_callable(context=context, **execute_callable_kwargs)
             ^^^^^^^^^^^^^^^^^^^^^^^^^^^^^^^^^^^^^^^^^^^^^^^^^^^^^^^^^^^^^
  File "/home/airflow/.local/lib/python3.12/site-packages/airflow/models/taskinstance.py", line 733, in _execute_callable
    return ExecutionCallableRunner(
           ^^^^^^^^^^^^^^^^^^^^^^^^
  File "/home/airflow/.local/lib/python3.12/site-packages/airflow/utils/operator_helpers.py", line 252, in run
    return self.func(*args, **kwargs)
           ^^^^^^^^^^^^^^^^^^^^^^^^^^
  File "/home/airflow/.local/lib/python3.12/site-packages/airflow/models/baseoperator.py", line 406, in wrapper
    return func(self, *args, **kwargs)
           ^^^^^^^^^^^^^^^^^^^^^^^^^^^
  File "/home/airflow/.local/lib/python3.12/site-packages/airflow/operators/python.py", line 238, in execute
    return_value = self.execute_callable()
                   ^^^^^^^^^^^^^^^^^^^^^^^
  File "/home/airflow/.local/lib/python3.12/site-packages/airflow/operators/python.py", line 256, in execute_callable
    return runner.run(*self.op_args, **self.op_kwargs)
           ^^^^^^^^^^^^^^^^^^^^^^^^^^^^^^^^^^^^^^^^^^^
  File "/home/airflow/.local/lib/python3.12/site-packages/airflow/utils/operator_helpers.py", line 252, in run
    return self.func(*args, **kwargs)
           ^^^^^^^^^^^^^^^^^^^^^^^^^^
  File "/opt/airflow/dags/dag.py", line 69, in create_table
    hook.run(create_table_query)
  File "/home/airflow/.local/lib/python3.12/site-packages/airflow/providers/common/sql/hooks/sql.py", line 452, in run
    with self._create_autocommit_connection(autocommit) as conn:
         ^^^^^^^^^^^^^^^^^^^^^^^^^^^^^^^^^^^^^^^^^^^^^^
  File "/usr/local/lib/python3.12/contextlib.py", line 137, in __enter__
    return next(self.gen)
           ^^^^^^^^^^^^^^
  File "/home/airflow/.local/lib/python3.12/site-packages/airflow/providers/common/sql/hooks/sql.py", line 574, in _create_autocommit_connection
    with closing(self.get_conn()) as conn:
                 ^^^^^^^^^^^^^^^
  File "/home/airflow/.local/lib/python3.12/site-packages/airflow/providers/postgres/hooks/postgres.py", line 146, in get_conn
    conn = deepcopy(self.connection or self.get_connection(conn_id))
                                       ^^^^^^^^^^^^^^^^^^^^^^^^^^^^
  File "/home/airflow/.local/lib/python3.12/site-packages/airflow/hooks/base.py", line 83, in get_connection
    conn = Connection.get_connection_from_secrets(conn_id)
           ^^^^^^^^^^^^^^^^^^^^^^^^^^^^^^^^^^^^^^^^^^^^^^^
  File "/home/airflow/.local/lib/python3.12/site-packages/airflow/models/connection.py", line 537, in get_connection_from_secrets
    raise AirflowNotFoundException(f"The conn_id `{conn_id}` isn't defined")
airflow.exceptions.AirflowNotFoundException: The conn_id `my_postgres` isn't defined
[2024-09-26T20:58:14.399+0000] {logging_mixin.py:190} INFO - Task instance in failure state
[2024-09-26T20:58:14.417+0000] {logging_mixin.py:190} INFO - Task start:2024-09-26 20:58:09.110564+00:00 end:2024-09-26 20:58:14.250199+00:00 duration:5.139635
[2024-09-26T20:58:14.471+0000] {logging_mixin.py:190} INFO - Task:<Task(PythonOperator): create_table> dag:<DAG: fetch_and_save_share_prices> dagrun:<DagRun fetch_and_save_share_prices @ 2023-10-01 00:00:00+00:00: scheduled__2023-10-01T00:00:00+00:00, state:running, queued_at: 2024-09-26 20:57:25.584096+00:00. externally triggered: False>
[2024-09-26T20:58:14.520+0000] {logging_mixin.py:190} INFO - Failure caused by The conn_id `my_postgres` isn't defined
[2024-09-26T20:58:14.539+0000] {taskinstance.py:1225} INFO - Marking task as UP_FOR_RETRY. dag_id=fetch_and_save_share_prices, task_id=create_table, run_id=scheduled__2023-10-01T00:00:00+00:00, execution_date=20231001T000000, start_date=20240926T205809, end_date=20240926T205814
[2024-09-26T20:58:14.743+0000] {taskinstance.py:340} INFO - ::group::Post task execution logs
[2024-09-26T20:58:14.746+0000] {standard_task_runner.py:124} ERROR - Failed to execute job 18 for task create_table (The conn_id `my_postgres` isn't defined; 1617)
Traceback (most recent call last):
  File "/home/airflow/.local/lib/python3.12/site-packages/airflow/task/task_runner/standard_task_runner.py", line 117, in _start_by_fork
    ret = args.func(args, dag=self.dag)
          ^^^^^^^^^^^^^^^^^^^^^^^^^^^^^
  File "/home/airflow/.local/lib/python3.12/site-packages/airflow/cli/cli_config.py", line 49, in command
    return func(*args, **kwargs)
           ^^^^^^^^^^^^^^^^^^^^^
  File "/home/airflow/.local/lib/python3.12/site-packages/airflow/utils/cli.py", line 115, in wrapper
    return f(*args, **kwargs)
           ^^^^^^^^^^^^^^^^^^
  File "/home/airflow/.local/lib/python3.12/site-packages/airflow/cli/commands/task_command.py", line 483, in task_run
    task_return_code = _run_task_by_selected_method(args, _dag, ti)
                       ^^^^^^^^^^^^^^^^^^^^^^^^^^^^^^^^^^^^^^^^^^^^
  File "/home/airflow/.local/lib/python3.12/site-packages/airflow/cli/commands/task_command.py", line 256, in _run_task_by_selected_method
    return _run_raw_task(args, ti)
           ^^^^^^^^^^^^^^^^^^^^^^^
  File "/home/airflow/.local/lib/python3.12/site-packages/airflow/cli/commands/task_command.py", line 341, in _run_raw_task
    return ti._run_raw_task(
           ^^^^^^^^^^^^^^^^^
  File "/home/airflow/.local/lib/python3.12/site-packages/airflow/utils/session.py", line 97, in wrapper
    return func(*args, session=session, **kwargs)
           ^^^^^^^^^^^^^^^^^^^^^^^^^^^^^^^^^^^^^^
  File "/home/airflow/.local/lib/python3.12/site-packages/airflow/models/taskinstance.py", line 3004, in _run_raw_task
    return _run_raw_task(
           ^^^^^^^^^^^^^^
  File "/home/airflow/.local/lib/python3.12/site-packages/airflow/models/taskinstance.py", line 273, in _run_raw_task
    TaskInstance._execute_task_with_callbacks(
  File "/home/airflow/.local/lib/python3.12/site-packages/airflow/models/taskinstance.py", line 3158, in _execute_task_with_callbacks
    result = self._execute_task(context, task_orig)
             ^^^^^^^^^^^^^^^^^^^^^^^^^^^^^^^^^^^^^^
  File "/home/airflow/.local/lib/python3.12/site-packages/airflow/models/taskinstance.py", line 3182, in _execute_task
    return _execute_task(self, context, task_orig)
           ^^^^^^^^^^^^^^^^^^^^^^^^^^^^^^^^^^^^^^^
  File "/home/airflow/.local/lib/python3.12/site-packages/airflow/models/taskinstance.py", line 767, in _execute_task
    result = _execute_callable(context=context, **execute_callable_kwargs)
             ^^^^^^^^^^^^^^^^^^^^^^^^^^^^^^^^^^^^^^^^^^^^^^^^^^^^^^^^^^^^^
  File "/home/airflow/.local/lib/python3.12/site-packages/airflow/models/taskinstance.py", line 733, in _execute_callable
    return ExecutionCallableRunner(
           ^^^^^^^^^^^^^^^^^^^^^^^^
  File "/home/airflow/.local/lib/python3.12/site-packages/airflow/utils/operator_helpers.py", line 252, in run
    return self.func(*args, **kwargs)
           ^^^^^^^^^^^^^^^^^^^^^^^^^^
  File "/home/airflow/.local/lib/python3.12/site-packages/airflow/models/baseoperator.py", line 406, in wrapper
    return func(self, *args, **kwargs)
           ^^^^^^^^^^^^^^^^^^^^^^^^^^^
  File "/home/airflow/.local/lib/python3.12/site-packages/airflow/operators/python.py", line 238, in execute
    return_value = self.execute_callable()
                   ^^^^^^^^^^^^^^^^^^^^^^^
  File "/home/airflow/.local/lib/python3.12/site-packages/airflow/operators/python.py", line 256, in execute_callable
    return runner.run(*self.op_args, **self.op_kwargs)
           ^^^^^^^^^^^^^^^^^^^^^^^^^^^^^^^^^^^^^^^^^^^
  File "/home/airflow/.local/lib/python3.12/site-packages/airflow/utils/operator_helpers.py", line 252, in run
    return self.func(*args, **kwargs)
           ^^^^^^^^^^^^^^^^^^^^^^^^^^
  File "/opt/airflow/dags/dag.py", line 69, in create_table
    hook.run(create_table_query)
  File "/home/airflow/.local/lib/python3.12/site-packages/airflow/providers/common/sql/hooks/sql.py", line 452, in run
    with self._create_autocommit_connection(autocommit) as conn:
         ^^^^^^^^^^^^^^^^^^^^^^^^^^^^^^^^^^^^^^^^^^^^^^
  File "/usr/local/lib/python3.12/contextlib.py", line 137, in __enter__
    return next(self.gen)
           ^^^^^^^^^^^^^^
  File "/home/airflow/.local/lib/python3.12/site-packages/airflow/providers/common/sql/hooks/sql.py", line 574, in _create_autocommit_connection
    with closing(self.get_conn()) as conn:
                 ^^^^^^^^^^^^^^^
  File "/home/airflow/.local/lib/python3.12/site-packages/airflow/providers/postgres/hooks/postgres.py", line 146, in get_conn
    conn = deepcopy(self.connection or self.get_connection(conn_id))
                                       ^^^^^^^^^^^^^^^^^^^^^^^^^^^^
  File "/home/airflow/.local/lib/python3.12/site-packages/airflow/hooks/base.py", line 83, in get_connection
    conn = Connection.get_connection_from_secrets(conn_id)
           ^^^^^^^^^^^^^^^^^^^^^^^^^^^^^^^^^^^^^^^^^^^^^^^
  File "/home/airflow/.local/lib/python3.12/site-packages/airflow/models/connection.py", line 537, in get_connection_from_secrets
    raise AirflowNotFoundException(f"The conn_id `{conn_id}` isn't defined")
airflow.exceptions.AirflowNotFoundException: The conn_id `my_postgres` isn't defined
[2024-09-26T20:58:15.002+0000] {local_task_job_runner.py:266} INFO - Task exited with return code 1
[2024-09-26T20:58:15.275+0000] {standard_task_runner.py:217} INFO - Process not found (most likely exited), stop collecting metrics
[2024-09-26T20:58:15.290+0000] {taskinstance.py:3900} INFO - 0 downstream tasks scheduled from follow-on schedule check
[2024-09-26T20:58:15.340+0000] {local_task_job_runner.py:245} INFO - ::endgroup::
[2024-09-26T21:40:05.094+0000] {local_task_job_runner.py:123} INFO - ::group::Pre task execution logs
[2024-09-26T21:40:05.226+0000] {taskinstance.py:2612} INFO - Dependencies all met for dep_context=non-requeueable deps ti=<TaskInstance: fetch_and_save_share_prices.create_table scheduled__2023-10-01T00:00:00+00:00 [queued]>
[2024-09-26T21:40:05.250+0000] {taskinstance.py:2612} INFO - Dependencies all met for dep_context=requeueable deps ti=<TaskInstance: fetch_and_save_share_prices.create_table scheduled__2023-10-01T00:00:00+00:00 [queued]>
[2024-09-26T21:40:05.257+0000] {taskinstance.py:2865} INFO - Starting attempt 1 of 2
[2024-09-26T21:40:05.637+0000] {taskinstance.py:2888} INFO - Executing <Task(PythonOperator): create_table> on 2023-10-01 00:00:00+00:00
[2024-09-26T21:40:05.671+0000] {standard_task_runner.py:104} INFO - Running: ['***', 'tasks', 'run', 'fetch_and_save_share_prices', 'create_table', 'scheduled__2023-10-01T00:00:00+00:00', '--job-id', '259', '--raw', '--subdir', 'DAGS_FOLDER/dag.py', '--cfg-path', '/tmp/tmpbqan6bb_']
[2024-09-26T21:40:05.683+0000] {warnings.py:112} WARNING - /home/***/.local/lib/python3.12/site-packages/***/task/task_runner/standard_task_runner.py:70: DeprecationWarning: This process (pid=3060) is multi-threaded, use of fork() may lead to deadlocks in the child.
  pid = os.fork()

[2024-09-26T21:40:05.733+0000] {standard_task_runner.py:72} INFO - Started process 3092 to run task
[2024-09-26T21:40:05.721+0000] {standard_task_runner.py:105} INFO - Job 259: Subtask create_table
[2024-09-26T21:40:05.985+0000] {task_command.py:467} INFO - Running <TaskInstance: fetch_and_save_share_prices.create_table scheduled__2023-10-01T00:00:00+00:00 [running]> on host 13b5797a93ab
[2024-09-26T21:40:06.936+0000] {taskinstance.py:3131} INFO - Exporting env vars: AIRFLOW_CTX_DAG_OWNER='***' AIRFLOW_CTX_DAG_ID='fetch_and_save_share_prices' AIRFLOW_CTX_TASK_ID='create_table' AIRFLOW_CTX_EXECUTION_DATE='2023-10-01T00:00:00+00:00' AIRFLOW_CTX_TRY_NUMBER='1' AIRFLOW_CTX_DAG_RUN_ID='scheduled__2023-10-01T00:00:00+00:00'
[2024-09-26T21:40:06.941+0000] {logging_mixin.py:190} INFO - Task instance is in running state
[2024-09-26T21:40:06.943+0000] {logging_mixin.py:190} INFO -  Previous state of the Task instance: queued
[2024-09-26T21:40:06.945+0000] {logging_mixin.py:190} INFO - Current task name:create_table state:running start_date:2024-09-26 21:40:05.228626+00:00
[2024-09-26T21:40:06.946+0000] {logging_mixin.py:190} INFO - Dag name:fetch_and_save_share_prices and current dag run status:running
[2024-09-26T21:40:06.952+0000] {taskinstance.py:731} INFO - ::endgroup::
[2024-09-26T21:40:07.200+0000] {taskinstance.py:3310} ERROR - Task failed with exception
Traceback (most recent call last):
  File "/home/airflow/.local/lib/python3.12/site-packages/airflow/models/taskinstance.py", line 767, in _execute_task
    result = _execute_callable(context=context, **execute_callable_kwargs)
             ^^^^^^^^^^^^^^^^^^^^^^^^^^^^^^^^^^^^^^^^^^^^^^^^^^^^^^^^^^^^^
  File "/home/airflow/.local/lib/python3.12/site-packages/airflow/models/taskinstance.py", line 733, in _execute_callable
    return ExecutionCallableRunner(
           ^^^^^^^^^^^^^^^^^^^^^^^^
  File "/home/airflow/.local/lib/python3.12/site-packages/airflow/utils/operator_helpers.py", line 252, in run
    return self.func(*args, **kwargs)
           ^^^^^^^^^^^^^^^^^^^^^^^^^^
  File "/home/airflow/.local/lib/python3.12/site-packages/airflow/models/baseoperator.py", line 406, in wrapper
    return func(self, *args, **kwargs)
           ^^^^^^^^^^^^^^^^^^^^^^^^^^^
  File "/home/airflow/.local/lib/python3.12/site-packages/airflow/operators/python.py", line 238, in execute
    return_value = self.execute_callable()
                   ^^^^^^^^^^^^^^^^^^^^^^^
  File "/home/airflow/.local/lib/python3.12/site-packages/airflow/operators/python.py", line 256, in execute_callable
    return runner.run(*self.op_args, **self.op_kwargs)
           ^^^^^^^^^^^^^^^^^^^^^^^^^^^^^^^^^^^^^^^^^^^
  File "/home/airflow/.local/lib/python3.12/site-packages/airflow/utils/operator_helpers.py", line 252, in run
    return self.func(*args, **kwargs)
           ^^^^^^^^^^^^^^^^^^^^^^^^^^
  File "/opt/airflow/dags/dag.py", line 69, in create_table
    hook.run(create_table_query)
  File "/home/airflow/.local/lib/python3.12/site-packages/airflow/providers/common/sql/hooks/sql.py", line 452, in run
    with self._create_autocommit_connection(autocommit) as conn:
         ^^^^^^^^^^^^^^^^^^^^^^^^^^^^^^^^^^^^^^^^^^^^^^
  File "/usr/local/lib/python3.12/contextlib.py", line 137, in __enter__
    return next(self.gen)
           ^^^^^^^^^^^^^^
  File "/home/airflow/.local/lib/python3.12/site-packages/airflow/providers/common/sql/hooks/sql.py", line 574, in _create_autocommit_connection
    with closing(self.get_conn()) as conn:
                 ^^^^^^^^^^^^^^^
  File "/home/airflow/.local/lib/python3.12/site-packages/airflow/providers/postgres/hooks/postgres.py", line 146, in get_conn
    conn = deepcopy(self.connection or self.get_connection(conn_id))
                                       ^^^^^^^^^^^^^^^^^^^^^^^^^^^^
  File "/home/airflow/.local/lib/python3.12/site-packages/airflow/hooks/base.py", line 83, in get_connection
    conn = Connection.get_connection_from_secrets(conn_id)
           ^^^^^^^^^^^^^^^^^^^^^^^^^^^^^^^^^^^^^^^^^^^^^^^
  File "/home/airflow/.local/lib/python3.12/site-packages/airflow/models/connection.py", line 537, in get_connection_from_secrets
    raise AirflowNotFoundException(f"The conn_id `{conn_id}` isn't defined")
airflow.exceptions.AirflowNotFoundException: The conn_id `my_postgres` isn't defined
[2024-09-26T21:40:07.314+0000] {logging_mixin.py:190} INFO - Task instance in failure state
[2024-09-26T21:40:07.316+0000] {logging_mixin.py:190} INFO - Task start:2024-09-26 21:40:05.228626+00:00 end:2024-09-26 21:40:07.313362+00:00 duration:2.084736
[2024-09-26T21:40:07.317+0000] {logging_mixin.py:190} INFO - Task:<Task(PythonOperator): create_table> dag:<DAG: fetch_and_save_share_prices> dagrun:<DagRun fetch_and_save_share_prices @ 2023-10-01 00:00:00+00:00: scheduled__2023-10-01T00:00:00+00:00, state:running, queued_at: 2024-09-26 21:39:52.627758+00:00. externally triggered: False>
[2024-09-26T21:40:07.318+0000] {logging_mixin.py:190} INFO - Failure caused by The conn_id `my_postgres` isn't defined
[2024-09-26T21:40:07.319+0000] {taskinstance.py:1225} INFO - Marking task as UP_FOR_RETRY. dag_id=fetch_and_save_share_prices, task_id=create_table, run_id=scheduled__2023-10-01T00:00:00+00:00, execution_date=20231001T000000, start_date=20240926T214005, end_date=20240926T214007
[2024-09-26T21:40:07.444+0000] {taskinstance.py:340} INFO - ::group::Post task execution logs
[2024-09-26T21:40:07.455+0000] {standard_task_runner.py:124} ERROR - Failed to execute job 259 for task create_table (The conn_id `my_postgres` isn't defined; 3092)
Traceback (most recent call last):
  File "/home/airflow/.local/lib/python3.12/site-packages/airflow/task/task_runner/standard_task_runner.py", line 117, in _start_by_fork
    ret = args.func(args, dag=self.dag)
          ^^^^^^^^^^^^^^^^^^^^^^^^^^^^^
  File "/home/airflow/.local/lib/python3.12/site-packages/airflow/cli/cli_config.py", line 49, in command
    return func(*args, **kwargs)
           ^^^^^^^^^^^^^^^^^^^^^
  File "/home/airflow/.local/lib/python3.12/site-packages/airflow/utils/cli.py", line 115, in wrapper
    return f(*args, **kwargs)
           ^^^^^^^^^^^^^^^^^^
  File "/home/airflow/.local/lib/python3.12/site-packages/airflow/cli/commands/task_command.py", line 483, in task_run
    task_return_code = _run_task_by_selected_method(args, _dag, ti)
                       ^^^^^^^^^^^^^^^^^^^^^^^^^^^^^^^^^^^^^^^^^^^^
  File "/home/airflow/.local/lib/python3.12/site-packages/airflow/cli/commands/task_command.py", line 256, in _run_task_by_selected_method
    return _run_raw_task(args, ti)
           ^^^^^^^^^^^^^^^^^^^^^^^
  File "/home/airflow/.local/lib/python3.12/site-packages/airflow/cli/commands/task_command.py", line 341, in _run_raw_task
    return ti._run_raw_task(
           ^^^^^^^^^^^^^^^^^
  File "/home/airflow/.local/lib/python3.12/site-packages/airflow/utils/session.py", line 97, in wrapper
    return func(*args, session=session, **kwargs)
           ^^^^^^^^^^^^^^^^^^^^^^^^^^^^^^^^^^^^^^
  File "/home/airflow/.local/lib/python3.12/site-packages/airflow/models/taskinstance.py", line 3004, in _run_raw_task
    return _run_raw_task(
           ^^^^^^^^^^^^^^
  File "/home/airflow/.local/lib/python3.12/site-packages/airflow/models/taskinstance.py", line 273, in _run_raw_task
    TaskInstance._execute_task_with_callbacks(
  File "/home/airflow/.local/lib/python3.12/site-packages/airflow/models/taskinstance.py", line 3158, in _execute_task_with_callbacks
    result = self._execute_task(context, task_orig)
             ^^^^^^^^^^^^^^^^^^^^^^^^^^^^^^^^^^^^^^
  File "/home/airflow/.local/lib/python3.12/site-packages/airflow/models/taskinstance.py", line 3182, in _execute_task
    return _execute_task(self, context, task_orig)
           ^^^^^^^^^^^^^^^^^^^^^^^^^^^^^^^^^^^^^^^
  File "/home/airflow/.local/lib/python3.12/site-packages/airflow/models/taskinstance.py", line 767, in _execute_task
    result = _execute_callable(context=context, **execute_callable_kwargs)
             ^^^^^^^^^^^^^^^^^^^^^^^^^^^^^^^^^^^^^^^^^^^^^^^^^^^^^^^^^^^^^
  File "/home/airflow/.local/lib/python3.12/site-packages/airflow/models/taskinstance.py", line 733, in _execute_callable
    return ExecutionCallableRunner(
           ^^^^^^^^^^^^^^^^^^^^^^^^
  File "/home/airflow/.local/lib/python3.12/site-packages/airflow/utils/operator_helpers.py", line 252, in run
    return self.func(*args, **kwargs)
           ^^^^^^^^^^^^^^^^^^^^^^^^^^
  File "/home/airflow/.local/lib/python3.12/site-packages/airflow/models/baseoperator.py", line 406, in wrapper
    return func(self, *args, **kwargs)
           ^^^^^^^^^^^^^^^^^^^^^^^^^^^
  File "/home/airflow/.local/lib/python3.12/site-packages/airflow/operators/python.py", line 238, in execute
    return_value = self.execute_callable()
                   ^^^^^^^^^^^^^^^^^^^^^^^
  File "/home/airflow/.local/lib/python3.12/site-packages/airflow/operators/python.py", line 256, in execute_callable
    return runner.run(*self.op_args, **self.op_kwargs)
           ^^^^^^^^^^^^^^^^^^^^^^^^^^^^^^^^^^^^^^^^^^^
  File "/home/airflow/.local/lib/python3.12/site-packages/airflow/utils/operator_helpers.py", line 252, in run
    return self.func(*args, **kwargs)
           ^^^^^^^^^^^^^^^^^^^^^^^^^^
  File "/opt/airflow/dags/dag.py", line 69, in create_table
    hook.run(create_table_query)
  File "/home/airflow/.local/lib/python3.12/site-packages/airflow/providers/common/sql/hooks/sql.py", line 452, in run
    with self._create_autocommit_connection(autocommit) as conn:
         ^^^^^^^^^^^^^^^^^^^^^^^^^^^^^^^^^^^^^^^^^^^^^^
  File "/usr/local/lib/python3.12/contextlib.py", line 137, in __enter__
    return next(self.gen)
           ^^^^^^^^^^^^^^
  File "/home/airflow/.local/lib/python3.12/site-packages/airflow/providers/common/sql/hooks/sql.py", line 574, in _create_autocommit_connection
    with closing(self.get_conn()) as conn:
                 ^^^^^^^^^^^^^^^
  File "/home/airflow/.local/lib/python3.12/site-packages/airflow/providers/postgres/hooks/postgres.py", line 146, in get_conn
    conn = deepcopy(self.connection or self.get_connection(conn_id))
                                       ^^^^^^^^^^^^^^^^^^^^^^^^^^^^
  File "/home/airflow/.local/lib/python3.12/site-packages/airflow/hooks/base.py", line 83, in get_connection
    conn = Connection.get_connection_from_secrets(conn_id)
           ^^^^^^^^^^^^^^^^^^^^^^^^^^^^^^^^^^^^^^^^^^^^^^^
  File "/home/airflow/.local/lib/python3.12/site-packages/airflow/models/connection.py", line 537, in get_connection_from_secrets
    raise AirflowNotFoundException(f"The conn_id `{conn_id}` isn't defined")
airflow.exceptions.AirflowNotFoundException: The conn_id `my_postgres` isn't defined
[2024-09-26T21:40:07.596+0000] {local_task_job_runner.py:266} INFO - Task exited with return code 1
[2024-09-26T21:40:07.747+0000] {taskinstance.py:3900} INFO - 0 downstream tasks scheduled from follow-on schedule check
[2024-09-26T21:40:07.764+0000] {local_task_job_runner.py:245} INFO - ::endgroup::
[2024-09-26T21:48:05.687+0000] {local_task_job_runner.py:123} INFO - ::group::Pre task execution logs
[2024-09-26T21:48:05.797+0000] {taskinstance.py:2612} INFO - Dependencies all met for dep_context=non-requeueable deps ti=<TaskInstance: fetch_and_save_share_prices.create_table scheduled__2023-10-01T00:00:00+00:00 [queued]>
[2024-09-26T21:48:05.849+0000] {taskinstance.py:2612} INFO - Dependencies all met for dep_context=requeueable deps ti=<TaskInstance: fetch_and_save_share_prices.create_table scheduled__2023-10-01T00:00:00+00:00 [queued]>
[2024-09-26T21:48:05.850+0000] {taskinstance.py:2865} INFO - Starting attempt 1 of 2
[2024-09-26T21:48:05.926+0000] {taskinstance.py:2888} INFO - Executing <Task(PythonOperator): create_table> on 2023-10-01 00:00:00+00:00
[2024-09-26T21:48:05.961+0000] {warnings.py:112} WARNING - /home/***/.local/lib/python3.12/site-packages/***/task/task_runner/standard_task_runner.py:70: DeprecationWarning: This process (pid=3344) is multi-threaded, use of fork() may lead to deadlocks in the child.
  pid = os.fork()

[2024-09-26T21:48:05.995+0000] {standard_task_runner.py:72} INFO - Started process 3376 to run task
[2024-09-26T21:48:05.999+0000] {standard_task_runner.py:104} INFO - Running: ['***', 'tasks', 'run', 'fetch_and_save_share_prices', 'create_table', 'scheduled__2023-10-01T00:00:00+00:00', '--job-id', '307', '--raw', '--subdir', 'DAGS_FOLDER/dag.py', '--cfg-path', '/tmp/tmp0a7khi32']
[2024-09-26T21:48:06.014+0000] {standard_task_runner.py:105} INFO - Job 307: Subtask create_table
[2024-09-26T21:48:06.391+0000] {task_command.py:467} INFO - Running <TaskInstance: fetch_and_save_share_prices.create_table scheduled__2023-10-01T00:00:00+00:00 [running]> on host 13b5797a93ab
[2024-09-26T21:48:07.126+0000] {taskinstance.py:3131} INFO - Exporting env vars: AIRFLOW_CTX_DAG_OWNER='***' AIRFLOW_CTX_DAG_ID='fetch_and_save_share_prices' AIRFLOW_CTX_TASK_ID='create_table' AIRFLOW_CTX_EXECUTION_DATE='2023-10-01T00:00:00+00:00' AIRFLOW_CTX_TRY_NUMBER='1' AIRFLOW_CTX_DAG_RUN_ID='scheduled__2023-10-01T00:00:00+00:00'
[2024-09-26T21:48:07.147+0000] {logging_mixin.py:190} INFO - Task instance is in running state
[2024-09-26T21:48:07.149+0000] {logging_mixin.py:190} INFO -  Previous state of the Task instance: queued
[2024-09-26T21:48:07.151+0000] {logging_mixin.py:190} INFO - Current task name:create_table state:running start_date:2024-09-26 21:48:05.805781+00:00
[2024-09-26T21:48:07.163+0000] {logging_mixin.py:190} INFO - Dag name:fetch_and_save_share_prices and current dag run status:running
[2024-09-26T21:48:07.166+0000] {taskinstance.py:731} INFO - ::endgroup::
[2024-09-26T21:48:07.245+0000] {base.py:84} INFO - Retrieving connection 'dse_connection'
[2024-09-26T21:48:07.342+0000] {sql.py:509} INFO - Running statement: 
        CREATE TABLE IF NOT EXISTS company_share_prices (
            id SERIAL,
            company_id INTEGER NOT NULL,
            date DATE,
            latest_trading_price VARCHAR(50),
            low_price VARCHAR(50),
            high_price VARCHAR(50),
            closing_price VARCHAR(50),
            ycp VARCHAR(50),
            change VARCHAR(10),
            trade VARCHAR(50),
            value VARCHAR(50),
            volume VARCHAR(50),
            PRIMARY KEY(company_id, id),
            FOREIGN KEY(company_id)
                REFERENCES company_list(company_id)
                ON UPDATE CASCADE ON DELETE CASCADE
        );
    , parameters: None
[2024-09-26T21:48:07.414+0000] {taskinstance.py:3310} ERROR - Task failed with exception
Traceback (most recent call last):
  File "/home/airflow/.local/lib/python3.12/site-packages/airflow/models/taskinstance.py", line 767, in _execute_task
    result = _execute_callable(context=context, **execute_callable_kwargs)
             ^^^^^^^^^^^^^^^^^^^^^^^^^^^^^^^^^^^^^^^^^^^^^^^^^^^^^^^^^^^^^
  File "/home/airflow/.local/lib/python3.12/site-packages/airflow/models/taskinstance.py", line 733, in _execute_callable
    return ExecutionCallableRunner(
           ^^^^^^^^^^^^^^^^^^^^^^^^
  File "/home/airflow/.local/lib/python3.12/site-packages/airflow/utils/operator_helpers.py", line 252, in run
    return self.func(*args, **kwargs)
           ^^^^^^^^^^^^^^^^^^^^^^^^^^
  File "/home/airflow/.local/lib/python3.12/site-packages/airflow/models/baseoperator.py", line 406, in wrapper
    return func(self, *args, **kwargs)
           ^^^^^^^^^^^^^^^^^^^^^^^^^^^
  File "/home/airflow/.local/lib/python3.12/site-packages/airflow/operators/python.py", line 238, in execute
    return_value = self.execute_callable()
                   ^^^^^^^^^^^^^^^^^^^^^^^
  File "/home/airflow/.local/lib/python3.12/site-packages/airflow/operators/python.py", line 256, in execute_callable
    return runner.run(*self.op_args, **self.op_kwargs)
           ^^^^^^^^^^^^^^^^^^^^^^^^^^^^^^^^^^^^^^^^^^^
  File "/home/airflow/.local/lib/python3.12/site-packages/airflow/utils/operator_helpers.py", line 252, in run
    return self.func(*args, **kwargs)
           ^^^^^^^^^^^^^^^^^^^^^^^^^^
  File "/opt/airflow/dags/dag.py", line 69, in create_table
    hook.run(create_table_query)
  File "/home/airflow/.local/lib/python3.12/site-packages/airflow/providers/common/sql/hooks/sql.py", line 456, in run
    self._run_command(cur, sql_statement, parameters)
  File "/home/airflow/.local/lib/python3.12/site-packages/airflow/providers/common/sql/hooks/sql.py", line 514, in _run_command
    cur.execute(sql_statement)
psycopg2.errors.UndefinedTable: relation "company_list" does not exist

[2024-09-26T21:48:07.557+0000] {logging_mixin.py:190} INFO - Task instance in failure state
[2024-09-26T21:48:07.568+0000] {logging_mixin.py:190} INFO - Task start:2024-09-26 21:48:05.805781+00:00 end:2024-09-26 21:48:07.555928+00:00 duration:1.750147
[2024-09-26T21:48:07.570+0000] {logging_mixin.py:190} INFO - Task:<Task(PythonOperator): create_table> dag:<DAG: fetch_and_save_share_prices> dagrun:<DagRun fetch_and_save_share_prices @ 2023-10-01 00:00:00+00:00: scheduled__2023-10-01T00:00:00+00:00, state:running, queued_at: 2024-09-26 21:47:49.143256+00:00. externally triggered: False>
[2024-09-26T21:48:07.573+0000] {logging_mixin.py:190} INFO - Failure caused by relation "company_list" does not exist
[2024-09-26T21:48:07.575+0000] {taskinstance.py:1225} INFO - Marking task as UP_FOR_RETRY. dag_id=fetch_and_save_share_prices, task_id=create_table, run_id=scheduled__2023-10-01T00:00:00+00:00, execution_date=20231001T000000, start_date=20240926T214805, end_date=20240926T214807
[2024-09-26T21:48:07.738+0000] {taskinstance.py:340} INFO - ::group::Post task execution logs
[2024-09-26T21:48:07.744+0000] {standard_task_runner.py:124} ERROR - Failed to execute job 307 for task create_table (relation "company_list" does not exist
; 3376)
Traceback (most recent call last):
  File "/home/airflow/.local/lib/python3.12/site-packages/airflow/task/task_runner/standard_task_runner.py", line 117, in _start_by_fork
    ret = args.func(args, dag=self.dag)
          ^^^^^^^^^^^^^^^^^^^^^^^^^^^^^
  File "/home/airflow/.local/lib/python3.12/site-packages/airflow/cli/cli_config.py", line 49, in command
    return func(*args, **kwargs)
           ^^^^^^^^^^^^^^^^^^^^^
  File "/home/airflow/.local/lib/python3.12/site-packages/airflow/utils/cli.py", line 115, in wrapper
    return f(*args, **kwargs)
           ^^^^^^^^^^^^^^^^^^
  File "/home/airflow/.local/lib/python3.12/site-packages/airflow/cli/commands/task_command.py", line 483, in task_run
    task_return_code = _run_task_by_selected_method(args, _dag, ti)
                       ^^^^^^^^^^^^^^^^^^^^^^^^^^^^^^^^^^^^^^^^^^^^
  File "/home/airflow/.local/lib/python3.12/site-packages/airflow/cli/commands/task_command.py", line 256, in _run_task_by_selected_method
    return _run_raw_task(args, ti)
           ^^^^^^^^^^^^^^^^^^^^^^^
  File "/home/airflow/.local/lib/python3.12/site-packages/airflow/cli/commands/task_command.py", line 341, in _run_raw_task
    return ti._run_raw_task(
           ^^^^^^^^^^^^^^^^^
  File "/home/airflow/.local/lib/python3.12/site-packages/airflow/utils/session.py", line 97, in wrapper
    return func(*args, session=session, **kwargs)
           ^^^^^^^^^^^^^^^^^^^^^^^^^^^^^^^^^^^^^^
  File "/home/airflow/.local/lib/python3.12/site-packages/airflow/models/taskinstance.py", line 3004, in _run_raw_task
    return _run_raw_task(
           ^^^^^^^^^^^^^^
  File "/home/airflow/.local/lib/python3.12/site-packages/airflow/models/taskinstance.py", line 273, in _run_raw_task
    TaskInstance._execute_task_with_callbacks(
  File "/home/airflow/.local/lib/python3.12/site-packages/airflow/models/taskinstance.py", line 3158, in _execute_task_with_callbacks
    result = self._execute_task(context, task_orig)
             ^^^^^^^^^^^^^^^^^^^^^^^^^^^^^^^^^^^^^^
  File "/home/airflow/.local/lib/python3.12/site-packages/airflow/models/taskinstance.py", line 3182, in _execute_task
    return _execute_task(self, context, task_orig)
           ^^^^^^^^^^^^^^^^^^^^^^^^^^^^^^^^^^^^^^^
  File "/home/airflow/.local/lib/python3.12/site-packages/airflow/models/taskinstance.py", line 767, in _execute_task
    result = _execute_callable(context=context, **execute_callable_kwargs)
             ^^^^^^^^^^^^^^^^^^^^^^^^^^^^^^^^^^^^^^^^^^^^^^^^^^^^^^^^^^^^^
  File "/home/airflow/.local/lib/python3.12/site-packages/airflow/models/taskinstance.py", line 733, in _execute_callable
    return ExecutionCallableRunner(
           ^^^^^^^^^^^^^^^^^^^^^^^^
  File "/home/airflow/.local/lib/python3.12/site-packages/airflow/utils/operator_helpers.py", line 252, in run
    return self.func(*args, **kwargs)
           ^^^^^^^^^^^^^^^^^^^^^^^^^^
  File "/home/airflow/.local/lib/python3.12/site-packages/airflow/models/baseoperator.py", line 406, in wrapper
    return func(self, *args, **kwargs)
           ^^^^^^^^^^^^^^^^^^^^^^^^^^^
  File "/home/airflow/.local/lib/python3.12/site-packages/airflow/operators/python.py", line 238, in execute
    return_value = self.execute_callable()
                   ^^^^^^^^^^^^^^^^^^^^^^^
  File "/home/airflow/.local/lib/python3.12/site-packages/airflow/operators/python.py", line 256, in execute_callable
    return runner.run(*self.op_args, **self.op_kwargs)
           ^^^^^^^^^^^^^^^^^^^^^^^^^^^^^^^^^^^^^^^^^^^
  File "/home/airflow/.local/lib/python3.12/site-packages/airflow/utils/operator_helpers.py", line 252, in run
    return self.func(*args, **kwargs)
           ^^^^^^^^^^^^^^^^^^^^^^^^^^
  File "/opt/airflow/dags/dag.py", line 69, in create_table
    hook.run(create_table_query)
  File "/home/airflow/.local/lib/python3.12/site-packages/airflow/providers/common/sql/hooks/sql.py", line 456, in run
    self._run_command(cur, sql_statement, parameters)
  File "/home/airflow/.local/lib/python3.12/site-packages/airflow/providers/common/sql/hooks/sql.py", line 514, in _run_command
    cur.execute(sql_statement)
psycopg2.errors.UndefinedTable: relation "company_list" does not exist

[2024-09-26T21:48:07.894+0000] {local_task_job_runner.py:266} INFO - Task exited with return code 1
[2024-09-26T21:48:08.033+0000] {taskinstance.py:3900} INFO - 0 downstream tasks scheduled from follow-on schedule check
[2024-09-26T21:48:08.052+0000] {local_task_job_runner.py:245} INFO - ::endgroup::
[2024-09-26T21:54:57.617+0000] {local_task_job_runner.py:123} INFO - ::group::Pre task execution logs
[2024-09-26T21:54:57.679+0000] {taskinstance.py:2612} INFO - Dependencies all met for dep_context=non-requeueable deps ti=<TaskInstance: fetch_and_save_share_prices.create_table scheduled__2023-10-01T00:00:00+00:00 [queued]>
[2024-09-26T21:54:57.700+0000] {taskinstance.py:2612} INFO - Dependencies all met for dep_context=requeueable deps ti=<TaskInstance: fetch_and_save_share_prices.create_table scheduled__2023-10-01T00:00:00+00:00 [queued]>
[2024-09-26T21:54:57.709+0000] {taskinstance.py:2865} INFO - Starting attempt 1 of 2
[2024-09-26T21:54:57.845+0000] {taskinstance.py:2888} INFO - Executing <Task(PythonOperator): create_table> on 2023-10-01 00:00:00+00:00
[2024-09-26T21:54:57.870+0000] {warnings.py:112} WARNING - /home/***/.local/lib/python3.12/site-packages/***/task/task_runner/standard_task_runner.py:70: DeprecationWarning: This process (pid=3621) is multi-threaded, use of fork() may lead to deadlocks in the child.
  pid = os.fork()

[2024-09-26T21:54:57.897+0000] {standard_task_runner.py:72} INFO - Started process 3655 to run task
[2024-09-26T21:54:57.948+0000] {standard_task_runner.py:104} INFO - Running: ['***', 'tasks', 'run', 'fetch_and_save_share_prices', 'create_table', 'scheduled__2023-10-01T00:00:00+00:00', '--job-id', '356', '--raw', '--subdir', 'DAGS_FOLDER/dag.py', '--cfg-path', '/tmp/tmpzmzcxk90']
[2024-09-26T21:54:57.954+0000] {standard_task_runner.py:105} INFO - Job 356: Subtask create_table
[2024-09-26T21:54:58.265+0000] {task_command.py:467} INFO - Running <TaskInstance: fetch_and_save_share_prices.create_table scheduled__2023-10-01T00:00:00+00:00 [running]> on host 13b5797a93ab
[2024-09-26T21:54:58.803+0000] {taskinstance.py:3131} INFO - Exporting env vars: AIRFLOW_CTX_DAG_OWNER='***' AIRFLOW_CTX_DAG_ID='fetch_and_save_share_prices' AIRFLOW_CTX_TASK_ID='create_table' AIRFLOW_CTX_EXECUTION_DATE='2023-10-01T00:00:00+00:00' AIRFLOW_CTX_TRY_NUMBER='1' AIRFLOW_CTX_DAG_RUN_ID='scheduled__2023-10-01T00:00:00+00:00'
[2024-09-26T21:54:58.814+0000] {logging_mixin.py:190} INFO - Task instance is in running state
[2024-09-26T21:54:58.826+0000] {logging_mixin.py:190} INFO -  Previous state of the Task instance: queued
[2024-09-26T21:54:58.830+0000] {logging_mixin.py:190} INFO - Current task name:create_table state:running start_date:2024-09-26 21:54:57.681285+00:00
[2024-09-26T21:54:58.831+0000] {logging_mixin.py:190} INFO - Dag name:fetch_and_save_share_prices and current dag run status:running
[2024-09-26T21:54:58.835+0000] {taskinstance.py:731} INFO - ::endgroup::
[2024-09-26T21:54:58.891+0000] {base.py:84} INFO - Retrieving connection 'dse_connection'
[2024-09-26T21:54:58.905+0000] {sql.py:509} INFO - Running statement: 
        CREATE TABLE IF NOT EXISTS company_share_prices (
            id SERIAL,
            company_id INTEGER NOT NULL,
            date DATE,
            latest_trading_price VARCHAR(50),
            low_price VARCHAR(50),
            high_price VARCHAR(50),
            closing_price VARCHAR(50),
            ycp VARCHAR(50),
            change VARCHAR(10),
            trade VARCHAR(50),
            value VARCHAR(50),
            volume VARCHAR(50),
            PRIMARY KEY(company_id, id),
            FOREIGN KEY(company_id)
                REFERENCES company_list(company_id)
                ON UPDATE CASCADE ON DELETE CASCADE
        );
    , parameters: None
[2024-09-26T21:54:58.931+0000] {taskinstance.py:3310} ERROR - Task failed with exception
Traceback (most recent call last):
  File "/home/airflow/.local/lib/python3.12/site-packages/airflow/models/taskinstance.py", line 767, in _execute_task
    result = _execute_callable(context=context, **execute_callable_kwargs)
             ^^^^^^^^^^^^^^^^^^^^^^^^^^^^^^^^^^^^^^^^^^^^^^^^^^^^^^^^^^^^^
  File "/home/airflow/.local/lib/python3.12/site-packages/airflow/models/taskinstance.py", line 733, in _execute_callable
    return ExecutionCallableRunner(
           ^^^^^^^^^^^^^^^^^^^^^^^^
  File "/home/airflow/.local/lib/python3.12/site-packages/airflow/utils/operator_helpers.py", line 252, in run
    return self.func(*args, **kwargs)
           ^^^^^^^^^^^^^^^^^^^^^^^^^^
  File "/home/airflow/.local/lib/python3.12/site-packages/airflow/models/baseoperator.py", line 406, in wrapper
    return func(self, *args, **kwargs)
           ^^^^^^^^^^^^^^^^^^^^^^^^^^^
  File "/home/airflow/.local/lib/python3.12/site-packages/airflow/operators/python.py", line 238, in execute
    return_value = self.execute_callable()
                   ^^^^^^^^^^^^^^^^^^^^^^^
  File "/home/airflow/.local/lib/python3.12/site-packages/airflow/operators/python.py", line 256, in execute_callable
    return runner.run(*self.op_args, **self.op_kwargs)
           ^^^^^^^^^^^^^^^^^^^^^^^^^^^^^^^^^^^^^^^^^^^
  File "/home/airflow/.local/lib/python3.12/site-packages/airflow/utils/operator_helpers.py", line 252, in run
    return self.func(*args, **kwargs)
           ^^^^^^^^^^^^^^^^^^^^^^^^^^
  File "/opt/airflow/dags/dag.py", line 69, in create_table
    hook.run(create_table_query)
  File "/home/airflow/.local/lib/python3.12/site-packages/airflow/providers/common/sql/hooks/sql.py", line 456, in run
    self._run_command(cur, sql_statement, parameters)
  File "/home/airflow/.local/lib/python3.12/site-packages/airflow/providers/common/sql/hooks/sql.py", line 514, in _run_command
    cur.execute(sql_statement)
psycopg2.errors.UndefinedTable: relation "company_list" does not exist

[2024-09-26T21:54:59.086+0000] {logging_mixin.py:190} INFO - Task instance in failure state
[2024-09-26T21:54:59.088+0000] {logging_mixin.py:190} INFO - Task start:2024-09-26 21:54:57.681285+00:00 end:2024-09-26 21:54:59.083916+00:00 duration:1.402631
[2024-09-26T21:54:59.113+0000] {logging_mixin.py:190} INFO - Task:<Task(PythonOperator): create_table> dag:<DAG: fetch_and_save_share_prices> dagrun:<DagRun fetch_and_save_share_prices @ 2023-10-01 00:00:00+00:00: scheduled__2023-10-01T00:00:00+00:00, state:running, queued_at: 2024-09-26 21:54:47.101803+00:00. externally triggered: False>
[2024-09-26T21:54:59.114+0000] {logging_mixin.py:190} INFO - Failure caused by relation "company_list" does not exist
[2024-09-26T21:54:59.116+0000] {taskinstance.py:1225} INFO - Marking task as UP_FOR_RETRY. dag_id=fetch_and_save_share_prices, task_id=create_table, run_id=scheduled__2023-10-01T00:00:00+00:00, execution_date=20231001T000000, start_date=20240926T215457, end_date=20240926T215459
[2024-09-26T21:54:59.264+0000] {taskinstance.py:340} INFO - ::group::Post task execution logs
[2024-09-26T21:54:59.267+0000] {standard_task_runner.py:124} ERROR - Failed to execute job 356 for task create_table (relation "company_list" does not exist
; 3655)
Traceback (most recent call last):
  File "/home/airflow/.local/lib/python3.12/site-packages/airflow/task/task_runner/standard_task_runner.py", line 117, in _start_by_fork
    ret = args.func(args, dag=self.dag)
          ^^^^^^^^^^^^^^^^^^^^^^^^^^^^^
  File "/home/airflow/.local/lib/python3.12/site-packages/airflow/cli/cli_config.py", line 49, in command
    return func(*args, **kwargs)
           ^^^^^^^^^^^^^^^^^^^^^
  File "/home/airflow/.local/lib/python3.12/site-packages/airflow/utils/cli.py", line 115, in wrapper
    return f(*args, **kwargs)
           ^^^^^^^^^^^^^^^^^^
  File "/home/airflow/.local/lib/python3.12/site-packages/airflow/cli/commands/task_command.py", line 483, in task_run
    task_return_code = _run_task_by_selected_method(args, _dag, ti)
                       ^^^^^^^^^^^^^^^^^^^^^^^^^^^^^^^^^^^^^^^^^^^^
  File "/home/airflow/.local/lib/python3.12/site-packages/airflow/cli/commands/task_command.py", line 256, in _run_task_by_selected_method
    return _run_raw_task(args, ti)
           ^^^^^^^^^^^^^^^^^^^^^^^
  File "/home/airflow/.local/lib/python3.12/site-packages/airflow/cli/commands/task_command.py", line 341, in _run_raw_task
    return ti._run_raw_task(
           ^^^^^^^^^^^^^^^^^
  File "/home/airflow/.local/lib/python3.12/site-packages/airflow/utils/session.py", line 97, in wrapper
    return func(*args, session=session, **kwargs)
           ^^^^^^^^^^^^^^^^^^^^^^^^^^^^^^^^^^^^^^
  File "/home/airflow/.local/lib/python3.12/site-packages/airflow/models/taskinstance.py", line 3004, in _run_raw_task
    return _run_raw_task(
           ^^^^^^^^^^^^^^
  File "/home/airflow/.local/lib/python3.12/site-packages/airflow/models/taskinstance.py", line 273, in _run_raw_task
    TaskInstance._execute_task_with_callbacks(
  File "/home/airflow/.local/lib/python3.12/site-packages/airflow/models/taskinstance.py", line 3158, in _execute_task_with_callbacks
    result = self._execute_task(context, task_orig)
             ^^^^^^^^^^^^^^^^^^^^^^^^^^^^^^^^^^^^^^
  File "/home/airflow/.local/lib/python3.12/site-packages/airflow/models/taskinstance.py", line 3182, in _execute_task
    return _execute_task(self, context, task_orig)
           ^^^^^^^^^^^^^^^^^^^^^^^^^^^^^^^^^^^^^^^
  File "/home/airflow/.local/lib/python3.12/site-packages/airflow/models/taskinstance.py", line 767, in _execute_task
    result = _execute_callable(context=context, **execute_callable_kwargs)
             ^^^^^^^^^^^^^^^^^^^^^^^^^^^^^^^^^^^^^^^^^^^^^^^^^^^^^^^^^^^^^
  File "/home/airflow/.local/lib/python3.12/site-packages/airflow/models/taskinstance.py", line 733, in _execute_callable
    return ExecutionCallableRunner(
           ^^^^^^^^^^^^^^^^^^^^^^^^
  File "/home/airflow/.local/lib/python3.12/site-packages/airflow/utils/operator_helpers.py", line 252, in run
    return self.func(*args, **kwargs)
           ^^^^^^^^^^^^^^^^^^^^^^^^^^
  File "/home/airflow/.local/lib/python3.12/site-packages/airflow/models/baseoperator.py", line 406, in wrapper
    return func(self, *args, **kwargs)
           ^^^^^^^^^^^^^^^^^^^^^^^^^^^
  File "/home/airflow/.local/lib/python3.12/site-packages/airflow/operators/python.py", line 238, in execute
    return_value = self.execute_callable()
                   ^^^^^^^^^^^^^^^^^^^^^^^
  File "/home/airflow/.local/lib/python3.12/site-packages/airflow/operators/python.py", line 256, in execute_callable
    return runner.run(*self.op_args, **self.op_kwargs)
           ^^^^^^^^^^^^^^^^^^^^^^^^^^^^^^^^^^^^^^^^^^^
  File "/home/airflow/.local/lib/python3.12/site-packages/airflow/utils/operator_helpers.py", line 252, in run
    return self.func(*args, **kwargs)
           ^^^^^^^^^^^^^^^^^^^^^^^^^^
  File "/opt/airflow/dags/dag.py", line 69, in create_table
    hook.run(create_table_query)
  File "/home/airflow/.local/lib/python3.12/site-packages/airflow/providers/common/sql/hooks/sql.py", line 456, in run
    self._run_command(cur, sql_statement, parameters)
  File "/home/airflow/.local/lib/python3.12/site-packages/airflow/providers/common/sql/hooks/sql.py", line 514, in _run_command
    cur.execute(sql_statement)
psycopg2.errors.UndefinedTable: relation "company_list" does not exist

[2024-09-26T21:54:59.367+0000] {local_task_job_runner.py:266} INFO - Task exited with return code 1
[2024-09-26T21:54:59.507+0000] {taskinstance.py:3900} INFO - 0 downstream tasks scheduled from follow-on schedule check
[2024-09-26T21:54:59.576+0000] {local_task_job_runner.py:245} INFO - ::endgroup::
