[2024-09-27T12:50:44.669+0000] {local_task_job_runner.py:123} INFO - ::group::Pre task execution logs
[2024-09-27T12:50:44.743+0000] {taskinstance.py:2612} INFO - Dependencies all met for dep_context=non-requeueable deps ti=<TaskInstance: fetch_and_save_share_prices.create_table scheduled__2024-06-19T00:00:00+00:00 [queued]>
[2024-09-27T12:50:44.760+0000] {taskinstance.py:2612} INFO - Dependencies all met for dep_context=requeueable deps ti=<TaskInstance: fetch_and_save_share_prices.create_table scheduled__2024-06-19T00:00:00+00:00 [queued]>
[2024-09-27T12:50:44.763+0000] {taskinstance.py:2865} INFO - Starting attempt 2 of 2
[2024-09-27T12:50:44.809+0000] {taskinstance.py:2888} INFO - Executing <Task(PythonOperator): create_table> on 2024-06-19 00:00:00+00:00
[2024-09-27T12:50:44.824+0000] {warnings.py:112} WARNING - /home/***/.local/lib/python3.12/site-packages/***/task/task_runner/standard_task_runner.py:70: DeprecationWarning: This process (pid=6932) is multi-threaded, use of fork() may lead to deadlocks in the child.
  pid = os.fork()

[2024-09-27T12:50:44.827+0000] {standard_task_runner.py:72} INFO - Started process 6951 to run task
[2024-09-27T12:50:44.834+0000] {standard_task_runner.py:104} INFO - Running: ['***', 'tasks', 'run', 'fetch_and_save_share_prices', 'create_table', 'scheduled__2024-06-19T00:00:00+00:00', '--job-id', '893', '--raw', '--subdir', 'DAGS_FOLDER/dag.py', '--cfg-path', '/tmp/tmp5ig4q7_t']
[2024-09-27T12:50:44.839+0000] {standard_task_runner.py:105} INFO - Job 893: Subtask create_table
[2024-09-27T12:50:44.999+0000] {task_command.py:467} INFO - Running <TaskInstance: fetch_and_save_share_prices.create_table scheduled__2024-06-19T00:00:00+00:00 [running]> on host 13b5797a93ab
[2024-09-27T12:50:45.277+0000] {taskinstance.py:3131} INFO - Exporting env vars: AIRFLOW_CTX_DAG_OWNER='***' AIRFLOW_CTX_DAG_ID='fetch_and_save_share_prices' AIRFLOW_CTX_TASK_ID='create_table' AIRFLOW_CTX_EXECUTION_DATE='2024-06-19T00:00:00+00:00' AIRFLOW_CTX_TRY_NUMBER='2' AIRFLOW_CTX_DAG_RUN_ID='scheduled__2024-06-19T00:00:00+00:00'
[2024-09-27T12:50:45.283+0000] {logging_mixin.py:190} INFO - Task instance is in running state
[2024-09-27T12:50:45.284+0000] {logging_mixin.py:190} INFO -  Previous state of the Task instance: queued
[2024-09-27T12:50:45.285+0000] {logging_mixin.py:190} INFO - Current task name:create_table state:running start_date:2024-09-27 12:50:44.744905+00:00
[2024-09-27T12:50:45.286+0000] {logging_mixin.py:190} INFO - Dag name:fetch_and_save_share_prices and current dag run status:running
[2024-09-27T12:50:45.287+0000] {taskinstance.py:731} INFO - ::endgroup::
[2024-09-27T12:50:45.314+0000] {base.py:84} INFO - Retrieving connection 'dse_connection'
[2024-09-27T12:50:45.331+0000] {sql.py:509} INFO - Running statement: 
        CREATE TABLE IF NOT EXISTS company_share_prices (
            id SERIAL,
            company_id INTEGER NOT NULL,
            date DATE,
            latest_trading_price VARCHAR(50),
            low_price VARCHAR(50),
            high_price VARCHAR(50),
            closing_price VARCHAR(50),
            ycp VARCHAR(50),
            change VARCHAR(10),
            trade VARCHAR(50),
            value VARCHAR(50),
            volume VARCHAR(50),
            PRIMARY KEY(company_id, id),
            FOREIGN KEY(company_id)
                REFERENCES company_list(company_id)
                ON UPDATE CASCADE ON DELETE CASCADE
        );
    , parameters: None
[2024-09-27T12:50:45.358+0000] {taskinstance.py:3310} ERROR - Task failed with exception
Traceback (most recent call last):
  File "/home/airflow/.local/lib/python3.12/site-packages/airflow/models/taskinstance.py", line 767, in _execute_task
    result = _execute_callable(context=context, **execute_callable_kwargs)
             ^^^^^^^^^^^^^^^^^^^^^^^^^^^^^^^^^^^^^^^^^^^^^^^^^^^^^^^^^^^^^
  File "/home/airflow/.local/lib/python3.12/site-packages/airflow/models/taskinstance.py", line 733, in _execute_callable
    return ExecutionCallableRunner(
           ^^^^^^^^^^^^^^^^^^^^^^^^
  File "/home/airflow/.local/lib/python3.12/site-packages/airflow/utils/operator_helpers.py", line 252, in run
    return self.func(*args, **kwargs)
           ^^^^^^^^^^^^^^^^^^^^^^^^^^
  File "/home/airflow/.local/lib/python3.12/site-packages/airflow/models/baseoperator.py", line 406, in wrapper
    return func(self, *args, **kwargs)
           ^^^^^^^^^^^^^^^^^^^^^^^^^^^
  File "/home/airflow/.local/lib/python3.12/site-packages/airflow/operators/python.py", line 238, in execute
    return_value = self.execute_callable()
                   ^^^^^^^^^^^^^^^^^^^^^^^
  File "/home/airflow/.local/lib/python3.12/site-packages/airflow/operators/python.py", line 256, in execute_callable
    return runner.run(*self.op_args, **self.op_kwargs)
           ^^^^^^^^^^^^^^^^^^^^^^^^^^^^^^^^^^^^^^^^^^^
  File "/home/airflow/.local/lib/python3.12/site-packages/airflow/utils/operator_helpers.py", line 252, in run
    return self.func(*args, **kwargs)
           ^^^^^^^^^^^^^^^^^^^^^^^^^^
  File "/opt/airflow/dags/dag.py", line 69, in create_table
    hook.run(create_table_query)
  File "/home/airflow/.local/lib/python3.12/site-packages/airflow/providers/common/sql/hooks/sql.py", line 456, in run
    self._run_command(cur, sql_statement, parameters)
  File "/home/airflow/.local/lib/python3.12/site-packages/airflow/providers/common/sql/hooks/sql.py", line 514, in _run_command
    cur.execute(sql_statement)
psycopg2.errors.UndefinedTable: relation "company_list" does not exist

[2024-09-27T12:50:45.409+0000] {logging_mixin.py:190} INFO - Task instance in failure state
[2024-09-27T12:50:45.412+0000] {logging_mixin.py:190} INFO - Task start:2024-09-27 12:50:44.744905+00:00 end:2024-09-27 12:50:45.408245+00:00 duration:0.66334
[2024-09-27T12:50:45.419+0000] {logging_mixin.py:190} INFO - Task:<Task(PythonOperator): create_table> dag:<DAG: fetch_and_save_share_prices> dagrun:<DagRun fetch_and_save_share_prices @ 2024-06-19 00:00:00+00:00: scheduled__2024-06-19T00:00:00+00:00, state:running, queued_at: 2024-09-27 12:45:28.812617+00:00. externally triggered: False>
[2024-09-27T12:50:45.427+0000] {logging_mixin.py:190} INFO - Failure caused by relation "company_list" does not exist
[2024-09-27T12:50:45.440+0000] {taskinstance.py:1225} INFO - Marking task as FAILED. dag_id=fetch_and_save_share_prices, task_id=create_table, run_id=scheduled__2024-06-19T00:00:00+00:00, execution_date=20240619T000000, start_date=20240927T125044, end_date=20240927T125045
[2024-09-27T12:50:45.483+0000] {taskinstance.py:340} INFO - ::group::Post task execution logs
[2024-09-27T12:50:45.498+0000] {standard_task_runner.py:124} ERROR - Failed to execute job 893 for task create_table (relation "company_list" does not exist
; 6951)
Traceback (most recent call last):
  File "/home/airflow/.local/lib/python3.12/site-packages/airflow/task/task_runner/standard_task_runner.py", line 117, in _start_by_fork
    ret = args.func(args, dag=self.dag)
          ^^^^^^^^^^^^^^^^^^^^^^^^^^^^^
  File "/home/airflow/.local/lib/python3.12/site-packages/airflow/cli/cli_config.py", line 49, in command
    return func(*args, **kwargs)
           ^^^^^^^^^^^^^^^^^^^^^
  File "/home/airflow/.local/lib/python3.12/site-packages/airflow/utils/cli.py", line 115, in wrapper
    return f(*args, **kwargs)
           ^^^^^^^^^^^^^^^^^^
  File "/home/airflow/.local/lib/python3.12/site-packages/airflow/cli/commands/task_command.py", line 483, in task_run
    task_return_code = _run_task_by_selected_method(args, _dag, ti)
                       ^^^^^^^^^^^^^^^^^^^^^^^^^^^^^^^^^^^^^^^^^^^^
  File "/home/airflow/.local/lib/python3.12/site-packages/airflow/cli/commands/task_command.py", line 256, in _run_task_by_selected_method
    return _run_raw_task(args, ti)
           ^^^^^^^^^^^^^^^^^^^^^^^
  File "/home/airflow/.local/lib/python3.12/site-packages/airflow/cli/commands/task_command.py", line 341, in _run_raw_task
    return ti._run_raw_task(
           ^^^^^^^^^^^^^^^^^
  File "/home/airflow/.local/lib/python3.12/site-packages/airflow/utils/session.py", line 97, in wrapper
    return func(*args, session=session, **kwargs)
           ^^^^^^^^^^^^^^^^^^^^^^^^^^^^^^^^^^^^^^
  File "/home/airflow/.local/lib/python3.12/site-packages/airflow/models/taskinstance.py", line 3004, in _run_raw_task
    return _run_raw_task(
           ^^^^^^^^^^^^^^
  File "/home/airflow/.local/lib/python3.12/site-packages/airflow/models/taskinstance.py", line 273, in _run_raw_task
    TaskInstance._execute_task_with_callbacks(
  File "/home/airflow/.local/lib/python3.12/site-packages/airflow/models/taskinstance.py", line 3158, in _execute_task_with_callbacks
    result = self._execute_task(context, task_orig)
             ^^^^^^^^^^^^^^^^^^^^^^^^^^^^^^^^^^^^^^
  File "/home/airflow/.local/lib/python3.12/site-packages/airflow/models/taskinstance.py", line 3182, in _execute_task
    return _execute_task(self, context, task_orig)
           ^^^^^^^^^^^^^^^^^^^^^^^^^^^^^^^^^^^^^^^
  File "/home/airflow/.local/lib/python3.12/site-packages/airflow/models/taskinstance.py", line 767, in _execute_task
    result = _execute_callable(context=context, **execute_callable_kwargs)
             ^^^^^^^^^^^^^^^^^^^^^^^^^^^^^^^^^^^^^^^^^^^^^^^^^^^^^^^^^^^^^
  File "/home/airflow/.local/lib/python3.12/site-packages/airflow/models/taskinstance.py", line 733, in _execute_callable
    return ExecutionCallableRunner(
           ^^^^^^^^^^^^^^^^^^^^^^^^
  File "/home/airflow/.local/lib/python3.12/site-packages/airflow/utils/operator_helpers.py", line 252, in run
    return self.func(*args, **kwargs)
           ^^^^^^^^^^^^^^^^^^^^^^^^^^
  File "/home/airflow/.local/lib/python3.12/site-packages/airflow/models/baseoperator.py", line 406, in wrapper
    return func(self, *args, **kwargs)
           ^^^^^^^^^^^^^^^^^^^^^^^^^^^
  File "/home/airflow/.local/lib/python3.12/site-packages/airflow/operators/python.py", line 238, in execute
    return_value = self.execute_callable()
                   ^^^^^^^^^^^^^^^^^^^^^^^
  File "/home/airflow/.local/lib/python3.12/site-packages/airflow/operators/python.py", line 256, in execute_callable
    return runner.run(*self.op_args, **self.op_kwargs)
           ^^^^^^^^^^^^^^^^^^^^^^^^^^^^^^^^^^^^^^^^^^^
  File "/home/airflow/.local/lib/python3.12/site-packages/airflow/utils/operator_helpers.py", line 252, in run
    return self.func(*args, **kwargs)
           ^^^^^^^^^^^^^^^^^^^^^^^^^^
  File "/opt/airflow/dags/dag.py", line 69, in create_table
    hook.run(create_table_query)
  File "/home/airflow/.local/lib/python3.12/site-packages/airflow/providers/common/sql/hooks/sql.py", line 456, in run
    self._run_command(cur, sql_statement, parameters)
  File "/home/airflow/.local/lib/python3.12/site-packages/airflow/providers/common/sql/hooks/sql.py", line 514, in _run_command
    cur.execute(sql_statement)
psycopg2.errors.UndefinedTable: relation "company_list" does not exist

[2024-09-27T12:50:45.567+0000] {local_task_job_runner.py:266} INFO - Task exited with return code 1
[2024-09-27T12:50:45.596+0000] {local_task_job_runner.py:245} INFO - ::endgroup::
