[2024-09-27T22:27:28.761+0000] {local_task_job_runner.py:123} INFO - ::group::Pre task execution logs
[2024-09-27T22:27:28.919+0000] {taskinstance.py:2612} INFO - Dependencies all met for dep_context=non-requeueable deps ti=<TaskInstance: scrape_and_save_share_prices_with_company_data.insert_company_data scheduled__2024-01-11T00:00:00+00:00 [queued]>
[2024-09-27T22:27:29.092+0000] {taskinstance.py:2612} INFO - Dependencies all met for dep_context=requeueable deps ti=<TaskInstance: scrape_and_save_share_prices_with_company_data.insert_company_data scheduled__2024-01-11T00:00:00+00:00 [queued]>
[2024-09-27T22:27:29.151+0000] {taskinstance.py:2865} INFO - Starting attempt 2 of 2
[2024-09-27T22:27:29.336+0000] {taskinstance.py:2888} INFO - Executing <Task(PythonOperator): insert_company_data> on 2024-01-11 00:00:00+00:00
[2024-09-27T22:27:29.445+0000] {warnings.py:112} WARNING - /home/***/.local/lib/python3.12/site-packages/***/task/task_runner/standard_task_runner.py:70: DeprecationWarning: This process (pid=58) is multi-threaded, use of fork() may lead to deadlocks in the child.
  pid = os.fork()

[2024-09-27T22:27:29.495+0000] {standard_task_runner.py:72} INFO - Started process 91 to run task
[2024-09-27T22:27:29.598+0000] {standard_task_runner.py:104} INFO - Running: ['***', 'tasks', 'run', 'scrape_and_save_share_prices_with_company_data', 'insert_company_data', 'scheduled__2024-01-11T00:00:00+00:00', '--job-id', '2593', '--raw', '--subdir', 'DAGS_FOLDER/dag.py', '--cfg-path', '/tmp/tmp_v52tm3c']
[2024-09-27T22:27:29.602+0000] {standard_task_runner.py:105} INFO - Job 2593: Subtask insert_company_data
[2024-09-27T22:27:30.253+0000] {task_command.py:467} INFO - Running <TaskInstance: scrape_and_save_share_prices_with_company_data.insert_company_data scheduled__2024-01-11T00:00:00+00:00 [running]> on host 7746de5121f6
[2024-09-27T22:27:30.751+0000] {taskinstance.py:3131} INFO - Exporting env vars: AIRFLOW_CTX_DAG_OWNER='***' AIRFLOW_CTX_DAG_ID='scrape_and_save_share_prices_with_company_data' AIRFLOW_CTX_TASK_ID='insert_company_data' AIRFLOW_CTX_EXECUTION_DATE='2024-01-11T00:00:00+00:00' AIRFLOW_CTX_TRY_NUMBER='2' AIRFLOW_CTX_DAG_RUN_ID='scheduled__2024-01-11T00:00:00+00:00'
[2024-09-27T22:27:30.757+0000] {logging_mixin.py:190} INFO - Task instance is in running state
[2024-09-27T22:27:30.758+0000] {logging_mixin.py:190} INFO -  Previous state of the Task instance: queued
[2024-09-27T22:27:30.759+0000] {logging_mixin.py:190} INFO - Current task name:insert_company_data state:running start_date:2024-09-27 22:27:28.994641+00:00
[2024-09-27T22:27:30.760+0000] {logging_mixin.py:190} INFO - Dag name:scrape_and_save_share_prices_with_company_data and current dag run status:running
[2024-09-27T22:27:30.762+0000] {taskinstance.py:731} INFO - ::endgroup::
[2024-09-27T22:27:47.326+0000] {job.py:229} INFO - Heartbeat recovered after 12.67 seconds
[2024-09-27T22:27:50.131+0000] {base.py:84} INFO - Retrieving connection 'dse_connection'
[2024-09-27T22:28:11.177+0000] {logging_mixin.py:190} INFO - Error inserting company data: connection to server at "172.26.0.3", port 5432 failed: Connection refused
	Is the server running on that host and accepting TCP/IP connections?
[2024-09-27T22:28:11.196+0000] {base.py:84} INFO - Retrieving connection 'dse_connection'
[2024-09-27T22:28:32.274+0000] {logging_mixin.py:190} INFO - Error inserting company data: connection to server at "172.26.0.3", port 5432 failed: Connection refused
	Is the server running on that host and accepting TCP/IP connections?
[2024-09-27T22:28:32.293+0000] {base.py:84} INFO - Retrieving connection 'dse_connection'
[2024-09-27T22:28:53.351+0000] {logging_mixin.py:190} INFO - Error inserting company data: connection to server at "172.26.0.3", port 5432 failed: Connection refused
	Is the server running on that host and accepting TCP/IP connections?
[2024-09-27T22:28:53.359+0000] {base.py:84} INFO - Retrieving connection 'dse_connection'
[2024-09-27T22:29:14.400+0000] {logging_mixin.py:190} INFO - Error inserting company data: connection to server at "172.26.0.3", port 5432 failed: Connection refused
	Is the server running on that host and accepting TCP/IP connections?
[2024-09-27T22:29:14.412+0000] {base.py:84} INFO - Retrieving connection 'dse_connection'
[2024-09-27T22:29:35.448+0000] {logging_mixin.py:190} INFO - Error inserting company data: connection to server at "172.26.0.3", port 5432 failed: Connection refused
	Is the server running on that host and accepting TCP/IP connections?
[2024-09-27T22:29:35.466+0000] {base.py:84} INFO - Retrieving connection 'dse_connection'
[2024-09-27T22:29:56.740+0000] {logging_mixin.py:190} INFO - Error inserting company data: connection to server at "172.26.0.3", port 5432 failed: Connection refused
	Is the server running on that host and accepting TCP/IP connections?
[2024-09-27T22:29:56.755+0000] {base.py:84} INFO - Retrieving connection 'dse_connection'
[2024-09-27T22:30:12.713+0000] {job.py:229} INFO - Heartbeat recovered after 11.51 seconds
[2024-09-27T22:30:17.560+0000] {logging_mixin.py:190} INFO - Error inserting company data: connection to server at "172.26.0.3", port 5432 failed: Connection refused
	Is the server running on that host and accepting TCP/IP connections?
[2024-09-27T22:30:17.615+0000] {base.py:84} INFO - Retrieving connection 'dse_connection'
[2024-09-27T22:30:19.254+0000] {job.py:229} INFO - Heartbeat recovered after 11.99 seconds
[2024-09-27T22:30:38.672+0000] {logging_mixin.py:190} INFO - Error inserting company data: connection to server at "172.26.0.3", port 5432 failed: Connection refused
	Is the server running on that host and accepting TCP/IP connections?
[2024-09-27T22:30:38.691+0000] {base.py:84} INFO - Retrieving connection 'dse_connection'
[2024-09-27T22:30:59.721+0000] {logging_mixin.py:190} INFO - Error inserting company data: connection to server at "172.26.0.3", port 5432 failed: Connection refused
	Is the server running on that host and accepting TCP/IP connections?
[2024-09-27T22:30:59.729+0000] {base.py:84} INFO - Retrieving connection 'dse_connection'
[2024-09-27T22:31:20.759+0000] {logging_mixin.py:190} INFO - Error inserting company data: connection to server at "172.26.0.3", port 5432 failed: Connection refused
	Is the server running on that host and accepting TCP/IP connections?
[2024-09-27T22:31:20.768+0000] {base.py:84} INFO - Retrieving connection 'dse_connection'
[2024-09-27T22:31:41.803+0000] {logging_mixin.py:190} INFO - Error inserting company data: connection to server at "172.26.0.3", port 5432 failed: Connection refused
	Is the server running on that host and accepting TCP/IP connections?
[2024-09-27T22:31:41.811+0000] {base.py:84} INFO - Retrieving connection 'dse_connection'
[2024-09-27T22:31:50.787+0000] {local_task_job_runner.py:346} WARNING - State of this instance has been externally set to failed. Terminating instance.
[2024-09-27T22:31:50.788+0000] {local_task_job_runner.py:245} INFO - ::endgroup::
[2024-09-27T22:31:50.791+0000] {process_utils.py:132} INFO - Sending 15 to group 91. PIDs of all processes in the group: [91]
[2024-09-27T22:31:50.791+0000] {process_utils.py:87} INFO - Sending the signal 15 to group 91
[2024-09-27T22:32:02.843+0000] {taskinstance.py:3092} ERROR - Received SIGTERM. Terminating subprocesses.
[2024-09-27T22:32:02.897+0000] {taskinstance.py:340} INFO - ::group::Post task execution logs
[2024-09-27T22:32:02.989+0000] {process_utils.py:80} INFO - Process psutil.Process(pid=91, status='terminated', exitcode=0, started='22:27:28') (91) terminated with exit code 0
