[2024-09-26T21:20:20.095+0000] {local_task_job_runner.py:123} INFO - ::group::Pre task execution logs
[2024-09-26T21:20:20.148+0000] {taskinstance.py:2612} INFO - Dependencies all met for dep_context=non-requeueable deps ti=<TaskInstance: fetch_and_save_share_prices.create_table scheduled__2023-11-24T00:00:00+00:00 [queued]>
[2024-09-26T21:20:20.172+0000] {taskinstance.py:2612} INFO - Dependencies all met for dep_context=requeueable deps ti=<TaskInstance: fetch_and_save_share_prices.create_table scheduled__2023-11-24T00:00:00+00:00 [queued]>
[2024-09-26T21:20:20.174+0000] {taskinstance.py:2865} INFO - Starting attempt 2 of 2
[2024-09-26T21:20:20.208+0000] {taskinstance.py:2888} INFO - Executing <Task(PythonOperator): create_table> on 2023-11-24 00:00:00+00:00
[2024-09-26T21:20:20.220+0000] {warnings.py:112} WARNING - /home/***/.local/lib/python3.12/site-packages/***/task/task_runner/standard_task_runner.py:70: DeprecationWarning: This process (pid=2340) is multi-threaded, use of fork() may lead to deadlocks in the child.
  pid = os.fork()

[2024-09-26T21:20:20.224+0000] {standard_task_runner.py:72} INFO - Started process 2356 to run task
[2024-09-26T21:20:20.223+0000] {standard_task_runner.py:104} INFO - Running: ['***', 'tasks', 'run', 'fetch_and_save_share_prices', 'create_table', 'scheduled__2023-11-24T00:00:00+00:00', '--job-id', '138', '--raw', '--subdir', 'DAGS_FOLDER/dag.py', '--cfg-path', '/tmp/tmpfvyhpxff']
[2024-09-26T21:20:20.226+0000] {standard_task_runner.py:105} INFO - Job 138: Subtask create_table
[2024-09-26T21:20:20.362+0000] {task_command.py:467} INFO - Running <TaskInstance: fetch_and_save_share_prices.create_table scheduled__2023-11-24T00:00:00+00:00 [running]> on host 13b5797a93ab
[2024-09-26T21:20:20.585+0000] {taskinstance.py:3131} INFO - Exporting env vars: AIRFLOW_CTX_DAG_OWNER='***' AIRFLOW_CTX_DAG_ID='fetch_and_save_share_prices' AIRFLOW_CTX_TASK_ID='create_table' AIRFLOW_CTX_EXECUTION_DATE='2023-11-24T00:00:00+00:00' AIRFLOW_CTX_TRY_NUMBER='2' AIRFLOW_CTX_DAG_RUN_ID='scheduled__2023-11-24T00:00:00+00:00'
[2024-09-26T21:20:20.587+0000] {logging_mixin.py:190} INFO - Task instance is in running state
[2024-09-26T21:20:20.588+0000] {logging_mixin.py:190} INFO -  Previous state of the Task instance: queued
[2024-09-26T21:20:20.589+0000] {logging_mixin.py:190} INFO - Current task name:create_table state:running start_date:2024-09-26 21:20:20.149618+00:00
[2024-09-26T21:20:20.590+0000] {logging_mixin.py:190} INFO - Dag name:fetch_and_save_share_prices and current dag run status:running
[2024-09-26T21:20:20.591+0000] {taskinstance.py:731} INFO - ::endgroup::
[2024-09-26T21:20:20.640+0000] {taskinstance.py:3310} ERROR - Task failed with exception
Traceback (most recent call last):
  File "/home/airflow/.local/lib/python3.12/site-packages/airflow/models/taskinstance.py", line 767, in _execute_task
    result = _execute_callable(context=context, **execute_callable_kwargs)
             ^^^^^^^^^^^^^^^^^^^^^^^^^^^^^^^^^^^^^^^^^^^^^^^^^^^^^^^^^^^^^
  File "/home/airflow/.local/lib/python3.12/site-packages/airflow/models/taskinstance.py", line 733, in _execute_callable
    return ExecutionCallableRunner(
           ^^^^^^^^^^^^^^^^^^^^^^^^
  File "/home/airflow/.local/lib/python3.12/site-packages/airflow/utils/operator_helpers.py", line 252, in run
    return self.func(*args, **kwargs)
           ^^^^^^^^^^^^^^^^^^^^^^^^^^
  File "/home/airflow/.local/lib/python3.12/site-packages/airflow/models/baseoperator.py", line 406, in wrapper
    return func(self, *args, **kwargs)
           ^^^^^^^^^^^^^^^^^^^^^^^^^^^
  File "/home/airflow/.local/lib/python3.12/site-packages/airflow/operators/python.py", line 238, in execute
    return_value = self.execute_callable()
                   ^^^^^^^^^^^^^^^^^^^^^^^
  File "/home/airflow/.local/lib/python3.12/site-packages/airflow/operators/python.py", line 256, in execute_callable
    return runner.run(*self.op_args, **self.op_kwargs)
           ^^^^^^^^^^^^^^^^^^^^^^^^^^^^^^^^^^^^^^^^^^^
  File "/home/airflow/.local/lib/python3.12/site-packages/airflow/utils/operator_helpers.py", line 252, in run
    return self.func(*args, **kwargs)
           ^^^^^^^^^^^^^^^^^^^^^^^^^^
  File "/opt/airflow/dags/dag.py", line 69, in create_table
    hook.run(create_table_query)
  File "/home/airflow/.local/lib/python3.12/site-packages/airflow/providers/common/sql/hooks/sql.py", line 452, in run
    with self._create_autocommit_connection(autocommit) as conn:
         ^^^^^^^^^^^^^^^^^^^^^^^^^^^^^^^^^^^^^^^^^^^^^^
  File "/usr/local/lib/python3.12/contextlib.py", line 137, in __enter__
    return next(self.gen)
           ^^^^^^^^^^^^^^
  File "/home/airflow/.local/lib/python3.12/site-packages/airflow/providers/common/sql/hooks/sql.py", line 574, in _create_autocommit_connection
    with closing(self.get_conn()) as conn:
                 ^^^^^^^^^^^^^^^
  File "/home/airflow/.local/lib/python3.12/site-packages/airflow/providers/postgres/hooks/postgres.py", line 146, in get_conn
    conn = deepcopy(self.connection or self.get_connection(conn_id))
                                       ^^^^^^^^^^^^^^^^^^^^^^^^^^^^
  File "/home/airflow/.local/lib/python3.12/site-packages/airflow/hooks/base.py", line 83, in get_connection
    conn = Connection.get_connection_from_secrets(conn_id)
           ^^^^^^^^^^^^^^^^^^^^^^^^^^^^^^^^^^^^^^^^^^^^^^^
  File "/home/airflow/.local/lib/python3.12/site-packages/airflow/models/connection.py", line 537, in get_connection_from_secrets
    raise AirflowNotFoundException(f"The conn_id `{conn_id}` isn't defined")
airflow.exceptions.AirflowNotFoundException: The conn_id `my_postgres` isn't defined
[2024-09-26T21:20:20.661+0000] {logging_mixin.py:190} INFO - Task instance in failure state
[2024-09-26T21:20:20.662+0000] {logging_mixin.py:190} INFO - Task start:2024-09-26 21:20:20.149618+00:00 end:2024-09-26 21:20:20.660329+00:00 duration:0.510711
[2024-09-26T21:20:20.664+0000] {logging_mixin.py:190} INFO - Task:<Task(PythonOperator): create_table> dag:<DAG: fetch_and_save_share_prices> dagrun:<DagRun fetch_and_save_share_prices @ 2023-11-24 00:00:00+00:00: scheduled__2023-11-24T00:00:00+00:00, state:running, queued_at: 2024-09-26 21:15:04.263219+00:00. externally triggered: False>
[2024-09-26T21:20:20.665+0000] {logging_mixin.py:190} INFO - Failure caused by The conn_id `my_postgres` isn't defined
[2024-09-26T21:20:20.666+0000] {taskinstance.py:1225} INFO - Marking task as FAILED. dag_id=fetch_and_save_share_prices, task_id=create_table, run_id=scheduled__2023-11-24T00:00:00+00:00, execution_date=20231124T000000, start_date=20240926T212020, end_date=20240926T212020
[2024-09-26T21:20:20.702+0000] {taskinstance.py:340} INFO - ::group::Post task execution logs
[2024-09-26T21:20:20.703+0000] {standard_task_runner.py:124} ERROR - Failed to execute job 138 for task create_table (The conn_id `my_postgres` isn't defined; 2356)
Traceback (most recent call last):
  File "/home/airflow/.local/lib/python3.12/site-packages/airflow/task/task_runner/standard_task_runner.py", line 117, in _start_by_fork
    ret = args.func(args, dag=self.dag)
          ^^^^^^^^^^^^^^^^^^^^^^^^^^^^^
  File "/home/airflow/.local/lib/python3.12/site-packages/airflow/cli/cli_config.py", line 49, in command
    return func(*args, **kwargs)
           ^^^^^^^^^^^^^^^^^^^^^
  File "/home/airflow/.local/lib/python3.12/site-packages/airflow/utils/cli.py", line 115, in wrapper
    return f(*args, **kwargs)
           ^^^^^^^^^^^^^^^^^^
  File "/home/airflow/.local/lib/python3.12/site-packages/airflow/cli/commands/task_command.py", line 483, in task_run
    task_return_code = _run_task_by_selected_method(args, _dag, ti)
                       ^^^^^^^^^^^^^^^^^^^^^^^^^^^^^^^^^^^^^^^^^^^^
  File "/home/airflow/.local/lib/python3.12/site-packages/airflow/cli/commands/task_command.py", line 256, in _run_task_by_selected_method
    return _run_raw_task(args, ti)
           ^^^^^^^^^^^^^^^^^^^^^^^
  File "/home/airflow/.local/lib/python3.12/site-packages/airflow/cli/commands/task_command.py", line 341, in _run_raw_task
    return ti._run_raw_task(
           ^^^^^^^^^^^^^^^^^
  File "/home/airflow/.local/lib/python3.12/site-packages/airflow/utils/session.py", line 97, in wrapper
    return func(*args, session=session, **kwargs)
           ^^^^^^^^^^^^^^^^^^^^^^^^^^^^^^^^^^^^^^
  File "/home/airflow/.local/lib/python3.12/site-packages/airflow/models/taskinstance.py", line 3004, in _run_raw_task
    return _run_raw_task(
           ^^^^^^^^^^^^^^
  File "/home/airflow/.local/lib/python3.12/site-packages/airflow/models/taskinstance.py", line 273, in _run_raw_task
    TaskInstance._execute_task_with_callbacks(
  File "/home/airflow/.local/lib/python3.12/site-packages/airflow/models/taskinstance.py", line 3158, in _execute_task_with_callbacks
    result = self._execute_task(context, task_orig)
             ^^^^^^^^^^^^^^^^^^^^^^^^^^^^^^^^^^^^^^
  File "/home/airflow/.local/lib/python3.12/site-packages/airflow/models/taskinstance.py", line 3182, in _execute_task
    return _execute_task(self, context, task_orig)
           ^^^^^^^^^^^^^^^^^^^^^^^^^^^^^^^^^^^^^^^
  File "/home/airflow/.local/lib/python3.12/site-packages/airflow/models/taskinstance.py", line 767, in _execute_task
    result = _execute_callable(context=context, **execute_callable_kwargs)
             ^^^^^^^^^^^^^^^^^^^^^^^^^^^^^^^^^^^^^^^^^^^^^^^^^^^^^^^^^^^^^
  File "/home/airflow/.local/lib/python3.12/site-packages/airflow/models/taskinstance.py", line 733, in _execute_callable
    return ExecutionCallableRunner(
           ^^^^^^^^^^^^^^^^^^^^^^^^
  File "/home/airflow/.local/lib/python3.12/site-packages/airflow/utils/operator_helpers.py", line 252, in run
    return self.func(*args, **kwargs)
           ^^^^^^^^^^^^^^^^^^^^^^^^^^
  File "/home/airflow/.local/lib/python3.12/site-packages/airflow/models/baseoperator.py", line 406, in wrapper
    return func(self, *args, **kwargs)
           ^^^^^^^^^^^^^^^^^^^^^^^^^^^
  File "/home/airflow/.local/lib/python3.12/site-packages/airflow/operators/python.py", line 238, in execute
    return_value = self.execute_callable()
                   ^^^^^^^^^^^^^^^^^^^^^^^
  File "/home/airflow/.local/lib/python3.12/site-packages/airflow/operators/python.py", line 256, in execute_callable
    return runner.run(*self.op_args, **self.op_kwargs)
           ^^^^^^^^^^^^^^^^^^^^^^^^^^^^^^^^^^^^^^^^^^^
  File "/home/airflow/.local/lib/python3.12/site-packages/airflow/utils/operator_helpers.py", line 252, in run
    return self.func(*args, **kwargs)
           ^^^^^^^^^^^^^^^^^^^^^^^^^^
  File "/opt/airflow/dags/dag.py", line 69, in create_table
    hook.run(create_table_query)
  File "/home/airflow/.local/lib/python3.12/site-packages/airflow/providers/common/sql/hooks/sql.py", line 452, in run
    with self._create_autocommit_connection(autocommit) as conn:
         ^^^^^^^^^^^^^^^^^^^^^^^^^^^^^^^^^^^^^^^^^^^^^^
  File "/usr/local/lib/python3.12/contextlib.py", line 137, in __enter__
    return next(self.gen)
           ^^^^^^^^^^^^^^
  File "/home/airflow/.local/lib/python3.12/site-packages/airflow/providers/common/sql/hooks/sql.py", line 574, in _create_autocommit_connection
    with closing(self.get_conn()) as conn:
                 ^^^^^^^^^^^^^^^
  File "/home/airflow/.local/lib/python3.12/site-packages/airflow/providers/postgres/hooks/postgres.py", line 146, in get_conn
    conn = deepcopy(self.connection or self.get_connection(conn_id))
                                       ^^^^^^^^^^^^^^^^^^^^^^^^^^^^
  File "/home/airflow/.local/lib/python3.12/site-packages/airflow/hooks/base.py", line 83, in get_connection
    conn = Connection.get_connection_from_secrets(conn_id)
           ^^^^^^^^^^^^^^^^^^^^^^^^^^^^^^^^^^^^^^^^^^^^^^^
  File "/home/airflow/.local/lib/python3.12/site-packages/airflow/models/connection.py", line 537, in get_connection_from_secrets
    raise AirflowNotFoundException(f"The conn_id `{conn_id}` isn't defined")
airflow.exceptions.AirflowNotFoundException: The conn_id `my_postgres` isn't defined
[2024-09-26T21:20:20.740+0000] {local_task_job_runner.py:266} INFO - Task exited with return code 1
[2024-09-26T21:20:20.801+0000] {taskinstance.py:3900} INFO - 0 downstream tasks scheduled from follow-on schedule check
[2024-09-26T21:20:20.811+0000] {local_task_job_runner.py:245} INFO - ::endgroup::
[2024-09-27T11:40:14.862+0000] {local_task_job_runner.py:123} INFO - ::group::Pre task execution logs
[2024-09-27T11:40:14.912+0000] {taskinstance.py:2612} INFO - Dependencies all met for dep_context=non-requeueable deps ti=<TaskInstance: fetch_and_save_share_prices.create_table scheduled__2023-11-24T00:00:00+00:00 [queued]>
[2024-09-27T11:40:14.938+0000] {taskinstance.py:2612} INFO - Dependencies all met for dep_context=requeueable deps ti=<TaskInstance: fetch_and_save_share_prices.create_table scheduled__2023-11-24T00:00:00+00:00 [queued]>
[2024-09-27T11:40:14.940+0000] {taskinstance.py:2865} INFO - Starting attempt 2 of 2
[2024-09-27T11:40:15.005+0000] {taskinstance.py:2888} INFO - Executing <Task(PythonOperator): create_table> on 2023-11-24 00:00:00+00:00
[2024-09-27T11:40:15.021+0000] {warnings.py:112} WARNING - /home/***/.local/lib/python3.12/site-packages/***/task/task_runner/standard_task_runner.py:70: DeprecationWarning: This process (pid=4370) is multi-threaded, use of fork() may lead to deadlocks in the child.
  pid = os.fork()

[2024-09-27T11:40:15.025+0000] {standard_task_runner.py:72} INFO - Started process 4385 to run task
[2024-09-27T11:40:15.028+0000] {standard_task_runner.py:104} INFO - Running: ['***', 'tasks', 'run', 'fetch_and_save_share_prices', 'create_table', 'scheduled__2023-11-24T00:00:00+00:00', '--job-id', '471', '--raw', '--subdir', 'DAGS_FOLDER/dag.py', '--cfg-path', '/tmp/tmpoeedqwac']
[2024-09-27T11:40:15.032+0000] {standard_task_runner.py:105} INFO - Job 471: Subtask create_table
[2024-09-27T11:40:15.196+0000] {task_command.py:467} INFO - Running <TaskInstance: fetch_and_save_share_prices.create_table scheduled__2023-11-24T00:00:00+00:00 [running]> on host 13b5797a93ab
[2024-09-27T11:40:15.525+0000] {taskinstance.py:3131} INFO - Exporting env vars: AIRFLOW_CTX_DAG_OWNER='***' AIRFLOW_CTX_DAG_ID='fetch_and_save_share_prices' AIRFLOW_CTX_TASK_ID='create_table' AIRFLOW_CTX_EXECUTION_DATE='2023-11-24T00:00:00+00:00' AIRFLOW_CTX_TRY_NUMBER='2' AIRFLOW_CTX_DAG_RUN_ID='scheduled__2023-11-24T00:00:00+00:00'
[2024-09-27T11:40:15.529+0000] {logging_mixin.py:190} INFO - Task instance is in running state
[2024-09-27T11:40:15.530+0000] {logging_mixin.py:190} INFO -  Previous state of the Task instance: queued
[2024-09-27T11:40:15.532+0000] {logging_mixin.py:190} INFO - Current task name:create_table state:running start_date:2024-09-27 11:40:14.915996+00:00
[2024-09-27T11:40:15.533+0000] {logging_mixin.py:190} INFO - Dag name:fetch_and_save_share_prices and current dag run status:running
[2024-09-27T11:40:15.534+0000] {taskinstance.py:731} INFO - ::endgroup::
[2024-09-27T11:40:15.557+0000] {base.py:84} INFO - Retrieving connection 'dse_connection'
[2024-09-27T11:40:15.567+0000] {sql.py:509} INFO - Running statement: 
        CREATE TABLE IF NOT EXISTS company_share_prices (
            id SERIAL,
            company_id INTEGER NOT NULL,
            date DATE,
            latest_trading_price VARCHAR(50),
            low_price VARCHAR(50),
            high_price VARCHAR(50),
            closing_price VARCHAR(50),
            ycp VARCHAR(50),
            change VARCHAR(10),
            trade VARCHAR(50),
            value VARCHAR(50),
            volume VARCHAR(50),
            PRIMARY KEY(company_id, id),
            FOREIGN KEY(company_id)
                REFERENCES company_list(company_id)
                ON UPDATE CASCADE ON DELETE CASCADE
        );
    , parameters: None
[2024-09-27T11:40:15.586+0000] {taskinstance.py:3310} ERROR - Task failed with exception
Traceback (most recent call last):
  File "/home/airflow/.local/lib/python3.12/site-packages/airflow/models/taskinstance.py", line 767, in _execute_task
    result = _execute_callable(context=context, **execute_callable_kwargs)
             ^^^^^^^^^^^^^^^^^^^^^^^^^^^^^^^^^^^^^^^^^^^^^^^^^^^^^^^^^^^^^
  File "/home/airflow/.local/lib/python3.12/site-packages/airflow/models/taskinstance.py", line 733, in _execute_callable
    return ExecutionCallableRunner(
           ^^^^^^^^^^^^^^^^^^^^^^^^
  File "/home/airflow/.local/lib/python3.12/site-packages/airflow/utils/operator_helpers.py", line 252, in run
    return self.func(*args, **kwargs)
           ^^^^^^^^^^^^^^^^^^^^^^^^^^
  File "/home/airflow/.local/lib/python3.12/site-packages/airflow/models/baseoperator.py", line 406, in wrapper
    return func(self, *args, **kwargs)
           ^^^^^^^^^^^^^^^^^^^^^^^^^^^
  File "/home/airflow/.local/lib/python3.12/site-packages/airflow/operators/python.py", line 238, in execute
    return_value = self.execute_callable()
                   ^^^^^^^^^^^^^^^^^^^^^^^
  File "/home/airflow/.local/lib/python3.12/site-packages/airflow/operators/python.py", line 256, in execute_callable
    return runner.run(*self.op_args, **self.op_kwargs)
           ^^^^^^^^^^^^^^^^^^^^^^^^^^^^^^^^^^^^^^^^^^^
  File "/home/airflow/.local/lib/python3.12/site-packages/airflow/utils/operator_helpers.py", line 252, in run
    return self.func(*args, **kwargs)
           ^^^^^^^^^^^^^^^^^^^^^^^^^^
  File "/opt/airflow/dags/dag.py", line 69, in create_table
    hook.run(create_table_query)
  File "/home/airflow/.local/lib/python3.12/site-packages/airflow/providers/common/sql/hooks/sql.py", line 456, in run
    self._run_command(cur, sql_statement, parameters)
  File "/home/airflow/.local/lib/python3.12/site-packages/airflow/providers/common/sql/hooks/sql.py", line 514, in _run_command
    cur.execute(sql_statement)
psycopg2.errors.UndefinedTable: relation "company_list" does not exist

[2024-09-27T11:40:15.642+0000] {logging_mixin.py:190} INFO - Task instance in failure state
[2024-09-27T11:40:15.644+0000] {logging_mixin.py:190} INFO - Task start:2024-09-27 11:40:14.915996+00:00 end:2024-09-27 11:40:15.641331+00:00 duration:0.725335
[2024-09-27T11:40:15.646+0000] {logging_mixin.py:190} INFO - Task:<Task(PythonOperator): create_table> dag:<DAG: fetch_and_save_share_prices> dagrun:<DagRun fetch_and_save_share_prices @ 2023-11-24 00:00:00+00:00: scheduled__2023-11-24T00:00:00+00:00, state:running, queued_at: 2024-09-27 11:34:59.559272+00:00. externally triggered: False>
[2024-09-27T11:40:15.654+0000] {logging_mixin.py:190} INFO - Failure caused by relation "company_list" does not exist
[2024-09-27T11:40:15.657+0000] {taskinstance.py:1225} INFO - Marking task as FAILED. dag_id=fetch_and_save_share_prices, task_id=create_table, run_id=scheduled__2023-11-24T00:00:00+00:00, execution_date=20231124T000000, start_date=20240927T114014, end_date=20240927T114015
[2024-09-27T11:40:15.702+0000] {taskinstance.py:340} INFO - ::group::Post task execution logs
[2024-09-27T11:40:15.704+0000] {standard_task_runner.py:124} ERROR - Failed to execute job 471 for task create_table (relation "company_list" does not exist
; 4385)
Traceback (most recent call last):
  File "/home/airflow/.local/lib/python3.12/site-packages/airflow/task/task_runner/standard_task_runner.py", line 117, in _start_by_fork
    ret = args.func(args, dag=self.dag)
          ^^^^^^^^^^^^^^^^^^^^^^^^^^^^^
  File "/home/airflow/.local/lib/python3.12/site-packages/airflow/cli/cli_config.py", line 49, in command
    return func(*args, **kwargs)
           ^^^^^^^^^^^^^^^^^^^^^
  File "/home/airflow/.local/lib/python3.12/site-packages/airflow/utils/cli.py", line 115, in wrapper
    return f(*args, **kwargs)
           ^^^^^^^^^^^^^^^^^^
  File "/home/airflow/.local/lib/python3.12/site-packages/airflow/cli/commands/task_command.py", line 483, in task_run
    task_return_code = _run_task_by_selected_method(args, _dag, ti)
                       ^^^^^^^^^^^^^^^^^^^^^^^^^^^^^^^^^^^^^^^^^^^^
  File "/home/airflow/.local/lib/python3.12/site-packages/airflow/cli/commands/task_command.py", line 256, in _run_task_by_selected_method
    return _run_raw_task(args, ti)
           ^^^^^^^^^^^^^^^^^^^^^^^
  File "/home/airflow/.local/lib/python3.12/site-packages/airflow/cli/commands/task_command.py", line 341, in _run_raw_task
    return ti._run_raw_task(
           ^^^^^^^^^^^^^^^^^
  File "/home/airflow/.local/lib/python3.12/site-packages/airflow/utils/session.py", line 97, in wrapper
    return func(*args, session=session, **kwargs)
           ^^^^^^^^^^^^^^^^^^^^^^^^^^^^^^^^^^^^^^
  File "/home/airflow/.local/lib/python3.12/site-packages/airflow/models/taskinstance.py", line 3004, in _run_raw_task
    return _run_raw_task(
           ^^^^^^^^^^^^^^
  File "/home/airflow/.local/lib/python3.12/site-packages/airflow/models/taskinstance.py", line 273, in _run_raw_task
    TaskInstance._execute_task_with_callbacks(
  File "/home/airflow/.local/lib/python3.12/site-packages/airflow/models/taskinstance.py", line 3158, in _execute_task_with_callbacks
    result = self._execute_task(context, task_orig)
             ^^^^^^^^^^^^^^^^^^^^^^^^^^^^^^^^^^^^^^
  File "/home/airflow/.local/lib/python3.12/site-packages/airflow/models/taskinstance.py", line 3182, in _execute_task
    return _execute_task(self, context, task_orig)
           ^^^^^^^^^^^^^^^^^^^^^^^^^^^^^^^^^^^^^^^
  File "/home/airflow/.local/lib/python3.12/site-packages/airflow/models/taskinstance.py", line 767, in _execute_task
    result = _execute_callable(context=context, **execute_callable_kwargs)
             ^^^^^^^^^^^^^^^^^^^^^^^^^^^^^^^^^^^^^^^^^^^^^^^^^^^^^^^^^^^^^
  File "/home/airflow/.local/lib/python3.12/site-packages/airflow/models/taskinstance.py", line 733, in _execute_callable
    return ExecutionCallableRunner(
           ^^^^^^^^^^^^^^^^^^^^^^^^
  File "/home/airflow/.local/lib/python3.12/site-packages/airflow/utils/operator_helpers.py", line 252, in run
    return self.func(*args, **kwargs)
           ^^^^^^^^^^^^^^^^^^^^^^^^^^
  File "/home/airflow/.local/lib/python3.12/site-packages/airflow/models/baseoperator.py", line 406, in wrapper
    return func(self, *args, **kwargs)
           ^^^^^^^^^^^^^^^^^^^^^^^^^^^
  File "/home/airflow/.local/lib/python3.12/site-packages/airflow/operators/python.py", line 238, in execute
    return_value = self.execute_callable()
                   ^^^^^^^^^^^^^^^^^^^^^^^
  File "/home/airflow/.local/lib/python3.12/site-packages/airflow/operators/python.py", line 256, in execute_callable
    return runner.run(*self.op_args, **self.op_kwargs)
           ^^^^^^^^^^^^^^^^^^^^^^^^^^^^^^^^^^^^^^^^^^^
  File "/home/airflow/.local/lib/python3.12/site-packages/airflow/utils/operator_helpers.py", line 252, in run
    return self.func(*args, **kwargs)
           ^^^^^^^^^^^^^^^^^^^^^^^^^^
  File "/opt/airflow/dags/dag.py", line 69, in create_table
    hook.run(create_table_query)
  File "/home/airflow/.local/lib/python3.12/site-packages/airflow/providers/common/sql/hooks/sql.py", line 456, in run
    self._run_command(cur, sql_statement, parameters)
  File "/home/airflow/.local/lib/python3.12/site-packages/airflow/providers/common/sql/hooks/sql.py", line 514, in _run_command
    cur.execute(sql_statement)
psycopg2.errors.UndefinedTable: relation "company_list" does not exist

[2024-09-27T11:40:15.768+0000] {local_task_job_runner.py:266} INFO - Task exited with return code 1
[2024-09-27T11:40:15.802+0000] {local_task_job_runner.py:245} INFO - ::endgroup::
