[2024-09-26T20:58:15.666+0000] {local_task_job_runner.py:123} INFO - ::group::Pre task execution logs
[2024-09-26T20:58:15.872+0000] {taskinstance.py:2612} INFO - Dependencies all met for dep_context=non-requeueable deps ti=<TaskInstance: fetch_and_save_share_prices.create_table scheduled__2023-10-08T00:00:00+00:00 [queued]>
[2024-09-26T20:58:16.010+0000] {taskinstance.py:2612} INFO - Dependencies all met for dep_context=requeueable deps ti=<TaskInstance: fetch_and_save_share_prices.create_table scheduled__2023-10-08T00:00:00+00:00 [queued]>
[2024-09-26T20:58:16.030+0000] {taskinstance.py:2865} INFO - Starting attempt 1 of 2
[2024-09-26T20:58:16.216+0000] {taskinstance.py:2888} INFO - Executing <Task(PythonOperator): create_table> on 2023-10-08 00:00:00+00:00
[2024-09-26T20:58:16.256+0000] {warnings.py:112} WARNING - /home/***/.local/lib/python3.12/site-packages/***/task/task_runner/standard_task_runner.py:70: DeprecationWarning: This process (pid=1597) is multi-threaded, use of fork() may lead to deadlocks in the child.
  pid = os.fork()

[2024-09-26T20:58:16.293+0000] {standard_task_runner.py:72} INFO - Started process 1632 to run task
[2024-09-26T20:58:16.296+0000] {standard_task_runner.py:104} INFO - Running: ['***', 'tasks', 'run', 'fetch_and_save_share_prices', 'create_table', 'scheduled__2023-10-08T00:00:00+00:00', '--job-id', '24', '--raw', '--subdir', 'DAGS_FOLDER/dag.py', '--cfg-path', '/tmp/tmpr05bxva1']
[2024-09-26T20:58:16.343+0000] {standard_task_runner.py:105} INFO - Job 24: Subtask create_table
[2024-09-26T20:58:16.847+0000] {task_command.py:467} INFO - Running <TaskInstance: fetch_and_save_share_prices.create_table scheduled__2023-10-08T00:00:00+00:00 [running]> on host 13b5797a93ab
[2024-09-26T20:58:17.446+0000] {taskinstance.py:3131} INFO - Exporting env vars: AIRFLOW_CTX_DAG_OWNER='***' AIRFLOW_CTX_DAG_ID='fetch_and_save_share_prices' AIRFLOW_CTX_TASK_ID='create_table' AIRFLOW_CTX_EXECUTION_DATE='2023-10-08T00:00:00+00:00' AIRFLOW_CTX_TRY_NUMBER='1' AIRFLOW_CTX_DAG_RUN_ID='scheduled__2023-10-08T00:00:00+00:00'
[2024-09-26T20:58:17.461+0000] {logging_mixin.py:190} INFO - Task instance is in running state
[2024-09-26T20:58:17.462+0000] {logging_mixin.py:190} INFO -  Previous state of the Task instance: queued
[2024-09-26T20:58:17.463+0000] {logging_mixin.py:190} INFO - Current task name:create_table state:running start_date:2024-09-26 20:58:15.899469+00:00
[2024-09-26T20:58:17.470+0000] {logging_mixin.py:190} INFO - Dag name:fetch_and_save_share_prices and current dag run status:running
[2024-09-26T20:58:17.472+0000] {taskinstance.py:731} INFO - ::endgroup::
[2024-09-26T20:58:17.624+0000] {taskinstance.py:3310} ERROR - Task failed with exception
Traceback (most recent call last):
  File "/home/airflow/.local/lib/python3.12/site-packages/airflow/models/taskinstance.py", line 767, in _execute_task
    result = _execute_callable(context=context, **execute_callable_kwargs)
             ^^^^^^^^^^^^^^^^^^^^^^^^^^^^^^^^^^^^^^^^^^^^^^^^^^^^^^^^^^^^^
  File "/home/airflow/.local/lib/python3.12/site-packages/airflow/models/taskinstance.py", line 733, in _execute_callable
    return ExecutionCallableRunner(
           ^^^^^^^^^^^^^^^^^^^^^^^^
  File "/home/airflow/.local/lib/python3.12/site-packages/airflow/utils/operator_helpers.py", line 252, in run
    return self.func(*args, **kwargs)
           ^^^^^^^^^^^^^^^^^^^^^^^^^^
  File "/home/airflow/.local/lib/python3.12/site-packages/airflow/models/baseoperator.py", line 406, in wrapper
    return func(self, *args, **kwargs)
           ^^^^^^^^^^^^^^^^^^^^^^^^^^^
  File "/home/airflow/.local/lib/python3.12/site-packages/airflow/operators/python.py", line 238, in execute
    return_value = self.execute_callable()
                   ^^^^^^^^^^^^^^^^^^^^^^^
  File "/home/airflow/.local/lib/python3.12/site-packages/airflow/operators/python.py", line 256, in execute_callable
    return runner.run(*self.op_args, **self.op_kwargs)
           ^^^^^^^^^^^^^^^^^^^^^^^^^^^^^^^^^^^^^^^^^^^
  File "/home/airflow/.local/lib/python3.12/site-packages/airflow/utils/operator_helpers.py", line 252, in run
    return self.func(*args, **kwargs)
           ^^^^^^^^^^^^^^^^^^^^^^^^^^
  File "/opt/airflow/dags/dag.py", line 69, in create_table
    hook.run(create_table_query)
  File "/home/airflow/.local/lib/python3.12/site-packages/airflow/providers/common/sql/hooks/sql.py", line 452, in run
    with self._create_autocommit_connection(autocommit) as conn:
         ^^^^^^^^^^^^^^^^^^^^^^^^^^^^^^^^^^^^^^^^^^^^^^
  File "/usr/local/lib/python3.12/contextlib.py", line 137, in __enter__
    return next(self.gen)
           ^^^^^^^^^^^^^^
  File "/home/airflow/.local/lib/python3.12/site-packages/airflow/providers/common/sql/hooks/sql.py", line 574, in _create_autocommit_connection
    with closing(self.get_conn()) as conn:
                 ^^^^^^^^^^^^^^^
  File "/home/airflow/.local/lib/python3.12/site-packages/airflow/providers/postgres/hooks/postgres.py", line 146, in get_conn
    conn = deepcopy(self.connection or self.get_connection(conn_id))
                                       ^^^^^^^^^^^^^^^^^^^^^^^^^^^^
  File "/home/airflow/.local/lib/python3.12/site-packages/airflow/hooks/base.py", line 83, in get_connection
    conn = Connection.get_connection_from_secrets(conn_id)
           ^^^^^^^^^^^^^^^^^^^^^^^^^^^^^^^^^^^^^^^^^^^^^^^
  File "/home/airflow/.local/lib/python3.12/site-packages/airflow/models/connection.py", line 537, in get_connection_from_secrets
    raise AirflowNotFoundException(f"The conn_id `{conn_id}` isn't defined")
airflow.exceptions.AirflowNotFoundException: The conn_id `my_postgres` isn't defined
[2024-09-26T20:58:17.715+0000] {logging_mixin.py:190} INFO - Task instance in failure state
[2024-09-26T20:58:17.717+0000] {logging_mixin.py:190} INFO - Task start:2024-09-26 20:58:15.899469+00:00 end:2024-09-26 20:58:17.714250+00:00 duration:1.814781
[2024-09-26T20:58:17.719+0000] {logging_mixin.py:190} INFO - Task:<Task(PythonOperator): create_table> dag:<DAG: fetch_and_save_share_prices> dagrun:<DagRun fetch_and_save_share_prices @ 2023-10-08 00:00:00+00:00: scheduled__2023-10-08T00:00:00+00:00, state:running, queued_at: 2024-09-26 20:57:31.501660+00:00. externally triggered: False>
[2024-09-26T20:58:17.720+0000] {logging_mixin.py:190} INFO - Failure caused by The conn_id `my_postgres` isn't defined
[2024-09-26T20:58:17.721+0000] {taskinstance.py:1225} INFO - Marking task as UP_FOR_RETRY. dag_id=fetch_and_save_share_prices, task_id=create_table, run_id=scheduled__2023-10-08T00:00:00+00:00, execution_date=20231008T000000, start_date=20240926T205815, end_date=20240926T205817
[2024-09-26T20:58:17.829+0000] {taskinstance.py:340} INFO - ::group::Post task execution logs
[2024-09-26T20:58:17.842+0000] {standard_task_runner.py:124} ERROR - Failed to execute job 24 for task create_table (The conn_id `my_postgres` isn't defined; 1632)
Traceback (most recent call last):
  File "/home/airflow/.local/lib/python3.12/site-packages/airflow/task/task_runner/standard_task_runner.py", line 117, in _start_by_fork
    ret = args.func(args, dag=self.dag)
          ^^^^^^^^^^^^^^^^^^^^^^^^^^^^^
  File "/home/airflow/.local/lib/python3.12/site-packages/airflow/cli/cli_config.py", line 49, in command
    return func(*args, **kwargs)
           ^^^^^^^^^^^^^^^^^^^^^
  File "/home/airflow/.local/lib/python3.12/site-packages/airflow/utils/cli.py", line 115, in wrapper
    return f(*args, **kwargs)
           ^^^^^^^^^^^^^^^^^^
  File "/home/airflow/.local/lib/python3.12/site-packages/airflow/cli/commands/task_command.py", line 483, in task_run
    task_return_code = _run_task_by_selected_method(args, _dag, ti)
                       ^^^^^^^^^^^^^^^^^^^^^^^^^^^^^^^^^^^^^^^^^^^^
  File "/home/airflow/.local/lib/python3.12/site-packages/airflow/cli/commands/task_command.py", line 256, in _run_task_by_selected_method
    return _run_raw_task(args, ti)
           ^^^^^^^^^^^^^^^^^^^^^^^
  File "/home/airflow/.local/lib/python3.12/site-packages/airflow/cli/commands/task_command.py", line 341, in _run_raw_task
    return ti._run_raw_task(
           ^^^^^^^^^^^^^^^^^
  File "/home/airflow/.local/lib/python3.12/site-packages/airflow/utils/session.py", line 97, in wrapper
    return func(*args, session=session, **kwargs)
           ^^^^^^^^^^^^^^^^^^^^^^^^^^^^^^^^^^^^^^
  File "/home/airflow/.local/lib/python3.12/site-packages/airflow/models/taskinstance.py", line 3004, in _run_raw_task
    return _run_raw_task(
           ^^^^^^^^^^^^^^
  File "/home/airflow/.local/lib/python3.12/site-packages/airflow/models/taskinstance.py", line 273, in _run_raw_task
    TaskInstance._execute_task_with_callbacks(
  File "/home/airflow/.local/lib/python3.12/site-packages/airflow/models/taskinstance.py", line 3158, in _execute_task_with_callbacks
    result = self._execute_task(context, task_orig)
             ^^^^^^^^^^^^^^^^^^^^^^^^^^^^^^^^^^^^^^
  File "/home/airflow/.local/lib/python3.12/site-packages/airflow/models/taskinstance.py", line 3182, in _execute_task
    return _execute_task(self, context, task_orig)
           ^^^^^^^^^^^^^^^^^^^^^^^^^^^^^^^^^^^^^^^
  File "/home/airflow/.local/lib/python3.12/site-packages/airflow/models/taskinstance.py", line 767, in _execute_task
    result = _execute_callable(context=context, **execute_callable_kwargs)
             ^^^^^^^^^^^^^^^^^^^^^^^^^^^^^^^^^^^^^^^^^^^^^^^^^^^^^^^^^^^^^
  File "/home/airflow/.local/lib/python3.12/site-packages/airflow/models/taskinstance.py", line 733, in _execute_callable
    return ExecutionCallableRunner(
           ^^^^^^^^^^^^^^^^^^^^^^^^
  File "/home/airflow/.local/lib/python3.12/site-packages/airflow/utils/operator_helpers.py", line 252, in run
    return self.func(*args, **kwargs)
           ^^^^^^^^^^^^^^^^^^^^^^^^^^
  File "/home/airflow/.local/lib/python3.12/site-packages/airflow/models/baseoperator.py", line 406, in wrapper
    return func(self, *args, **kwargs)
           ^^^^^^^^^^^^^^^^^^^^^^^^^^^
  File "/home/airflow/.local/lib/python3.12/site-packages/airflow/operators/python.py", line 238, in execute
    return_value = self.execute_callable()
                   ^^^^^^^^^^^^^^^^^^^^^^^
  File "/home/airflow/.local/lib/python3.12/site-packages/airflow/operators/python.py", line 256, in execute_callable
    return runner.run(*self.op_args, **self.op_kwargs)
           ^^^^^^^^^^^^^^^^^^^^^^^^^^^^^^^^^^^^^^^^^^^
  File "/home/airflow/.local/lib/python3.12/site-packages/airflow/utils/operator_helpers.py", line 252, in run
    return self.func(*args, **kwargs)
           ^^^^^^^^^^^^^^^^^^^^^^^^^^
  File "/opt/airflow/dags/dag.py", line 69, in create_table
    hook.run(create_table_query)
  File "/home/airflow/.local/lib/python3.12/site-packages/airflow/providers/common/sql/hooks/sql.py", line 452, in run
    with self._create_autocommit_connection(autocommit) as conn:
         ^^^^^^^^^^^^^^^^^^^^^^^^^^^^^^^^^^^^^^^^^^^^^^
  File "/usr/local/lib/python3.12/contextlib.py", line 137, in __enter__
    return next(self.gen)
           ^^^^^^^^^^^^^^
  File "/home/airflow/.local/lib/python3.12/site-packages/airflow/providers/common/sql/hooks/sql.py", line 574, in _create_autocommit_connection
    with closing(self.get_conn()) as conn:
                 ^^^^^^^^^^^^^^^
  File "/home/airflow/.local/lib/python3.12/site-packages/airflow/providers/postgres/hooks/postgres.py", line 146, in get_conn
    conn = deepcopy(self.connection or self.get_connection(conn_id))
                                       ^^^^^^^^^^^^^^^^^^^^^^^^^^^^
  File "/home/airflow/.local/lib/python3.12/site-packages/airflow/hooks/base.py", line 83, in get_connection
    conn = Connection.get_connection_from_secrets(conn_id)
           ^^^^^^^^^^^^^^^^^^^^^^^^^^^^^^^^^^^^^^^^^^^^^^^
  File "/home/airflow/.local/lib/python3.12/site-packages/airflow/models/connection.py", line 537, in get_connection_from_secrets
    raise AirflowNotFoundException(f"The conn_id `{conn_id}` isn't defined")
airflow.exceptions.AirflowNotFoundException: The conn_id `my_postgres` isn't defined
[2024-09-26T20:58:18.050+0000] {local_task_job_runner.py:266} INFO - Task exited with return code 1
[2024-09-26T20:58:18.142+0000] {local_task_job_runner.py:245} INFO - ::endgroup::
[2024-09-26T21:40:09.515+0000] {local_task_job_runner.py:123} INFO - ::group::Pre task execution logs
[2024-09-26T21:40:09.645+0000] {taskinstance.py:2612} INFO - Dependencies all met for dep_context=non-requeueable deps ti=<TaskInstance: fetch_and_save_share_prices.create_table scheduled__2023-10-08T00:00:00+00:00 [queued]>
[2024-09-26T21:40:09.705+0000] {taskinstance.py:2612} INFO - Dependencies all met for dep_context=requeueable deps ti=<TaskInstance: fetch_and_save_share_prices.create_table scheduled__2023-10-08T00:00:00+00:00 [queued]>
[2024-09-26T21:40:09.708+0000] {taskinstance.py:2865} INFO - Starting attempt 1 of 2
[2024-09-26T21:40:09.772+0000] {taskinstance.py:2888} INFO - Executing <Task(PythonOperator): create_table> on 2023-10-08 00:00:00+00:00
[2024-09-26T21:40:09.824+0000] {warnings.py:112} WARNING - /home/***/.local/lib/python3.12/site-packages/***/task/task_runner/standard_task_runner.py:70: DeprecationWarning: This process (pid=3074) is multi-threaded, use of fork() may lead to deadlocks in the child.
  pid = os.fork()

[2024-09-26T21:40:09.832+0000] {standard_task_runner.py:72} INFO - Started process 3104 to run task
[2024-09-26T21:40:09.841+0000] {standard_task_runner.py:104} INFO - Running: ['***', 'tasks', 'run', 'fetch_and_save_share_prices', 'create_table', 'scheduled__2023-10-08T00:00:00+00:00', '--job-id', '265', '--raw', '--subdir', 'DAGS_FOLDER/dag.py', '--cfg-path', '/tmp/tmp0jr1bkln']
[2024-09-26T21:40:09.848+0000] {standard_task_runner.py:105} INFO - Job 265: Subtask create_table
[2024-09-26T21:40:10.260+0000] {task_command.py:467} INFO - Running <TaskInstance: fetch_and_save_share_prices.create_table scheduled__2023-10-08T00:00:00+00:00 [running]> on host 13b5797a93ab
[2024-09-26T21:40:10.529+0000] {taskinstance.py:3131} INFO - Exporting env vars: AIRFLOW_CTX_DAG_OWNER='***' AIRFLOW_CTX_DAG_ID='fetch_and_save_share_prices' AIRFLOW_CTX_TASK_ID='create_table' AIRFLOW_CTX_EXECUTION_DATE='2023-10-08T00:00:00+00:00' AIRFLOW_CTX_TRY_NUMBER='1' AIRFLOW_CTX_DAG_RUN_ID='scheduled__2023-10-08T00:00:00+00:00'
[2024-09-26T21:40:10.532+0000] {logging_mixin.py:190} INFO - Task instance is in running state
[2024-09-26T21:40:10.533+0000] {logging_mixin.py:190} INFO -  Previous state of the Task instance: queued
[2024-09-26T21:40:10.535+0000] {logging_mixin.py:190} INFO - Current task name:create_table state:running start_date:2024-09-26 21:40:09.658748+00:00
[2024-09-26T21:40:10.536+0000] {logging_mixin.py:190} INFO - Dag name:fetch_and_save_share_prices and current dag run status:running
[2024-09-26T21:40:10.537+0000] {taskinstance.py:731} INFO - ::endgroup::
[2024-09-26T21:40:10.589+0000] {taskinstance.py:3310} ERROR - Task failed with exception
Traceback (most recent call last):
  File "/home/airflow/.local/lib/python3.12/site-packages/airflow/models/taskinstance.py", line 767, in _execute_task
    result = _execute_callable(context=context, **execute_callable_kwargs)
             ^^^^^^^^^^^^^^^^^^^^^^^^^^^^^^^^^^^^^^^^^^^^^^^^^^^^^^^^^^^^^
  File "/home/airflow/.local/lib/python3.12/site-packages/airflow/models/taskinstance.py", line 733, in _execute_callable
    return ExecutionCallableRunner(
           ^^^^^^^^^^^^^^^^^^^^^^^^
  File "/home/airflow/.local/lib/python3.12/site-packages/airflow/utils/operator_helpers.py", line 252, in run
    return self.func(*args, **kwargs)
           ^^^^^^^^^^^^^^^^^^^^^^^^^^
  File "/home/airflow/.local/lib/python3.12/site-packages/airflow/models/baseoperator.py", line 406, in wrapper
    return func(self, *args, **kwargs)
           ^^^^^^^^^^^^^^^^^^^^^^^^^^^
  File "/home/airflow/.local/lib/python3.12/site-packages/airflow/operators/python.py", line 238, in execute
    return_value = self.execute_callable()
                   ^^^^^^^^^^^^^^^^^^^^^^^
  File "/home/airflow/.local/lib/python3.12/site-packages/airflow/operators/python.py", line 256, in execute_callable
    return runner.run(*self.op_args, **self.op_kwargs)
           ^^^^^^^^^^^^^^^^^^^^^^^^^^^^^^^^^^^^^^^^^^^
  File "/home/airflow/.local/lib/python3.12/site-packages/airflow/utils/operator_helpers.py", line 252, in run
    return self.func(*args, **kwargs)
           ^^^^^^^^^^^^^^^^^^^^^^^^^^
  File "/opt/airflow/dags/dag.py", line 69, in create_table
    hook.run(create_table_query)
  File "/home/airflow/.local/lib/python3.12/site-packages/airflow/providers/common/sql/hooks/sql.py", line 452, in run
    with self._create_autocommit_connection(autocommit) as conn:
         ^^^^^^^^^^^^^^^^^^^^^^^^^^^^^^^^^^^^^^^^^^^^^^
  File "/usr/local/lib/python3.12/contextlib.py", line 137, in __enter__
    return next(self.gen)
           ^^^^^^^^^^^^^^
  File "/home/airflow/.local/lib/python3.12/site-packages/airflow/providers/common/sql/hooks/sql.py", line 574, in _create_autocommit_connection
    with closing(self.get_conn()) as conn:
                 ^^^^^^^^^^^^^^^
  File "/home/airflow/.local/lib/python3.12/site-packages/airflow/providers/postgres/hooks/postgres.py", line 146, in get_conn
    conn = deepcopy(self.connection or self.get_connection(conn_id))
                                       ^^^^^^^^^^^^^^^^^^^^^^^^^^^^
  File "/home/airflow/.local/lib/python3.12/site-packages/airflow/hooks/base.py", line 83, in get_connection
    conn = Connection.get_connection_from_secrets(conn_id)
           ^^^^^^^^^^^^^^^^^^^^^^^^^^^^^^^^^^^^^^^^^^^^^^^
  File "/home/airflow/.local/lib/python3.12/site-packages/airflow/models/connection.py", line 537, in get_connection_from_secrets
    raise AirflowNotFoundException(f"The conn_id `{conn_id}` isn't defined")
airflow.exceptions.AirflowNotFoundException: The conn_id `my_postgres` isn't defined
[2024-09-26T21:40:10.628+0000] {logging_mixin.py:190} INFO - Task instance in failure state
[2024-09-26T21:40:10.629+0000] {logging_mixin.py:190} INFO - Task start:2024-09-26 21:40:09.658748+00:00 end:2024-09-26 21:40:10.626947+00:00 duration:0.968199
[2024-09-26T21:40:10.631+0000] {logging_mixin.py:190} INFO - Task:<Task(PythonOperator): create_table> dag:<DAG: fetch_and_save_share_prices> dagrun:<DagRun fetch_and_save_share_prices @ 2023-10-08 00:00:00+00:00: scheduled__2023-10-08T00:00:00+00:00, state:running, queued_at: 2024-09-26 21:39:57.899350+00:00. externally triggered: False>
[2024-09-26T21:40:10.632+0000] {logging_mixin.py:190} INFO - Failure caused by The conn_id `my_postgres` isn't defined
[2024-09-26T21:40:10.633+0000] {taskinstance.py:1225} INFO - Marking task as UP_FOR_RETRY. dag_id=fetch_and_save_share_prices, task_id=create_table, run_id=scheduled__2023-10-08T00:00:00+00:00, execution_date=20231008T000000, start_date=20240926T214009, end_date=20240926T214010
[2024-09-26T21:40:10.681+0000] {taskinstance.py:340} INFO - ::group::Post task execution logs
[2024-09-26T21:40:10.683+0000] {standard_task_runner.py:124} ERROR - Failed to execute job 265 for task create_table (The conn_id `my_postgres` isn't defined; 3104)
Traceback (most recent call last):
  File "/home/airflow/.local/lib/python3.12/site-packages/airflow/task/task_runner/standard_task_runner.py", line 117, in _start_by_fork
    ret = args.func(args, dag=self.dag)
          ^^^^^^^^^^^^^^^^^^^^^^^^^^^^^
  File "/home/airflow/.local/lib/python3.12/site-packages/airflow/cli/cli_config.py", line 49, in command
    return func(*args, **kwargs)
           ^^^^^^^^^^^^^^^^^^^^^
  File "/home/airflow/.local/lib/python3.12/site-packages/airflow/utils/cli.py", line 115, in wrapper
    return f(*args, **kwargs)
           ^^^^^^^^^^^^^^^^^^
  File "/home/airflow/.local/lib/python3.12/site-packages/airflow/cli/commands/task_command.py", line 483, in task_run
    task_return_code = _run_task_by_selected_method(args, _dag, ti)
                       ^^^^^^^^^^^^^^^^^^^^^^^^^^^^^^^^^^^^^^^^^^^^
  File "/home/airflow/.local/lib/python3.12/site-packages/airflow/cli/commands/task_command.py", line 256, in _run_task_by_selected_method
    return _run_raw_task(args, ti)
           ^^^^^^^^^^^^^^^^^^^^^^^
  File "/home/airflow/.local/lib/python3.12/site-packages/airflow/cli/commands/task_command.py", line 341, in _run_raw_task
    return ti._run_raw_task(
           ^^^^^^^^^^^^^^^^^
  File "/home/airflow/.local/lib/python3.12/site-packages/airflow/utils/session.py", line 97, in wrapper
    return func(*args, session=session, **kwargs)
           ^^^^^^^^^^^^^^^^^^^^^^^^^^^^^^^^^^^^^^
  File "/home/airflow/.local/lib/python3.12/site-packages/airflow/models/taskinstance.py", line 3004, in _run_raw_task
    return _run_raw_task(
           ^^^^^^^^^^^^^^
  File "/home/airflow/.local/lib/python3.12/site-packages/airflow/models/taskinstance.py", line 273, in _run_raw_task
    TaskInstance._execute_task_with_callbacks(
  File "/home/airflow/.local/lib/python3.12/site-packages/airflow/models/taskinstance.py", line 3158, in _execute_task_with_callbacks
    result = self._execute_task(context, task_orig)
             ^^^^^^^^^^^^^^^^^^^^^^^^^^^^^^^^^^^^^^
  File "/home/airflow/.local/lib/python3.12/site-packages/airflow/models/taskinstance.py", line 3182, in _execute_task
    return _execute_task(self, context, task_orig)
           ^^^^^^^^^^^^^^^^^^^^^^^^^^^^^^^^^^^^^^^
  File "/home/airflow/.local/lib/python3.12/site-packages/airflow/models/taskinstance.py", line 767, in _execute_task
    result = _execute_callable(context=context, **execute_callable_kwargs)
             ^^^^^^^^^^^^^^^^^^^^^^^^^^^^^^^^^^^^^^^^^^^^^^^^^^^^^^^^^^^^^
  File "/home/airflow/.local/lib/python3.12/site-packages/airflow/models/taskinstance.py", line 733, in _execute_callable
    return ExecutionCallableRunner(
           ^^^^^^^^^^^^^^^^^^^^^^^^
  File "/home/airflow/.local/lib/python3.12/site-packages/airflow/utils/operator_helpers.py", line 252, in run
    return self.func(*args, **kwargs)
           ^^^^^^^^^^^^^^^^^^^^^^^^^^
  File "/home/airflow/.local/lib/python3.12/site-packages/airflow/models/baseoperator.py", line 406, in wrapper
    return func(self, *args, **kwargs)
           ^^^^^^^^^^^^^^^^^^^^^^^^^^^
  File "/home/airflow/.local/lib/python3.12/site-packages/airflow/operators/python.py", line 238, in execute
    return_value = self.execute_callable()
                   ^^^^^^^^^^^^^^^^^^^^^^^
  File "/home/airflow/.local/lib/python3.12/site-packages/airflow/operators/python.py", line 256, in execute_callable
    return runner.run(*self.op_args, **self.op_kwargs)
           ^^^^^^^^^^^^^^^^^^^^^^^^^^^^^^^^^^^^^^^^^^^
  File "/home/airflow/.local/lib/python3.12/site-packages/airflow/utils/operator_helpers.py", line 252, in run
    return self.func(*args, **kwargs)
           ^^^^^^^^^^^^^^^^^^^^^^^^^^
  File "/opt/airflow/dags/dag.py", line 69, in create_table
    hook.run(create_table_query)
  File "/home/airflow/.local/lib/python3.12/site-packages/airflow/providers/common/sql/hooks/sql.py", line 452, in run
    with self._create_autocommit_connection(autocommit) as conn:
         ^^^^^^^^^^^^^^^^^^^^^^^^^^^^^^^^^^^^^^^^^^^^^^
  File "/usr/local/lib/python3.12/contextlib.py", line 137, in __enter__
    return next(self.gen)
           ^^^^^^^^^^^^^^
  File "/home/airflow/.local/lib/python3.12/site-packages/airflow/providers/common/sql/hooks/sql.py", line 574, in _create_autocommit_connection
    with closing(self.get_conn()) as conn:
                 ^^^^^^^^^^^^^^^
  File "/home/airflow/.local/lib/python3.12/site-packages/airflow/providers/postgres/hooks/postgres.py", line 146, in get_conn
    conn = deepcopy(self.connection or self.get_connection(conn_id))
                                       ^^^^^^^^^^^^^^^^^^^^^^^^^^^^
  File "/home/airflow/.local/lib/python3.12/site-packages/airflow/hooks/base.py", line 83, in get_connection
    conn = Connection.get_connection_from_secrets(conn_id)
           ^^^^^^^^^^^^^^^^^^^^^^^^^^^^^^^^^^^^^^^^^^^^^^^
  File "/home/airflow/.local/lib/python3.12/site-packages/airflow/models/connection.py", line 537, in get_connection_from_secrets
    raise AirflowNotFoundException(f"The conn_id `{conn_id}` isn't defined")
airflow.exceptions.AirflowNotFoundException: The conn_id `my_postgres` isn't defined
[2024-09-26T21:40:10.737+0000] {local_task_job_runner.py:266} INFO - Task exited with return code 1
[2024-09-26T21:40:10.814+0000] {taskinstance.py:3900} INFO - 0 downstream tasks scheduled from follow-on schedule check
[2024-09-26T21:40:10.818+0000] {local_task_job_runner.py:245} INFO - ::endgroup::
[2024-09-26T21:48:09.542+0000] {local_task_job_runner.py:123} INFO - ::group::Pre task execution logs
[2024-09-26T21:48:09.626+0000] {taskinstance.py:2612} INFO - Dependencies all met for dep_context=non-requeueable deps ti=<TaskInstance: fetch_and_save_share_prices.create_table scheduled__2023-10-08T00:00:00+00:00 [queued]>
[2024-09-26T21:48:09.674+0000] {taskinstance.py:2612} INFO - Dependencies all met for dep_context=requeueable deps ti=<TaskInstance: fetch_and_save_share_prices.create_table scheduled__2023-10-08T00:00:00+00:00 [queued]>
[2024-09-26T21:48:09.690+0000] {taskinstance.py:2865} INFO - Starting attempt 1 of 2
[2024-09-26T21:48:09.755+0000] {taskinstance.py:2888} INFO - Executing <Task(PythonOperator): create_table> on 2023-10-08 00:00:00+00:00
[2024-09-26T21:48:09.778+0000] {warnings.py:112} WARNING - /home/***/.local/lib/python3.12/site-packages/***/task/task_runner/standard_task_runner.py:70: DeprecationWarning: This process (pid=3358) is multi-threaded, use of fork() may lead to deadlocks in the child.
  pid = os.fork()

[2024-09-26T21:48:09.788+0000] {standard_task_runner.py:104} INFO - Running: ['***', 'tasks', 'run', 'fetch_and_save_share_prices', 'create_table', 'scheduled__2023-10-08T00:00:00+00:00', '--job-id', '314', '--raw', '--subdir', 'DAGS_FOLDER/dag.py', '--cfg-path', '/tmp/tmpz6nml8si']
[2024-09-26T21:48:09.801+0000] {standard_task_runner.py:105} INFO - Job 314: Subtask create_table
[2024-09-26T21:48:09.791+0000] {standard_task_runner.py:72} INFO - Started process 3397 to run task
[2024-09-26T21:48:10.024+0000] {task_command.py:467} INFO - Running <TaskInstance: fetch_and_save_share_prices.create_table scheduled__2023-10-08T00:00:00+00:00 [running]> on host 13b5797a93ab
[2024-09-26T21:48:10.305+0000] {taskinstance.py:3131} INFO - Exporting env vars: AIRFLOW_CTX_DAG_OWNER='***' AIRFLOW_CTX_DAG_ID='fetch_and_save_share_prices' AIRFLOW_CTX_TASK_ID='create_table' AIRFLOW_CTX_EXECUTION_DATE='2023-10-08T00:00:00+00:00' AIRFLOW_CTX_TRY_NUMBER='1' AIRFLOW_CTX_DAG_RUN_ID='scheduled__2023-10-08T00:00:00+00:00'
[2024-09-26T21:48:10.308+0000] {logging_mixin.py:190} INFO - Task instance is in running state
[2024-09-26T21:48:10.309+0000] {logging_mixin.py:190} INFO -  Previous state of the Task instance: queued
[2024-09-26T21:48:10.311+0000] {logging_mixin.py:190} INFO - Current task name:create_table state:running start_date:2024-09-26 21:48:09.628370+00:00
[2024-09-26T21:48:10.312+0000] {logging_mixin.py:190} INFO - Dag name:fetch_and_save_share_prices and current dag run status:running
[2024-09-26T21:48:10.313+0000] {taskinstance.py:731} INFO - ::endgroup::
[2024-09-26T21:48:10.338+0000] {base.py:84} INFO - Retrieving connection 'dse_connection'
[2024-09-26T21:48:10.357+0000] {sql.py:509} INFO - Running statement: 
        CREATE TABLE IF NOT EXISTS company_share_prices (
            id SERIAL,
            company_id INTEGER NOT NULL,
            date DATE,
            latest_trading_price VARCHAR(50),
            low_price VARCHAR(50),
            high_price VARCHAR(50),
            closing_price VARCHAR(50),
            ycp VARCHAR(50),
            change VARCHAR(10),
            trade VARCHAR(50),
            value VARCHAR(50),
            volume VARCHAR(50),
            PRIMARY KEY(company_id, id),
            FOREIGN KEY(company_id)
                REFERENCES company_list(company_id)
                ON UPDATE CASCADE ON DELETE CASCADE
        );
    , parameters: None
[2024-09-26T21:48:10.384+0000] {taskinstance.py:3310} ERROR - Task failed with exception
Traceback (most recent call last):
  File "/home/airflow/.local/lib/python3.12/site-packages/airflow/models/taskinstance.py", line 767, in _execute_task
    result = _execute_callable(context=context, **execute_callable_kwargs)
             ^^^^^^^^^^^^^^^^^^^^^^^^^^^^^^^^^^^^^^^^^^^^^^^^^^^^^^^^^^^^^
  File "/home/airflow/.local/lib/python3.12/site-packages/airflow/models/taskinstance.py", line 733, in _execute_callable
    return ExecutionCallableRunner(
           ^^^^^^^^^^^^^^^^^^^^^^^^
  File "/home/airflow/.local/lib/python3.12/site-packages/airflow/utils/operator_helpers.py", line 252, in run
    return self.func(*args, **kwargs)
           ^^^^^^^^^^^^^^^^^^^^^^^^^^
  File "/home/airflow/.local/lib/python3.12/site-packages/airflow/models/baseoperator.py", line 406, in wrapper
    return func(self, *args, **kwargs)
           ^^^^^^^^^^^^^^^^^^^^^^^^^^^
  File "/home/airflow/.local/lib/python3.12/site-packages/airflow/operators/python.py", line 238, in execute
    return_value = self.execute_callable()
                   ^^^^^^^^^^^^^^^^^^^^^^^
  File "/home/airflow/.local/lib/python3.12/site-packages/airflow/operators/python.py", line 256, in execute_callable
    return runner.run(*self.op_args, **self.op_kwargs)
           ^^^^^^^^^^^^^^^^^^^^^^^^^^^^^^^^^^^^^^^^^^^
  File "/home/airflow/.local/lib/python3.12/site-packages/airflow/utils/operator_helpers.py", line 252, in run
    return self.func(*args, **kwargs)
           ^^^^^^^^^^^^^^^^^^^^^^^^^^
  File "/opt/airflow/dags/dag.py", line 69, in create_table
    hook.run(create_table_query)
  File "/home/airflow/.local/lib/python3.12/site-packages/airflow/providers/common/sql/hooks/sql.py", line 456, in run
    self._run_command(cur, sql_statement, parameters)
  File "/home/airflow/.local/lib/python3.12/site-packages/airflow/providers/common/sql/hooks/sql.py", line 514, in _run_command
    cur.execute(sql_statement)
psycopg2.errors.UndefinedTable: relation "company_list" does not exist

[2024-09-26T21:48:10.454+0000] {logging_mixin.py:190} INFO - Task instance in failure state
[2024-09-26T21:48:10.456+0000] {logging_mixin.py:190} INFO - Task start:2024-09-26 21:48:09.628370+00:00 end:2024-09-26 21:48:10.447874+00:00 duration:0.819504
[2024-09-26T21:48:10.458+0000] {logging_mixin.py:190} INFO - Task:<Task(PythonOperator): create_table> dag:<DAG: fetch_and_save_share_prices> dagrun:<DagRun fetch_and_save_share_prices @ 2023-10-08 00:00:00+00:00: scheduled__2023-10-08T00:00:00+00:00, state:running, queued_at: 2024-09-26 21:47:54.494331+00:00. externally triggered: False>
[2024-09-26T21:48:10.462+0000] {logging_mixin.py:190} INFO - Failure caused by relation "company_list" does not exist
[2024-09-26T21:48:10.465+0000] {taskinstance.py:1225} INFO - Marking task as UP_FOR_RETRY. dag_id=fetch_and_save_share_prices, task_id=create_table, run_id=scheduled__2023-10-08T00:00:00+00:00, execution_date=20231008T000000, start_date=20240926T214809, end_date=20240926T214810
[2024-09-26T21:48:10.528+0000] {taskinstance.py:340} INFO - ::group::Post task execution logs
[2024-09-26T21:48:10.530+0000] {standard_task_runner.py:124} ERROR - Failed to execute job 314 for task create_table (relation "company_list" does not exist
; 3397)
Traceback (most recent call last):
  File "/home/airflow/.local/lib/python3.12/site-packages/airflow/task/task_runner/standard_task_runner.py", line 117, in _start_by_fork
    ret = args.func(args, dag=self.dag)
          ^^^^^^^^^^^^^^^^^^^^^^^^^^^^^
  File "/home/airflow/.local/lib/python3.12/site-packages/airflow/cli/cli_config.py", line 49, in command
    return func(*args, **kwargs)
           ^^^^^^^^^^^^^^^^^^^^^
  File "/home/airflow/.local/lib/python3.12/site-packages/airflow/utils/cli.py", line 115, in wrapper
    return f(*args, **kwargs)
           ^^^^^^^^^^^^^^^^^^
  File "/home/airflow/.local/lib/python3.12/site-packages/airflow/cli/commands/task_command.py", line 483, in task_run
    task_return_code = _run_task_by_selected_method(args, _dag, ti)
                       ^^^^^^^^^^^^^^^^^^^^^^^^^^^^^^^^^^^^^^^^^^^^
  File "/home/airflow/.local/lib/python3.12/site-packages/airflow/cli/commands/task_command.py", line 256, in _run_task_by_selected_method
    return _run_raw_task(args, ti)
           ^^^^^^^^^^^^^^^^^^^^^^^
  File "/home/airflow/.local/lib/python3.12/site-packages/airflow/cli/commands/task_command.py", line 341, in _run_raw_task
    return ti._run_raw_task(
           ^^^^^^^^^^^^^^^^^
  File "/home/airflow/.local/lib/python3.12/site-packages/airflow/utils/session.py", line 97, in wrapper
    return func(*args, session=session, **kwargs)
           ^^^^^^^^^^^^^^^^^^^^^^^^^^^^^^^^^^^^^^
  File "/home/airflow/.local/lib/python3.12/site-packages/airflow/models/taskinstance.py", line 3004, in _run_raw_task
    return _run_raw_task(
           ^^^^^^^^^^^^^^
  File "/home/airflow/.local/lib/python3.12/site-packages/airflow/models/taskinstance.py", line 273, in _run_raw_task
    TaskInstance._execute_task_with_callbacks(
  File "/home/airflow/.local/lib/python3.12/site-packages/airflow/models/taskinstance.py", line 3158, in _execute_task_with_callbacks
    result = self._execute_task(context, task_orig)
             ^^^^^^^^^^^^^^^^^^^^^^^^^^^^^^^^^^^^^^
  File "/home/airflow/.local/lib/python3.12/site-packages/airflow/models/taskinstance.py", line 3182, in _execute_task
    return _execute_task(self, context, task_orig)
           ^^^^^^^^^^^^^^^^^^^^^^^^^^^^^^^^^^^^^^^
  File "/home/airflow/.local/lib/python3.12/site-packages/airflow/models/taskinstance.py", line 767, in _execute_task
    result = _execute_callable(context=context, **execute_callable_kwargs)
             ^^^^^^^^^^^^^^^^^^^^^^^^^^^^^^^^^^^^^^^^^^^^^^^^^^^^^^^^^^^^^
  File "/home/airflow/.local/lib/python3.12/site-packages/airflow/models/taskinstance.py", line 733, in _execute_callable
    return ExecutionCallableRunner(
           ^^^^^^^^^^^^^^^^^^^^^^^^
  File "/home/airflow/.local/lib/python3.12/site-packages/airflow/utils/operator_helpers.py", line 252, in run
    return self.func(*args, **kwargs)
           ^^^^^^^^^^^^^^^^^^^^^^^^^^
  File "/home/airflow/.local/lib/python3.12/site-packages/airflow/models/baseoperator.py", line 406, in wrapper
    return func(self, *args, **kwargs)
           ^^^^^^^^^^^^^^^^^^^^^^^^^^^
  File "/home/airflow/.local/lib/python3.12/site-packages/airflow/operators/python.py", line 238, in execute
    return_value = self.execute_callable()
                   ^^^^^^^^^^^^^^^^^^^^^^^
  File "/home/airflow/.local/lib/python3.12/site-packages/airflow/operators/python.py", line 256, in execute_callable
    return runner.run(*self.op_args, **self.op_kwargs)
           ^^^^^^^^^^^^^^^^^^^^^^^^^^^^^^^^^^^^^^^^^^^
  File "/home/airflow/.local/lib/python3.12/site-packages/airflow/utils/operator_helpers.py", line 252, in run
    return self.func(*args, **kwargs)
           ^^^^^^^^^^^^^^^^^^^^^^^^^^
  File "/opt/airflow/dags/dag.py", line 69, in create_table
    hook.run(create_table_query)
  File "/home/airflow/.local/lib/python3.12/site-packages/airflow/providers/common/sql/hooks/sql.py", line 456, in run
    self._run_command(cur, sql_statement, parameters)
  File "/home/airflow/.local/lib/python3.12/site-packages/airflow/providers/common/sql/hooks/sql.py", line 514, in _run_command
    cur.execute(sql_statement)
psycopg2.errors.UndefinedTable: relation "company_list" does not exist

[2024-09-26T21:48:10.619+0000] {local_task_job_runner.py:266} INFO - Task exited with return code 1
[2024-09-26T21:48:10.722+0000] {taskinstance.py:3900} INFO - 0 downstream tasks scheduled from follow-on schedule check
[2024-09-26T21:48:10.744+0000] {local_task_job_runner.py:245} INFO - ::endgroup::
[2024-09-26T21:55:03.254+0000] {local_task_job_runner.py:123} INFO - ::group::Pre task execution logs
[2024-09-26T21:55:03.335+0000] {taskinstance.py:2612} INFO - Dependencies all met for dep_context=non-requeueable deps ti=<TaskInstance: fetch_and_save_share_prices.create_table scheduled__2023-10-08T00:00:00+00:00 [queued]>
[2024-09-26T21:55:03.357+0000] {taskinstance.py:2612} INFO - Dependencies all met for dep_context=requeueable deps ti=<TaskInstance: fetch_and_save_share_prices.create_table scheduled__2023-10-08T00:00:00+00:00 [queued]>
[2024-09-26T21:55:03.358+0000] {taskinstance.py:2865} INFO - Starting attempt 1 of 2
[2024-09-26T21:55:03.436+0000] {taskinstance.py:2888} INFO - Executing <Task(PythonOperator): create_table> on 2023-10-08 00:00:00+00:00
[2024-09-26T21:55:03.496+0000] {warnings.py:112} WARNING - /home/***/.local/lib/python3.12/site-packages/***/task/task_runner/standard_task_runner.py:70: DeprecationWarning: This process (pid=3636) is multi-threaded, use of fork() may lead to deadlocks in the child.
  pid = os.fork()

[2024-09-26T21:55:03.502+0000] {standard_task_runner.py:104} INFO - Running: ['***', 'tasks', 'run', 'fetch_and_save_share_prices', 'create_table', 'scheduled__2023-10-08T00:00:00+00:00', '--job-id', '362', '--raw', '--subdir', 'DAGS_FOLDER/dag.py', '--cfg-path', '/tmp/tmp6237_qa7']
[2024-09-26T21:55:03.541+0000] {standard_task_runner.py:105} INFO - Job 362: Subtask create_table
[2024-09-26T21:55:03.515+0000] {standard_task_runner.py:72} INFO - Started process 3667 to run task
[2024-09-26T21:55:03.909+0000] {task_command.py:467} INFO - Running <TaskInstance: fetch_and_save_share_prices.create_table scheduled__2023-10-08T00:00:00+00:00 [running]> on host 13b5797a93ab
[2024-09-26T21:55:04.300+0000] {taskinstance.py:3131} INFO - Exporting env vars: AIRFLOW_CTX_DAG_OWNER='***' AIRFLOW_CTX_DAG_ID='fetch_and_save_share_prices' AIRFLOW_CTX_TASK_ID='create_table' AIRFLOW_CTX_EXECUTION_DATE='2023-10-08T00:00:00+00:00' AIRFLOW_CTX_TRY_NUMBER='1' AIRFLOW_CTX_DAG_RUN_ID='scheduled__2023-10-08T00:00:00+00:00'
[2024-09-26T21:55:04.311+0000] {logging_mixin.py:190} INFO - Task instance is in running state
[2024-09-26T21:55:04.322+0000] {logging_mixin.py:190} INFO -  Previous state of the Task instance: queued
[2024-09-26T21:55:04.325+0000] {logging_mixin.py:190} INFO - Current task name:create_table state:running start_date:2024-09-26 21:55:03.336070+00:00
[2024-09-26T21:55:04.326+0000] {logging_mixin.py:190} INFO - Dag name:fetch_and_save_share_prices and current dag run status:running
[2024-09-26T21:55:04.329+0000] {taskinstance.py:731} INFO - ::endgroup::
[2024-09-26T21:55:04.367+0000] {base.py:84} INFO - Retrieving connection 'dse_connection'
[2024-09-26T21:55:04.380+0000] {sql.py:509} INFO - Running statement: 
        CREATE TABLE IF NOT EXISTS company_share_prices (
            id SERIAL,
            company_id INTEGER NOT NULL,
            date DATE,
            latest_trading_price VARCHAR(50),
            low_price VARCHAR(50),
            high_price VARCHAR(50),
            closing_price VARCHAR(50),
            ycp VARCHAR(50),
            change VARCHAR(10),
            trade VARCHAR(50),
            value VARCHAR(50),
            volume VARCHAR(50),
            PRIMARY KEY(company_id, id),
            FOREIGN KEY(company_id)
                REFERENCES company_list(company_id)
                ON UPDATE CASCADE ON DELETE CASCADE
        );
    , parameters: None
[2024-09-26T21:55:04.429+0000] {taskinstance.py:3310} ERROR - Task failed with exception
Traceback (most recent call last):
  File "/home/airflow/.local/lib/python3.12/site-packages/airflow/models/taskinstance.py", line 767, in _execute_task
    result = _execute_callable(context=context, **execute_callable_kwargs)
             ^^^^^^^^^^^^^^^^^^^^^^^^^^^^^^^^^^^^^^^^^^^^^^^^^^^^^^^^^^^^^
  File "/home/airflow/.local/lib/python3.12/site-packages/airflow/models/taskinstance.py", line 733, in _execute_callable
    return ExecutionCallableRunner(
           ^^^^^^^^^^^^^^^^^^^^^^^^
  File "/home/airflow/.local/lib/python3.12/site-packages/airflow/utils/operator_helpers.py", line 252, in run
    return self.func(*args, **kwargs)
           ^^^^^^^^^^^^^^^^^^^^^^^^^^
  File "/home/airflow/.local/lib/python3.12/site-packages/airflow/models/baseoperator.py", line 406, in wrapper
    return func(self, *args, **kwargs)
           ^^^^^^^^^^^^^^^^^^^^^^^^^^^
  File "/home/airflow/.local/lib/python3.12/site-packages/airflow/operators/python.py", line 238, in execute
    return_value = self.execute_callable()
                   ^^^^^^^^^^^^^^^^^^^^^^^
  File "/home/airflow/.local/lib/python3.12/site-packages/airflow/operators/python.py", line 256, in execute_callable
    return runner.run(*self.op_args, **self.op_kwargs)
           ^^^^^^^^^^^^^^^^^^^^^^^^^^^^^^^^^^^^^^^^^^^
  File "/home/airflow/.local/lib/python3.12/site-packages/airflow/utils/operator_helpers.py", line 252, in run
    return self.func(*args, **kwargs)
           ^^^^^^^^^^^^^^^^^^^^^^^^^^
  File "/opt/airflow/dags/dag.py", line 69, in create_table
    hook.run(create_table_query)
  File "/home/airflow/.local/lib/python3.12/site-packages/airflow/providers/common/sql/hooks/sql.py", line 456, in run
    self._run_command(cur, sql_statement, parameters)
  File "/home/airflow/.local/lib/python3.12/site-packages/airflow/providers/common/sql/hooks/sql.py", line 514, in _run_command
    cur.execute(sql_statement)
psycopg2.errors.UndefinedTable: relation "company_list" does not exist

[2024-09-26T21:55:04.540+0000] {logging_mixin.py:190} INFO - Task instance in failure state
[2024-09-26T21:55:04.541+0000] {logging_mixin.py:190} INFO - Task start:2024-09-26 21:55:03.336070+00:00 end:2024-09-26 21:55:04.536964+00:00 duration:1.200894
[2024-09-26T21:55:04.550+0000] {logging_mixin.py:190} INFO - Task:<Task(PythonOperator): create_table> dag:<DAG: fetch_and_save_share_prices> dagrun:<DagRun fetch_and_save_share_prices @ 2023-10-08 00:00:00+00:00: scheduled__2023-10-08T00:00:00+00:00, state:running, queued_at: 2024-09-26 21:54:51.606495+00:00. externally triggered: False>
[2024-09-26T21:55:04.554+0000] {logging_mixin.py:190} INFO - Failure caused by relation "company_list" does not exist
[2024-09-26T21:55:04.560+0000] {taskinstance.py:1225} INFO - Marking task as UP_FOR_RETRY. dag_id=fetch_and_save_share_prices, task_id=create_table, run_id=scheduled__2023-10-08T00:00:00+00:00, execution_date=20231008T000000, start_date=20240926T215503, end_date=20240926T215504
[2024-09-26T21:55:04.626+0000] {taskinstance.py:340} INFO - ::group::Post task execution logs
[2024-09-26T21:55:04.629+0000] {standard_task_runner.py:124} ERROR - Failed to execute job 362 for task create_table (relation "company_list" does not exist
; 3667)
Traceback (most recent call last):
  File "/home/airflow/.local/lib/python3.12/site-packages/airflow/task/task_runner/standard_task_runner.py", line 117, in _start_by_fork
    ret = args.func(args, dag=self.dag)
          ^^^^^^^^^^^^^^^^^^^^^^^^^^^^^
  File "/home/airflow/.local/lib/python3.12/site-packages/airflow/cli/cli_config.py", line 49, in command
    return func(*args, **kwargs)
           ^^^^^^^^^^^^^^^^^^^^^
  File "/home/airflow/.local/lib/python3.12/site-packages/airflow/utils/cli.py", line 115, in wrapper
    return f(*args, **kwargs)
           ^^^^^^^^^^^^^^^^^^
  File "/home/airflow/.local/lib/python3.12/site-packages/airflow/cli/commands/task_command.py", line 483, in task_run
    task_return_code = _run_task_by_selected_method(args, _dag, ti)
                       ^^^^^^^^^^^^^^^^^^^^^^^^^^^^^^^^^^^^^^^^^^^^
  File "/home/airflow/.local/lib/python3.12/site-packages/airflow/cli/commands/task_command.py", line 256, in _run_task_by_selected_method
    return _run_raw_task(args, ti)
           ^^^^^^^^^^^^^^^^^^^^^^^
  File "/home/airflow/.local/lib/python3.12/site-packages/airflow/cli/commands/task_command.py", line 341, in _run_raw_task
    return ti._run_raw_task(
           ^^^^^^^^^^^^^^^^^
  File "/home/airflow/.local/lib/python3.12/site-packages/airflow/utils/session.py", line 97, in wrapper
    return func(*args, session=session, **kwargs)
           ^^^^^^^^^^^^^^^^^^^^^^^^^^^^^^^^^^^^^^
  File "/home/airflow/.local/lib/python3.12/site-packages/airflow/models/taskinstance.py", line 3004, in _run_raw_task
    return _run_raw_task(
           ^^^^^^^^^^^^^^
  File "/home/airflow/.local/lib/python3.12/site-packages/airflow/models/taskinstance.py", line 273, in _run_raw_task
    TaskInstance._execute_task_with_callbacks(
  File "/home/airflow/.local/lib/python3.12/site-packages/airflow/models/taskinstance.py", line 3158, in _execute_task_with_callbacks
    result = self._execute_task(context, task_orig)
             ^^^^^^^^^^^^^^^^^^^^^^^^^^^^^^^^^^^^^^
  File "/home/airflow/.local/lib/python3.12/site-packages/airflow/models/taskinstance.py", line 3182, in _execute_task
    return _execute_task(self, context, task_orig)
           ^^^^^^^^^^^^^^^^^^^^^^^^^^^^^^^^^^^^^^^
  File "/home/airflow/.local/lib/python3.12/site-packages/airflow/models/taskinstance.py", line 767, in _execute_task
    result = _execute_callable(context=context, **execute_callable_kwargs)
             ^^^^^^^^^^^^^^^^^^^^^^^^^^^^^^^^^^^^^^^^^^^^^^^^^^^^^^^^^^^^^
  File "/home/airflow/.local/lib/python3.12/site-packages/airflow/models/taskinstance.py", line 733, in _execute_callable
    return ExecutionCallableRunner(
           ^^^^^^^^^^^^^^^^^^^^^^^^
  File "/home/airflow/.local/lib/python3.12/site-packages/airflow/utils/operator_helpers.py", line 252, in run
    return self.func(*args, **kwargs)
           ^^^^^^^^^^^^^^^^^^^^^^^^^^
  File "/home/airflow/.local/lib/python3.12/site-packages/airflow/models/baseoperator.py", line 406, in wrapper
    return func(self, *args, **kwargs)
           ^^^^^^^^^^^^^^^^^^^^^^^^^^^
  File "/home/airflow/.local/lib/python3.12/site-packages/airflow/operators/python.py", line 238, in execute
    return_value = self.execute_callable()
                   ^^^^^^^^^^^^^^^^^^^^^^^
  File "/home/airflow/.local/lib/python3.12/site-packages/airflow/operators/python.py", line 256, in execute_callable
    return runner.run(*self.op_args, **self.op_kwargs)
           ^^^^^^^^^^^^^^^^^^^^^^^^^^^^^^^^^^^^^^^^^^^
  File "/home/airflow/.local/lib/python3.12/site-packages/airflow/utils/operator_helpers.py", line 252, in run
    return self.func(*args, **kwargs)
           ^^^^^^^^^^^^^^^^^^^^^^^^^^
  File "/opt/airflow/dags/dag.py", line 69, in create_table
    hook.run(create_table_query)
  File "/home/airflow/.local/lib/python3.12/site-packages/airflow/providers/common/sql/hooks/sql.py", line 456, in run
    self._run_command(cur, sql_statement, parameters)
  File "/home/airflow/.local/lib/python3.12/site-packages/airflow/providers/common/sql/hooks/sql.py", line 514, in _run_command
    cur.execute(sql_statement)
psycopg2.errors.UndefinedTable: relation "company_list" does not exist

[2024-09-26T21:55:04.716+0000] {local_task_job_runner.py:266} INFO - Task exited with return code 1
[2024-09-26T21:55:04.816+0000] {local_task_job_runner.py:245} INFO - ::endgroup::
